Workbook
Name \a: #N/A
Name \B: #REF!
Name \C: #REF!
Name \D: #REF!
Name \E: #REF!
Name \F: #REF!
Name \G: #REF!
Name \H: #REF!
Name \I: #REF!
Name \J: #REF!
Name \K: #REF!
Name \T: #REF!
Name \Z: #REF!
Name ___end1: [1]DATA!$V$71
Name __2_4THCOL: [3]DATA!$T$35:$T$35
Name __4_4THPMV: [3]DATA!$S$35:$S$35
Name __6_4THSPEND: [3]DATA!$U$35:$U$35
Name __end1: [3]DATA!$V$71
Name __new1: #REF!
Name _1_4THCOL: [1]DATA!$T$35:$T$35
Name _2_4THCOL: [4]DATA!$T$35:$T$35
Name _2_4THPMV: [1]DATA!$S$35:$S$35
Name _3_4THSPEND: [1]DATA!$U$35:$U$35
Name _4_4THPMV: [4]DATA!$S$35:$S$35
Name _6_4THSPEND: [4]DATA!$U$35:$U$35
Name _acr2: '[5]Apr-05'!#REF!
Name _CON1: #REF!
Name _CON10: #REF!
Name _CON11: #REF!
Name _CON12: #REF!
Name _CON13: #REF!
Name _CON14: #REF!
Name _CON15: #REF!
Name _CON16: #REF!
Name _CON2: #REF!
Name _CON3: #REF!
Name _CON4: #REF!
Name _CON5: #REF!
Name _CON6: #REF!
Name _CON7: #REF!
Name _CON8: #REF!
Name _CON9: #REF!
Name _end1: [4]DATA!$V$71
Name _ETB1: #REF!
Name _ETB2: #REF!
Name _ETB3: #REF!
Name _ETB4: #REF!
Name _ETB5: #REF!
Name _ETB6: #REF!
Name _fim: #REF!
Name _new1: [7]Original!$V$8
Name _OH1: #REF!
Name _OH2: #REF!
Name _OH3: #REF!
Name _OH4: #REF!
Name _OH5: #REF!
Name _OH6: #REF!
Name a: '[9]Manpower Master'!$O$57:$O$66
Name aa: #REF!
Name AB: #REF!

Sheet Pricing Notes
H6: Appendix A – Price Framework – FM Fees
H7: Pricing Notes
B9: · Accepted Fees: The amount accepted in the Letter of Acceptance for the completion of the FM Services.
B10: · Total FM Fees: The amount payable to the FM Service Provider for the Services and
B11: includes Variations and Reimbursable Expenses (Provisional Sum) as applicable in
B12: accordance with the Agreement.
B13: · Rates are per Person (EGP/Shift) including all required\proposed tools & equipment & consumables related to the Services
B14: · Service Provider shall be responsible for the consumables related to the Services
B15: · The Tenderer’s fee proposal for the Services shall be made on a total Man/Month basis with the total sum as the ceiling for the Contract Sum inclusive of all required\proposed tools & equipment, salaries, social insurance, overheads, direct and indirect expenses, all expected reimbursable, VAT, withholding tax and any other costs or expenditures required in the Arab Republic of Egypt for proper completion of the Scope of Services.
B16: · Monthly payment will be based on the actual attendance for each position at the rates stated in the Manning Schedule accepted by the Service Provider
B17: · Within the stated scope of services and the total Contract duration as stated, the Service Provider to ensure that the staff as per the manning schedule are sufficient to perform and complete the Scope of Services.
B18: · Should the Service Provider fail to cover the required Scope of Services in full satisfactory performance, the Employer reserve the right to instruct The Service Provider’s Representative to increase the staffing to recover such default without any extra cost whatsoever to the Employer.
B19: · A biometric attendance system must be used for daily attendance.
B20: · The Employer has the full right to extract the daily attendance at any time.
... B55: The Service Provider shall submit all the documentary evidence and substantiation to the Employer prior to the payment of Reimbursable / Provisional expenses in all cases.

Sheet FM Fees Summary
D2: Facility Management Services for Zone 2D, Zone 3D & Civic Park
D3: The Price Framework, Schedule 1 - Appendix A- Rev 03
D4: FM Fees Summary
D7: Zone | E7: Zone 2D | F7: Zone | G7: Zone 2D - 3D & Civic Park
D8: Contractual Year | E8: Year 1 | F8: Contractual Year | G8: Year 2
D9: Contractual Month | E9: Total amount/ Year1 | F9: Contractual Month | G9: Total amount/ Year2
D10: Mobilization | E10: ='Manning Schedule'!B12 -> 1579876 | F10: Mobilization (Not Applicable) / year 2 | G10: ='Manning Schedule'!T12 -> 0
D11: Total amount for MEP Services /year 1 | E11: ='Manning Schedule'!B31 -> 7322040 | F11: Total amount for MEP Services /year 2 | G11: ='Manning Schedule'!T31 -> 11566440
D12: Total amount for Housekeeping /year 1 | E12: ='Manning Schedule'!B37 -> 7147080 | F12: Total amount for Housekeeping /year 2 | G12: ='Manning Schedule'!T37 -> 12538440
D13: Total amount for Pest Control /year 1 | E13: ='Manning Schedule'!B41 -> 1008000 | F13: Total amount for Pest Control /year 2 | G13: ='Manning Schedule'!T41 -> 2130120
D14: Total amount for Landscape /year 1 | E14: ='Manning Schedule'!B46 -> 5643360 | F14: Total amount for Landscape /year 2 | G14: ='Manning Schedule'!T46 -> 16568280
D15: Total amount for Security Services /year 1 | E15: ='Manning Schedule'!B53 -> 12167280 | F15: Total amount for Security Services /year 2 | G15: ='Manning Schedule'!T53 -> 36174240
D16: Total amount for Transportation /year 1 | E16: ='Manning Schedule'!B58 -> 3469680 | F16: Total amount for Transportation /year 2 | G16: ='Manning Schedule'!T58 -> 3898080
D17: FM Fees/ year 1 | E17: =SUM(E10:E16) -> 38337316 | F17: FM Fees/ year 2 | G17: =SUM(G10:G16) -> 82875600
D18: Provisional Sum / reimbursable items / year 1 | E18: 10000000 | F18: Provisional Sum / reimbursable items / year 2 | G18: 10000000
D19: Total FM Fees amount including Provisional Sum/ year 1 | E19: =E18+E17 -> 48337316 | F19: Total FM Fees amount including Provisional Sum / year 2 | G19: =G18+G17 -> 92875600
D20: Total FM Fees Excluding VAT | E20: =E19+G19 -> 141212916
D21: VAT 14% | E21: =E20*0.14 -> 19769808
D22: Total FM Fees Including VAT | E22: =E20+E21 -> 1.6098272e+08

Sheet Manning Schedule
A2: Facility Management Services for Zone 2D, Zone 3D & Civic Park
A3: RFP Manning Schedule and Rates -Rev 03
A6: Zone | B6: Zone 2D | S6: Zone | T6: Zone 2D - 3D & Civic Park
A7: Contractual Year | B7: Year 1 | S7: Contractual Year | T7: Year 2
A8: Contractual Month | B8: Rate/ Shift/ Day | C8: No. of Manning/ Shift/ Day | O8: No. of Shifts/Day | P8: No. of Shifts /Month | Q8: Total Rate /Month | R8: Total Rate /Year 1 | T8: Rate/ Shift/ Day | U8: No. of Manning/ Shift/ Day | AG8: No. of Shifts/Day | AH8: No. of Shifts /Month | AI8: Total Rate /Month | AJ8: Total Rate /Year 2
C9: M1 | D9: M2 | E9: M3 | F9: M4 | G9: M5 | H9: M6 | I9: M7 | J9: M8 | K9: M9 | L9: M10 | M9: M11 | N9: M12 | S9: Contractual Month | U9: M1 | V9: M2 | W9: M3 | X9: M4 | Y9: M5 | Z9: M6 | AA9: M7 | AB9: M8 | AC9: M9 | AD9: M10 | AE9: M11 | AF9: M12
B10: Mobilization | T10: Mobilization
A11: Mobilization (Lumpsum item) | B11: =ROUNDUP('Mobilization Budget'!E105,0) -> 1579876 | C11: 1 | O11: 1 | P11: 1 | Q11: =B11*C11*P11 -> 1579876 | R11: =B11*SUM(C11:N11)*P11 -> 1579876 | S11: Mobilization (Not Applicable) | T11: 0
A12: Total amount for Mobilization /year 1 | B12: =R11 -> 1579876 | S12: Total amount for Mobilization /year 2 | T12: =AJ11 -> 0
J13: MEP Services | T13: MEP Services
A14: FM Manager | B14: ='MEP Budget-Y1'!N7 -> 2419 | C14: 1 | D14: 1 | E14: 1 | F14: 1 | G14: 1 | H14: 1 | I14: 1 | J14: 1 | K14: 1 | L14: 1 | M14: 1 | N14: 1 | O14: 1 | P14: =O14*30 -> 30 | Q14: =B14*C14*P14 -> 72570 | R14: =B14*SUM(C14:N14)*P14 -> 870840 | S14: FM Manager | T14: ='MEP Budget-Y2'!N7 -> 2760 | U14: 1 | V14: 1 | W14: 1 | X14: 1 | Y14: 1 | Z14: 1 | AA14: 1 | AB14: 1 | AC14: 1 | AD14: 1 | AE14: 1 | AF14: 1 | AG14: 1 | AH14: =AG14*30 -> 30 | AI14: =T14*U14*AH14 -> 82800 | AJ14: =T14*SUM(U14:AF14)*AH14 -> 993600
A15: Senior Engineer MEP | B15: ='MEP Budget-Y1'!N8 -> 1573 | C15: 1 | D15: 1 | E15: 1 | F15: 1 | G15: 1 | H15: 1 | I15: 1 | J15: 1 | K15: 1 | L15: 1 | M15: 1 | N15: 1 | O15: 1 | P15: =O15*30 -> 30 | Q15: =B15*C15*P15 -> 47190 | R15: =B15*SUM(C15:N15)*P15 -> 566280 | S15: Senior Engineer MEP | T15: ='MEP Budget-Y2'!N8 -> 1794 | U15: 2 | V15: 2 | W15: 2 | X15: 2 | Y15: 2 | Z15: 2 | AA15: 2 | AB15: 2 | AC15: 2 | AD15: 2 | AE15: 2 | AF15: 2 | AG15: 1 | AH15: =AG15*30 -> 30 | AI15: =T15*U15*AH15 -> 107640 | AJ15: =T15*SUM(U15:AF15)*AH15 -> 1291680
A16: Supervisor - Electrical | B16: ='MEP Budget-Y1'!N9 -> 883 | C16: 1 | D16: 1 | E16: 1 | F16: 1 | G16: 1 | H16: 1 | I16: 1 | J16: 1 | K16: 1 | L16: 1 | M16: 1 | N16: 1 | O16: 1 | P16: =O16*30 -> 30 | Q16: =B16*C16*P16 -> 26490 | R16: =B16*SUM(C16:N16)*P16 -> 317880 | S16: Supervisor - Electrical | T16: ='MEP Budget-Y2'!N9 -> 1008 | U16: 2 | V16: 2 | W16: 2 | X16: 2 | Y16: 2 | Z16: 2 | AA16: 2 | AB16: 2 | AC16: 2 | AD16: 2 | AE16: 2 | AF16: 2 | AG16: 1 | AH16: =AG16*30 -> 30 | AI16: =T16*U16*AH16 -> 60480 | AJ16: =T16*SUM(U16:AF16)*AH16 -> 725760
A17: Supervisor - Mechanical | B17: ='MEP Budget-Y1'!N10 -> 883 | C17: 1 | D17: 1 | E17: 1 | F17: 1 | G17: 1 | H17: 1 | I17: 1 | J17: 1 | K17: 1 | L17: 1 | M17: 1 | N17: 1 | O17: 1 | P17: =O17*30 -> 30 | Q17: =B17*C17*P17 -> 26490 | R17: =B17*SUM(C17:N17)*P17 -> 317880 | S17: Supervisor - Mechanical | T17: ='MEP Budget-Y2'!N10 -> 1008 | U17: 2 | V17: 2 | W17: 2 | X17: 2 | Y17: 2 | Z17: 2 | AA17: 2 | AB17: 2 | AC17: 2 | AD17: 2 | AE17: 2 | AF17: 2 | AG17: 1 | AH17: =AG17*30 -> 30 | AI17: =T17*U17*AH17 -> 60480 | AJ17: =T17*SUM(U17:AF17)*AH17 -> 725760
A18: Supervisor - Light Current | B18: ='MEP Budget-Y1'!N11 -> 883 | C18: 1 | D18: 1 | E18: 1 | F18: 1 | G18: 1 | H18: 1 | I18: 1 | J18: 1 | K18: 1 | L18: 1 | M18: 1 | N18: 1 | O18: 1 | P18: =O18*30 -> 30 | Q18: =B18*C18*P18 -> 26490 | R18: =B18*SUM(C18:N18)*P18 -> 317880 | S18: Supervisor - Light Current | T18: ='MEP Budget-Y2'!N11 -> 1008 | U18: 1 | V18: 1 | W18: 1 | X18: 1 | Y18: 1 | Z18: 1 | AA18: 1 | AB18: 1 | AC18: 1 | AD18: 1 | AE18: 1 | AF18: 1 | AG18: 1 | AH18: =AG18*30 -> 30 | AI18: =T18*U18*AH18 -> 30240 | AJ18: =T18*SUM(U18:AF18)*AH18 -> 362880
A19: Technician - Electrical | B19: ='MEP Budget-Y1'!N12 -> 500 | C19: 3 | D19: 3 | E19: 3 | F19: 3 | G19: 3 | H19: 3 | I19: 3 | J19: 3 | K19: 3 | L19: 3 | M19: 3 | N19: 3 | O19: 1 | P19: =O19*30 -> 30 | Q19: =B19*C19*P19 -> 45000 | R19: =B19*SUM(C19:N19)*P19 -> 540000 | S19: Technician - Electrical | T19: ='MEP Budget-Y2'!N12 -> 577 | U19: 5 | V19: 5 | W19: 5 | X19: 5 | Y19: 5 | Z19: 5 | AA19: 5 | AB19: 5 | AC19: 5 | AD19: 5 | AE19: 5 | AF19: 5 | AG19: 1 | AH19: =AG19*30 -> 30 | AI19: =T19*U19*AH19 -> 86550 | AJ19: =T19*SUM(U19:AF19)*AH19 -> 1038600
A20: Technician - Mechanical | B20: ='MEP Budget-Y1'!N13 -> 530 | C20: 1 | D20: 1 | E20: 1 | F20: 1 | G20: 1 | H20: 1 | I20: 1 | J20: 1 | K20: 1 | L20: 1 | M20: 1 | N20: 1 | O20: 1 | P20: =O20*30 -> 30 | Q20: =B20*C20*P20 -> 15900 | R20: =B20*SUM(C20:N20)*P20 -> 190800 | S20: Technician - Mechanical | T20: ='MEP Budget-Y2'!N13 -> 604 | U20: 2 | V20: 2 | W20: 2 | X20: 2 | Y20: 2 | Z20: 2 | AA20: 2 | AB20: 2 | AC20: 2 | AD20: 2 | AE20: 2 | AF20: 2 | AG20: 1 | AH20: =AG20*30 -> 30 | AI20: =T20*U20*AH20 -> 36240 | AJ20: =T20*SUM(U20:AF20)*AH20 -> 434880
A21: Technician - Pluming | B21: ='MEP Budget-Y1'!N14 -> 491 | C21: 3 | D21: 3 | E21: 3 | F21: 3 | G21: 3 | H21: 3 | I21: 3 | J21: 3 | K21: 3 | L21: 3 | M21: 3 | N21: 3 | O21: 1 | P21: =O21*30 -> 30 | Q21: =B21*C21*P21 -> 44190 | R21: =B21*SUM(C21:N21)*P21 -> 530280 | S21: Technician - Pluming | T21: ='MEP Budget-Y2'!N14 -> 567 | U21: 5 | V21: 5 | W21: 5 | X21: 5 | Y21: 5 | Z21: 5 | AA21: 5 | AB21: 5 | AC21: 5 | AD21: 5 | AE21: 5 | AF21: 5 | AG21: 1 | AH21: =AG21*30 -> 30 | AI21: =T21*U21*AH21 -> 85050 | AJ21: =T21*SUM(U21:AF21)*AH21 -> 1020600
A22: Technician - light Current | B22: ='MEP Budget-Y1'!N15 -> 545 | C22: 1 | D22: 1 | E22: 1 | F22: 1 | G22: 1 | H22: 1 | I22: 1 | J22: 1 | K22: 1 | L22: 1 | M22: 1 | N22: 1 | O22: 1 | P22: =O22*30 -> 30 | Q22: =B22*C22*P22 -> 16350 | R22: =B22*SUM(C22:N22)*P22 -> 196200 | S22: Technician - light Current | T22: ='MEP Budget-Y2'!N15 -> 621 | U22: 1 | V22: 1 | W22: 1 | X22: 1 | Y22: 1 | Z22: 1 | AA22: 1 | AB22: 1 | AC22: 1 | AD22: 1 | AE22: 1 | AF22: 1 | AG22: 1 | AH22: =AG22*30 -> 30 | AI22: =T22*U22*AH22 -> 18630 | AJ22: =T22*SUM(U22:AF22)*AH22 -> 223560
A23: CAFM - Coordinator | B23: ='MEP Budget-Y1'!N16 -> 744 | C23: 1 | D23: 1 | E23: 1 | F23: 1 | G23: 1 | H23: 1 | I23: 1 | J23: 1 | K23: 1 | L23: 1 | M23: 1 | N23: 1 | O23: 1 | P23: =O23*30 -> 30 | Q23: =B23*C23*P23 -> 22320 | R23: =B23*SUM(C23:N23)*P23 -> 267840 | S23: CAFM - Coordinator | T23: ='MEP Budget-Y2'!N16 -> 849 | U23: 1 | V23: 1 | W23: 1 | X23: 1 | Y23: 1 | Z23: 1 | AA23: 1 | AB23: 1 | AC23: 1 | AD23: 1 | AE23: 1 | AF23: 1 | AG23: 1 | AH23: =AG23*30 -> 30 | AI23: =T23*U23*AH23 -> 25470 | AJ23: =T23*SUM(U23:AF23)*AH23 -> 305640
A24: Painter | B24: ='MEP Budget-Y1'!N17 -> 514 | C24: 1 | D24: 1 | E24: 1 | F24: 1 | G24: 1 | H24: 1 | I24: 1 | J24: 1 | K24: 1 | L24: 1 | M24: 1 | N24: 1 | O24: 1 | P24: =O24*30 -> 30 | Q24: =B24*C24*P24 -> 15420 | R24: =B24*SUM(C24:N24)*P24 -> 185040 | S24: Painter | T24: ='MEP Budget-Y2'!N17 -> 587 | U24: 2 | V24: 2 | W24: 2 | X24: 2 | Y24: 2 | Z24: 2 | AA24: 2 | AB24: 2 | AC24: 2 | AD24: 2 | AE24: 2 | AF24: 2 | AG24: 1 | AH24: =AG24*30 -> 30 | AI24: =T24*U24*AH24 -> 35220 | AJ24: =T24*SUM(U24:AF24)*AH24 -> 422640
A25: Carpenter | B25: ='MEP Budget-Y1'!N18 -> 514 | C25: 1 | D25: 1 | E25: 1 | F25: 1 | G25: 1 | H25: 1 | I25: 1 | J25: 1 | K25: 1 | L25: 1 | M25: 1 | N25: 1 | O25: 1 | P25: =O25*30 -> 30 | Q25: =B25*C25*P25 -> 15420 | R25: =B25*SUM(C25:N25)*P25 -> 185040 | S25: Carpenter | T25: ='MEP Budget-Y2'!N18 -> 587 | U25: 2 | V25: 2 | W25: 2 | X25: 2 | Y25: 2 | Z25: 2 | AA25: 2 | AB25: 2 | AC25: 2 | AD25: 2 | AE25: 2 | AF25: 2 | AG25: 1 | AH25: =AG25*30 -> 30 | AI25: =T25*U25*AH25 -> 35220 | AJ25: =T25*SUM(U25:AF25)*AH25 -> 422640
... A30: Manlift | B30: ='MEP Budget-Y1'!N23 -> 3628 | C30: 1 | D30: 1 | E30: 1 | F30: 1 | G30: 1 | H30: 1 | I30: 1 | J30: 1 | K30: 1 | L30: 1 | M30: 1 | N30: 1 | O30: 1 | P30: =O30*30 -> 30 | Q30: =B30*C30*P30 -> 108840 | R30: =B30*SUM(C30:N30)*P30 -> 1306080 | S30: Manlift | T30: ='MEP Budget-Y2'!N23 -> 4140 | U30: 1 | V30: 1 | W30: 1 | X30: 1 | Y30: 1 | Z30: 1 | AA30: 1 | AB30: 1 | AC30: 1 | AD30: 1 | AE30: 1 | AF30: 1 | AG30: 1 | AH30: =AG30*30 -> 30 | AI30: =T30*U30*AH30 -> 124200 | AJ30: =T30*SUM(U30:AF30)*AH30 -> 1490400
A31: Total amount for MEP Services /year 1 | B31: =SUM(R14:R30) -> 7322040 | S31: Total amount for MEP Services /year 2 | T31: =SUM(AJ14:AJ30) -> 11566440
J32: Housekeeping & Waste Management | AB32: Housekeeping
A33: HK Supervisors | B33: ='HK & Waste Management-Y1'!N7 -> 895 | C33: 2 | D33: 2 | E33: 2 | F33: 2 | G33: 2 | H33: 2 | I33: 2 | J33: 2 | K33: 2 | L33: 2 | M33: 2 | N33: 2 | O33: 1 | P33: =O33*30 -> 30 | Q33: =B33*C33*P33 -> 53700 | R33: =B33*SUM(C33:N33)*P33 -> 644400 | S33: HK Supervisors | T33: ='HK & Waste Management-Y2'!N7 -> 955 | U33: 4 | V33: 4 | W33: 4 | X33: 4 | Y33: 4 | Z33: 4 | AA33: 4 | AB33: 4 | AC33: 4 | AD33: 4 | AE33: 4 | AF33: 4 | AG33: 1 | AH33: =AG33*30 -> 30 | AI33: =T33*U33*AH33 -> 114600 | AJ33: =T33*SUM(U33:AF33)*AH33 -> 1375200
A34: Janitors | B34: ='HK & Waste Management-Y1'!N8 -> 392 | C34: 20 | D34: 20 | E34: 20 | F34: 20 | G34: 20 | H34: 20 | I34: 20 | J34: 20 | K34: 20 | L34: 20 | M34: 20 | N34: 20 | O34: 1 | P34: =O34*30 -> 30 | Q34: =B34*C34*P34 -> 235200 | R34: =B34*SUM(C34:N34)*P34 -> 2822400 | S34: Janitors | T34: ='HK & Waste Management-Y2'!N8 -> 430 | U34: 40 | V34: 40 | W34: 40 | X34: 40 | Y34: 40 | Z34: 40 | AA34: 40 | AB34: 40 | AC34: 40 | AD34: 40 | AE34: 40 | AF34: 40 | AG34: 1 | AH34: =AG34*30 -> 30 | AI34: =T34*U34*AH34 -> 516000 | AJ34: =T34*SUM(U34:AF34)*AH34 -> 6192000
A35: Road Sweeper | B35: ='HK & Waste Management-Y1'!N9 -> 7667 | C35: 1 | D35: 1 | E35: 1 | F35: 1 | G35: 1 | H35: 1 | I35: 1 | J35: 1 | K35: 1 | L35: 1 | M35: 1 | N35: 1 | O35: 1 | P35: =O35*30 -> 30 | Q35: =B35*C35*P35 -> 230010 | R35: =B35*SUM(C35:N35)*P35 -> 2760120 | S35: Road Sweeper | T35: ='HK & Waste Management-Y2'!N9 -> 9095 | U35: 1 | V35: 1 | W35: 1 | X35: 1 | Y35: 1 | Z35: 1 | AA35: 1 | AB35: 1 | AC35: 1 | AD35: 1 | AE35: 1 | AF35: 1 | AG35: 1 | AH35: =AG35*30 -> 30 | AI35: =T35*U35*AH35 -> 272850 | AJ35: =T35*SUM(U35:AF35)*AH35 -> 3274200
A36: Waste Management (Lumpsum item per month) | B36: ='HK & Waste Management-Y1'!N10 -> 2556 | C36: 1 | D36: 1 | E36: 1 | F36: 1 | G36: 1 | H36: 1 | I36: 1 | J36: 1 | K36: 1 | L36: 1 | M36: 1 | N36: 1 | O36: 1 | P36: =O36*30 -> 30 | Q36: =B36*C36*P36 -> 76680 | R36: =B36*SUM(C36:N36)*P36 -> 920160 | S36: Waste Management | T36: ='HK & Waste Management-Y2'!N10 -> 4714 | U36: 1 | V36: 1 | W36: 1 | X36: 1 | Y36: 1 | Z36: 1 | AA36: 1 | AB36: 1 | AC36: 1 | AD36: 1 | AE36: 1 | AF36: 1 | AG36: 1 | AH36: =AG36*30 -> 30 | AI36: =T36*U36*AH36 -> 141420 | AJ36: =T36*SUM(U36:AF36)*AH36 -> 1697040
A37: Total amount for Housekeeping /year 1 | B37: =SUM(R33:R36) -> 7147080 | S37: Total amount for Housekeeping /year 2 | T37: =SUM(AJ33:AJ36) -> 12538440
J38: Pest Control | AB38: Pest Control
A39: Pest Control Supervisor | B39: ='Pest Control Y-1'!N7 -> 850 | C39: 1 | D39: 1 | E39: 1 | F39: 1 | G39: 1 | H39: 1 | I39: 1 | J39: 1 | K39: 1 | L39: 1 | M39: 1 | N39: 1 | O39: 1 | P39: =O39*30 -> 30 | Q39: =B39*C39*P39 -> 25500 | R39: =B39*SUM(C39:N39)*P39 -> 306000 | S39: Pest Control Supervisor | T39: ='Pest Control Y-2'!N7 -> 844 | U39: 1 | V39: 1 | W39: 1 | X39: 1 | Y39: 1 | Z39: 1 | AA39: 1 | AB39: 1 | AC39: 1 | AD39: 1 | AE39: 1 | AF39: 1 | AG39: 1 | AH39: =AG39*30 -> 30 | AI39: =T39*U39*AH39 -> 25320 | AJ39: =T39*SUM(U39:AF39)*AH39 -> 303840
A40: Pest Control Service (Lumpsum item per month) | B40: ='Pest Control Y-1'!N8 -> 1950 | C40: 1 | D40: 1 | E40: 1 | F40: 1 | G40: 1 | H40: 1 | I40: 1 | J40: 1 | K40: 1 | L40: 1 | M40: 1 | N40: 1 | O40: 1 | P40: =O40*30 -> 30 | Q40: =B40*C40*P40 -> 58500 | R40: =B40*SUM(C40:N40)*P40 -> 702000 | S40: Pest Control Service | T40: ='Pest Control Y-2'!N8 -> 5073 | U40: 1 | V40: 1 | W40: 1 | X40: 1 | Y40: 1 | Z40: 1 | AA40: 1 | AB40: 1 | AC40: 1 | AD40: 1 | AE40: 1 | AF40: 1 | AG40: 1 | AH40: =AG40*30 -> 30 | AI40: =T40*U40*AH40 -> 152190 | AJ40: =T40*SUM(U40:AF40)*AH40 -> 1826280
A41: Total amount for Pest Control /year 1 | B41: =SUM(R39:R40) -> 1008000 | C41: =#REF!*SUM(#REF!)*B41 -> #REF! | D41: =#REF!*SUM(#REF!)*C41 -> #REF! | E41: =#REF!*SUM(#REF!)*D41 -> #REF! | F41: =#REF!*SUM(#REF!)*E41 -> #REF! | G41: =#REF!*SUM(#REF!)*F41 -> #REF! | H41: =#REF!*SUM(#REF!)*G41 -> #REF! | I41: =#REF!*SUM(#REF!)*H41 -> #REF! | J41: =#REF!*SUM(#REF!)*I41 -> #REF! | ... M41: =#REF!*SUM(#REF!)*L41 -> #REF! | N41: =#REF!*SUM(A41:K41)*M41 -> #REF! | O41: =#REF!*SUM(A41:L41)*N41 -> #REF! | P41: =A41*SUM(B41:M41)*O41 -> #VALUE! | R41: =B41*SUM(C41:N41)*P41 -> #REF! | S41: Total amount for Pest Control /year 2 | T41: =SUM(AJ39:AJ40) -> 2130120
J42: Landscape (optional) | AB42: Landscape (optional)
A43: Landscape Manager | B43: ='Landscape Y1'!N7 -> 1958 | C43: 1 | D43: 1 | E43: 1 | F43: 1 | G43: 1 | H43: 1 | I43: 1 | J43: 1 | K43: 1 | L43: 1 | M43: 1 | N43: 1 | O43: 1 | P43: =O43*30 -> 30 | Q43: =B43*C43*P43 -> 58740 | R43: =B43*SUM(C43:N43)*P43 -> 704880 | S43: Landscape Manager | T43: ='Landscape Y2'!N7 -> 2179 | U43: 1 | V43: 1 | W43: 1 | X43: 1 | Y43: 1 | Z43: 1 | AA43: 1 | AB43: 1 | AC43: 1 | AD43: 1 | AE43: 1 | AF43: 1 | AG43: 1 | AH43: =AG43*30 -> 30 | AI43: =T43*U43*AH43 -> 65370 | AJ43: =T43*SUM(U43:AF43)*AH43 -> 784440
A44: Landscape Supervisor | B44: ='Landscape Y1'!N8 -> 1599 | C44: 2 | D44: 2 | E44: 2 | F44: 2 | G44: 2 | H44: 2 | I44: 2 | J44: 2 | K44: 2 | L44: 2 | M44: 2 | N44: 2 | O44: 1 | P44: =O44*30 -> 30 | Q44: =B44*C44*P44 -> 95940 | R44: =B44*SUM(C44:N44)*P44 -> 1151280 | S44: Landscape Supervisor | T44: ='Landscape Y2'!N8 -> 1631 | U44: 4 | V44: 4 | W44: 4 | X44: 4 | Y44: 4 | Z44: 4 | AA44: 4 | AB44: 4 | AC44: 4 | AD44: 4 | AE44: 4 | AF44: 4 | AG44: 1 | AH44: =AG44*30 -> 30 | AI44: =T44*U44*AH44 -> 195720 | AJ44: =T44*SUM(U44:AF44)*AH44 -> 2348640
A45: Gardner | B45: ='Landscape Y1'!N9 -> 526 | C45: 20 | D45: 20 | E45: 20 | F45: 20 | G45: 20 | H45: 20 | I45: 20 | J45: 20 | K45: 20 | L45: 20 | M45: 20 | N45: 20 | O45: 1 | P45: =O45*30 -> 30 | Q45: =B45*C45*P45 -> 315600 | R45: =B45*SUM(C45:N45)*P45 -> 3787200 | S45: Gardner | T45: ='Landscape Y2'!N9 -> 622 | U45: 60 | V45: 60 | W45: 60 | X45: 60 | Y45: 60 | Z45: 60 | AA45: 60 | AB45: 60 | AC45: 60 | AD45: 60 | AE45: 60 | AF45: 60 | AG45: 1 | AH45: =AG45*30 -> 30 | AI45: =T45*U45*AH45 -> 1119600 | AJ45: =T45*SUM(U45:AF45)*AH45 -> 13435200
A46: Total amount for Landscape /year 1 | B46: =SUM(R43:R45) -> 5643360 | S46: Total amount for Landscape /year 2 | T46: =SUM(AJ43:AJ45) -> 16568280
J47: Security Services | AB47: Security Services
...

Sheet End User Services Rates
B3: Facility Management Services for Zone 2D, Zone 3D & Civic Park
B4: End User & Days Works Rates
B7: Labor category | C7: Unite | D7: Rate
B10: Maintenance Engineer | C10: Hr | D10: 225
B11: Electrician | C11: Hr | D11: 100
B12: Electrician Helper | C12: Hr | D12: 80
B13: HVAC Technician | C13: Hr | D13: 120
B14: HVAC Helper | C14: Hr | D14: 80
B15: Plumber | C15: Hr | D15: 100
B16: Plumber Helper | C16: Hr | D16: 80
B17: Carpenter | C17: Hr | D17: 100
B18: Planting & Irrigator technician | C18: Hr | D18: 80
B19: Painter | C19: Hr | D19: 100
B20: 24-hour emergency call | C20: Day | D20: 3200
B21: Construction Waste Disposal from Tenants Units to Outside Project Boundary | C21: Trip | D21: 1800
... B24: Sewage Truck | C24: Visit | D24: 10000

Sheet Manning Schedule (2)
A2: Facility Management Services for Zone 2D, Zone 3D & Civic Park
A3: RFP Manning Schedule and Rates -Rev 03
A6: Zone | B6: Zone 2D | S6: Zone | T6: Zone 2D - 3D & Civic Park
A7: Contractual Year | B7: Year 1 | S7: Contractual Year | T7: Year 2
A8: Contractual Month | B8: Rate/ Shift/ Day | C8: No. of Manning/ Shift/ Day | O8: No. of Shifts/Day | P8: No. of Shifts /Month | Q8: Total Rate /Month | R8: Total Rate /Year 1 | T8: Rate/ Shift/ Day | U8: No. of Manning/ Shift/ Day | AG8: No. of Shifts/Day | AH8: No. of Shifts /Month | AI8: Total Rate /Month | AJ8: Total Rate /Year 2
C9: M1 | D9: M2 | E9: M3 | F9: M4 | G9: M5 | H9: M6 | I9: M7 | J9: M8 | K9: M9 | L9: M10 | M9: M11 | N9: M12 | S9: Contractual Month | U9: M1 | V9: M2 | W9: M3 | X9: M4 | Y9: M5 | Z9: M6 | AA9: M7 | AB9: M8 | AC9: M9 | AD9: M10 | AE9: M11 | AF9: M12
B10: Mobilization | T10: Mobilization
A11: Mobilization (Lumpsum item) | B11: =ROUNDUP('Mobilization Budget'!E105,0) -> 1579876 | C11: 1 | O11: 1 | P11: 1 | Q11: =B11*C11*P11 -> 1579876 | R11: =B11*SUM(C11:N11)*P11 -> 1579876 | S11: Mobilization (Not Applicable) | T11: 0
A12: Total amount for Mobilization /year 1 | B12: =R11 -> 1579876 | S12: Total amount for Mobilization /year 2 | T12: =AJ11 -> 0
J13: MEP Services | T13: MEP Services
A14: FM Manager | B14: ='MEP Budget-Y1'!N7 -> 2419 | C14: 1 | D14: 1 | E14: 1 | F14: 1 | G14: 1 | H14: 1 | I14: 1 | J14: 1 | K14: 1 | L14: 1 | M14: 1 | N14: 1 | O14: 1 | P14: =O14*30 -> 30 | Q14: =B14*C14*P14 -> 72570 | R14: =B14*SUM(C14:N14)*P14 -> 870840 | S14: FM Manager | T14: ='MEP Budget-Y2'!N7 -> 2760 | U14: 1 | V14: 1 | W14: 1 | X14: 1 | Y14: 1 | Z14: 1 | AA14: 1 | AB14: 1 | AC14: 1 | AD14: 1 | AE14: 1 | AF14: 1 | AG14: 1 | AH14: =AG14*30 -> 30 | AI14: =T14*U14*AH14 -> 82800 | AJ14: =T14*SUM(U14:AF14)*AH14 -> 993600
A15: Senior Engineer MEP | B15: ='MEP Budget-Y1'!N8 -> 1573 | C15: 1 | D15: 1 | E15: 1 | F15: 1 | G15: 1 | H15: 1 | I15: 1 | J15: 1 | K15: 1 | L15: 1 | M15: 1 | N15: 1 | O15: 1 | P15: =O15*30 -> 30 | Q15: =B15*C15*P15 -> 47190 | R15: =B15*SUM(C15:N15)*P15 -> 566280 | S15: Senior Engineer MEP | T15: ='MEP Budget-Y2'!N8 -> 1794 | U15: 2 | V15: 2 | W15: 2 | X15: 2 | Y15: 2 | Z15: 2 | AA15: 2 | AB15: 2 | AC15: 2 | AD15: 2 | AE15: 2 | AF15: 2 | AG15: 1 | AH15: =AG15*30 -> 30 | AI15: =T15*U15*AH15 -> 107640 | AJ15: =T15*SUM(U15:AF15)*AH15 -> 1291680
A16: Supervisor - Electrical | B16: ='MEP Budget-Y1'!N9 -> 883 | C16: 1 | D16: 1 | E16: 1 | F16: 1 | G16: 1 | H16: 1 | I16: 1 | J16: 1 | K16: 1 | L16: 1 | M16: 1 | N16: 1 | O16: 1 | P16: =O16*30 -> 30 | Q16: =B16*C16*P16 -> 26490 | R16: =B16*SUM(C16:N16)*P16 -> 317880 | S16: Supervisor - Electrical | T16: ='MEP Budget-Y2'!N9 -> 1008 | U16: 2 | V16: 2 | W16: 2 | X16: 2 | Y16: 2 | Z16: 2 | AA16: 2 | AB16: 2 | AC16: 2 | AD16: 2 | AE16: 2 | AF16: 2 | AG16: 1 | AH16: =AG16*30 -> 30 | AI16: =T16*U16*AH16 -> 60480 | AJ16: =T16*SUM(U16:AF16)*AH16 -> 725760
A17: Supervisor - Mechanical | B17: ='MEP Budget-Y1'!N10 -> 883 | C17: 1 | D17: 1 | E17: 1 | F17: 1 | G17: 1 | H17: 1 | I17: 1 | J17: 1 | K17: 1 | L17: 1 | M17: 1 | N17: 1 | O17: 1 | P17: =O17*30 -> 30 | Q17: =B17*C17*P17 -> 26490 | R17: =B17*SUM(C17:N17)*P17 -> 317880 | S17: Supervisor - Mechanical | T17: ='MEP Budget-Y2'!N10 -> 1008 | U17: 2 | V17: 2 | W17: 2 | X17: 2 | Y17: 2 | Z17: 2 | AA17: 2 | AB17: 2 | AC17: 2 | AD17: 2 | AE17: 2 | AF17: 2 | AG17: 1 | AH17: =AG17*30 -> 30 | AI17: =T17*U17*AH17 -> 60480 | AJ17: =T17*SUM(U17:AF17)*AH17 -> 725760
A18: Supervisor - Light Current | B18: ='MEP Budget-Y1'!N11 -> 883 | C18: 1 | D18: 1 | E18: 1 | F18: 1 | G18: 1 | H18: 1 | I18: 1 | J18: 1 | K18: 1 | L18: 1 | M18: 1 | N18: 1 | O18: 1 | P18: =O18*30 -> 30 | Q18: =B18*C18*P18 -> 26490 | R18: =B18*SUM(C18:N18)*P18 -> 317880 | S18: Supervisor - Light Current | T18: ='MEP Budget-Y2'!N11 -> 1008 | U18: 1 | V18: 1 | W18: 1 | X18: 1 | Y18: 1 | Z18: 1 | AA18: 1 | AB18: 1 | AC18: 1 | AD18: 1 | AE18: 1 | AF18: 1 | AG18: 1 | AH18: =AG18*30 -> 30 | AI18: =T18*U18*AH18 -> 30240 | AJ18: =T18*SUM(U18:AF18)*AH18 -> 362880
A19: Technician - Electrical | B19: ='MEP Budget-Y1'!N12 -> 500 | C19: 3 | D19: 3 | E19: 3 | F19: 3 | G19: 3 | H19: 3 | I19: 3 | J19: 3 | K19: 3 | L19: 3 | M19: 3 | N19: 3 | O19: 1 | P19: =O19*30 -> 30 | Q19: =B19*C19*P19 -> 45000 | R19: =B19*SUM(C19:N19)*P19 -> 540000 | S19: Technician - Electrical | T19: ='MEP Budget-Y2'!N12 -> 577 | U19: 5 | V19: 5 | W19: 5 | X19: 5 | Y19: 5 | Z19: 5 | AA19: 5 | AB19: 5 | AC19: 5 | AD19: 5 | AE19: 5 | AF19: 5 | AG19: 1 | AH19: =AG19*30 -> 30 | AI19: =T19*U19*AH19 -> 86550 | AJ19: =T19*SUM(U19:AF19)*AH19 -> 1038600
A20: Technician - Mechanical | B20: ='MEP Budget-Y1'!N13 -> 530 | C20: 1 | D20: 1 | E20: 1 | F20: 1 | G20: 1 | H20: 1 | I20: 1 | J20: 1 | K20: 1 | L20: 1 | M20: 1 | N20: 1 | O20: 1 | P20: =O20*30 -> 30 | Q20: =B20*C20*P20 -> 15900 | R20: =B20*SUM(C20:N20)*P20 -> 190800 | S20: Technician - Mechanical | T20: ='MEP Budget-Y2'!N13 -> 604 | U20: 2 | V20: 2 | W20: 2 | X20: 2 | Y20: 2 | Z20: 2 | AA20: 2 | AB20: 2 | AC20: 2 | AD20: 2 | AE20: 2 | AF20: 2 | AG20: 1 | AH20: =AG20*30 -> 30 | AI20: =T20*U20*AH20 -> 36240 | AJ20: =T20*SUM(U20:AF20)*AH20 -> 434880
A21: Technician - Pluming | B21: ='MEP Budget-Y1'!N14 -> 491 | C21: 3 | D21: 3 | E21: 3 | F21: 3 | G21: 3 | H21: 3 | I21: 3 | J21: 3 | K21: 3 | L21: 3 | M21: 3 | N21: 3 | O21: 1 | P21: =O21*30 -> 30 | Q21: =B21*C21*P21 -> 44190 | R21: =B21*SUM(C21:N21)*P21 -> 530280 | S21: Technician - Pluming | T21: ='MEP Budget-Y2'!N14 -> 567 | U21: 5 | V21: 5 | W21: 5 | X21: 5 | Y21: 5 | Z21: 5 | AA21: 5 | AB21: 5 | AC21: 5 | AD21: 5 | AE21: 5 | AF21: 5 | AG21: 1 | AH21: =AG21*30 -> 30 | AI21: =T21*U21*AH21 -> 85050 | AJ21: =T21*SUM(U21:AF21)*AH21 -> 1020600
A22: Technician - light Current | B22: ='MEP Budget-Y1'!N15 -> 545 | C22: 1 | D22: 1 | E22: 1 | F22: 1 | G22: 1 | H22: 1 | I22: 1 | J22: 1 | K22: 1 | L22: 1 | M22: 1 | N22: 1 | O22: 1 | P22: =O22*30 -> 30 | Q22: =B22*C22*P22 -> 16350 | R22: =B22*SUM(C22:N22)*P22 -> 196200 | S22: Technician - light Current | T22: ='MEP Budget-Y2'!N15 -> 621 | U22: 1 | V22: 1 | W22: 1 | X22: 1 | Y22: 1 | Z22: 1 | AA22: 1 | AB22: 1 | AC22: 1 | AD22: 1 | AE22: 1 | AF22: 1 | AG22: 1 | AH22: =AG22*30 -> 30 | AI22: =T22*U22*AH22 -> 18630 | AJ22: =T22*SUM(U22:AF22)*AH22 -> 223560
A23: CAFM - Coordinator | B23: ='MEP Budget-Y1'!N16 -> 744 | C23: 1 | D23: 1 | E23: 1 | F23: 1 | G23: 1 | H23: 1 | I23: 1 | J23: 1 | K23: 1 | L23: 1 | M23: 1 | N23: 1 | O23: 1 | P23: =O23*30 -> 30 | Q23: =B23*C23*P23 -> 22320 | R23: =B23*SUM(C23:N23)*P23 -> 267840 | S23: CAFM - Coordinator | T23: ='MEP Budget-Y2'!N16 -> 849 | U23: 1 | V23: 1 | W23: 1 | X23: 1 | Y23: 1 | Z23: 1 | AA23: 1 | AB23: 1 | AC23: 1 | AD23: 1 | AE23: 1 | AF23: 1 | AG23: 1 | AH23: =AG23*30 -> 30 | AI23: =T23*U23*AH23 -> 25470 | AJ23: =T23*SUM(U23:AF23)*AH23 -> 305640
A24: Painter | B24: ='MEP Budget-Y1'!N17 -> 514 | C24: 1 | D24: 1 | E24: 1 | F24: 1 | G24: 1 | H24: 1 | I24: 1 | J24: 1 | K24: 1 | L24: 1 | M24: 1 | N24: 1 | O24: 1 | P24: =O24*30 -> 30 | Q24: =B24*C24*P24 -> 15420 | R24: =B24*SUM(C24:N24)*P24 -> 185040 | S24: Painter | T24: ='MEP Budget-Y2'!N17 -> 587 | U24: 2 | V24: 2 | W24: 2 | X24: 2 | Y24: 2 | Z24: 2 | AA24: 2 | AB24: 2 | AC24: 2 | AD24: 2 | AE24: 2 | AF24: 2 | AG24: 1 | AH24: =AG24*30 -> 30 | AI24: =T24*U24*AH24 -> 35220 | AJ24: =T24*SUM(U24:AF24)*AH24 -> 422640
A25: Carpenter | B25: ='MEP Budget-Y1'!N18 -> 514 | C25: 1 | D25: 1 | E25: 1 | F25: 1 | G25: 1 | H25: 1 | I25: 1 | J25: 1 | K25: 1 | L25: 1 | M25: 1 | N25: 1 | O25: 1 | P25: =O25*30 -> 30 | Q25: =B25*C25*P25 -> 15420 | R25: =B25*SUM(C25:N25)*P25 -> 185040 | S25: Carpenter | T25: ='MEP Budget-Y2'!N18 -> 587 | U25: 2 | V25: 2 | W25: 2 | X25: 2 | Y25: 2 | Z25: 2 | AA25: 2 | AB25: 2 | AC25: 2 | AD25: 2 | AE25: 2 | AF25: 2 | AG25: 1 | AH25: =AG25*30 -> 30 | AI25: =T25*U25*AH25 -> 35220 | AJ25: =T25*SUM(U25:AF25)*AH25 -> 422640
... A30: Manlift | B30: ='MEP Budget-Y1'!N23 -> 3628 | C30: 1 | D30: 1 | E30: 1 | F30: 1 | G30: 1 | H30: 1 | I30: 1 | J30: 1 | K30: 1 | L30: 1 | M30: 1 | N30: 1 | O30: 1 | P30: =O30*30 -> 30 | Q30: =B30*C30*P30 -> 108840 | R30: =B30*SUM(C30:N30)*P30 -> 1306080 | S30: Manlift | T30: ='MEP Budget-Y2'!N23 -> 4140 | U30: 1 | V30: 1 | W30: 1 | X30: 1 | Y30: 1 | Z30: 1 | AA30: 1 | AB30: 1 | AC30: 1 | AD30: 1 | AE30: 1 | AF30: 1 | AG30: 1 | AH30: =AG30*30 -> 30 | AI30: =T30*U30*AH30 -> 124200 | AJ30: =T30*SUM(U30:AF30)*AH30 -> 1490400
A31: Total amount for MEP Services /year 1 | B31: =SUM(R14:R30) -> 7322040 | S31: Total amount for MEP Services /year 2 | T31: =SUM(AJ14:AJ30) -> 11566440
J32: Housekeeping & Waste Management | AB32: Housekeeping
A33: HK Supervisors | B33: ='HK & Waste Management-Y1'!N7 -> 895 | C33: 2 | D33: 2 | E33: 2 | F33: 2 | G33: 2 | H33: 2 | I33: 2 | J33: 2 | K33: 2 | L33: 2 | M33: 2 | N33: 2 | O33: 1 | P33: =O33*30 -> 30 | Q33: =B33*C33*P33 -> 53700 | R33: =B33*SUM(C33:N33)*P33 -> 644400 | S33: HK Supervisors | T33: ='HK & Waste Management-Y2'!N7 -> 955 | U33: 4 | V33: 4 | W33: 4 | X33: 4 | Y33: 4 | Z33: 4 | AA33: 4 | AB33: 4 | AC33: 4 | AD33: 4 | AE33: 4 | AF33: 4 | AG33: 1 | AH33: =AG33*30 -> 30 | AI33: =T33*U33*AH33 -> 114600 | AJ33: =T33*SUM(U33:AF33)*AH33 -> 1375200
A34: Janitors | B34: ='HK & Waste Management-Y1'!N8 -> 392 | C34: 20 | D34: 20 | E34: 20 | F34: 20 | G34: 20 | H34: 20 | I34: 20 | J34: 20 | K34: 20 | L34: 20 | M34: 20 | N34: 20 | O34: 1 | P34: =O34*30 -> 30 | Q34: =B34*C34*P34 -> 235200 | R34: =B34*SUM(C34:N34)*P34 -> 2822400 | S34: Janitors | T34: ='HK & Waste Management-Y2'!N8 -> 430 | U34: 40 | V34: 40 | W34: 40 | X34: 40 | Y34: 40 | Z34: 40 | AA34: 40 | AB34: 40 | AC34: 40 | AD34: 40 | AE34: 40 | AF34: 40 | AG34: 1 | AH34: =AG34*30 -> 30 | AI34: =T34*U34*AH34 -> 516000 | AJ34: =T34*SUM(U34:AF34)*AH34 -> 6192000
A35: Road Sweeper | B35: ='HK & Waste Management-Y1'!N9 -> 7667 | C35: 1 | D35: 1 | E35: 1 | F35: 1 | G35: 1 | H35: 1 | I35: 1 | J35: 1 | K35: 1 | L35: 1 | M35: 1 | N35: 1 | O35: 1 | P35: =O35*30 -> 30 | Q35: =B35*C35*P35 -> 230010 | R35: =B35*SUM(C35:N35)*P35 -> 2760120 | S35: Road Sweeper | T35: ='HK & Waste Management-Y2'!N9 -> 9095 | U35: 1 | V35: 1 | W35: 1 | X35: 1 | Y35: 1 | Z35: 1 | AA35: 1 | AB35: 1 | AC35: 1 | AD35: 1 | AE35: 1 | AF35: 1 | AG35: 1 | AH35: =AG35*30 -> 30 | AI35: =T35*U35*AH35 -> 272850 | AJ35: =T35*SUM(U35:AF35)*AH35 -> 3274200
A36: Waste Management (Lumpsum item per month) | B36: ='HK & Waste Management-Y1'!N10 -> 2556 | C36: 1 | D36: 1 | E36: 1 | F36: 1 | G36: 1 | H36: 1 | I36: 1 | J36: 1 | K36: 1 | L36: 1 | M36: 1 | N36: 1 | O36: 1 | P36: =O36*30 -> 30 | Q36: =B36*C36*P36 -> 76680 | R36: =B36*SUM(C36:N36)*P36 -> 920160 | S36: Waste Management | T36: ='HK & Waste Management-Y2'!N10 -> 4714 | U36: 1 | V36: 1 | W36: 1 | X36: 1 | Y36: 1 | Z36: 1 | AA36: 1 | AB36: 1 | AC36: 1 | AD36: 1 | AE36: 1 | AF36: 1 | AG36: 1 | AH36: =AG36*30 -> 30 | AI36: =T36*U36*AH36 -> 141420 | AJ36: =T36*SUM(U36:AF36)*AH36 -> 1697040
A37: Total amount for Housekeeping /year 1 | B37: =SUM(R33:R36) -> 7147080 | S37: Total amount for Housekeeping /year 2 | T37: =SUM(AJ33:AJ36) -> 12538440
J38: Pest Control | AB38: Pest Control
A39: Pest Control Supervisor | B39: ='Pest Control Y-1'!N7 -> 850 | C39: 1 | D39: 1 | E39: 1 | F39: 1 | G39: 1 | H39: 1 | I39: 1 | J39: 1 | K39: 1 | L39: 1 | M39: 1 | N39: 1 | O39: 1 | P39: =O39*30 -> 30 | Q39: =B39*C39*P39 -> 25500 | R39: =B39*SUM(C39:N39)*P39 -> 306000 | S39: Pest Control Supervisor | T39: ='Pest Control Y-2'!N7 -> 844 | U39: 1 | V39: 1 | W39: 1 | X39: 1 | Y39: 1 | Z39: 1 | AA39: 1 | AB39: 1 | AC39: 1 | AD39: 1 | AE39: 1 | AF39: 1 | AG39: 1 | AH39: =AG39*30 -> 30 | AI39: =T39*U39*AH39 -> 25320 | AJ39: =T39*SUM(U39:AF39)*AH39 -> 303840
A40: Pest Control Service (Lumpsum item per month) | B40: ='Pest Control Y-1'!N8 -> 1950 | C40: 1 | D40: 1 | E40: 1 | F40: 1 | G40: 1 | H40: 1 | I40: 1 | J40: 1 | K40: 1 | L40: 1 | M40: 1 | N40: 1 | O40: 1 | P40: =O40*30 -> 30 | Q40: =B40*C40*P40 -> 58500 | R40: =B40*SUM(C40:N40)*P40 -> 702000 | S40: Pest Control Service | T40: ='Pest Control Y-2'!N8 -> 5073 | U40: 1 | V40: 1 | W40: 1 | X40: 1 | Y40: 1 | Z40: 1 | AA40: 1 | AB40: 1 | AC40: 1 | AD40: 1 | AE40: 1 | AF40: 1 | AG40: 1 | AH40: =AG40*30 -> 30 | AI40: =T40*U40*AH40 -> 152190 | AJ40: =T40*SUM(U40:AF40)*AH40 -> 1826280
A41: Total amount for Pest Control /year 1 | B41: =SUM(R39:R40) -> 1008000 | C41: =#REF!*SUM(#REF!)*B41 -> #REF! | D41: =#REF!*SUM(#REF!)*C41 -> #REF! | E41: =#REF!*SUM(#REF!)*D41 -> #REF! | F41: =#REF!*SUM(#REF!)*E41 -> #REF! | G41: =#REF!*SUM(#REF!)*F41 -> #REF! | H41: =#REF!*SUM(#REF!)*G41 -> #REF! | I41: =#REF!*SUM(#REF!)*H41 -> #REF! | J41: =#REF!*SUM(#REF!)*I41 -> #REF! | ... M41: =#REF!*SUM(#REF!)*L41 -> #REF! | N41: =#REF!*SUM(A41:K41)*M41 -> #REF! | O41: =#REF!*SUM(A41:L41)*N41 -> #REF! | P41: =A41*SUM(B41:M41)*O41 -> #VALUE! | R41: =B41*SUM(C41:N41)*P41 -> #REF! | S41: Total amount for Pest Control /year 2 | T41: =SUM(AJ39:AJ40) -> 2130120
J42: Landscape (optional) | AB42: Landscape (optional)
A43: Landscape Manager | B43: ='Landscape Y1'!N7 -> 1958 | C43: 1 | D43: 1 | E43: 1 | F43: 1 | G43: 1 | H43: 1 | I43: 1 | J43: 1 | K43: 1 | L43: 1 | M43: 1 | N43: 1 | O43: 1 | P43: =O43*30 -> 30 | Q43: =B43*C43*P43 -> 58740 | R43: =B43*SUM(C43:N43)*P43 -> 704880 | S43: Landscape Manager | T43: ='Landscape Y2'!N7 -> 2179 | U43: 1 | V43: 1 | W43: 1 | X43: 1 | Y43: 1 | Z43: 1 | AA43: 1 | AB43: 1 | AC43: 1 | AD43: 1 | AE43: 1 | AF43: 1 | AG43: 1 | AH43: =AG43*30 -> 30 | AI43: =T43*U43*AH43 -> 65370 | AJ43: =T43*SUM(U43:AF43)*AH43 -> 784440
A44: Landscape Supervisor | B44: ='Landscape Y1'!N8 -> 1599 | C44: 2 | D44: 2 | E44: 2 | F44: 2 | G44: 2 | H44: 2 | I44: 2 | J44: 2 | K44: 2 | L44: 2 | M44: 2 | N44: 2 | O44: 1 | P44: =O44*30 -> 30 | Q44: =B44*C44*P44 -> 95940 | R44: =B44*SUM(C44:N44)*P44 -> 1151280 | S44: Landscape Supervisor | T44: ='Landscape Y2'!N8 -> 1631 | U44: 4 | V44: 4 | W44: 4 | X44: 4 | Y44: 4 | Z44: 4 | AA44: 4 | AB44: 4 | AC44: 4 | AD44: 4 | AE44: 4 | AF44: 4 | AG44: 1 | AH44: =AG44*30 -> 30 | AI44: =T44*U44*AH44 -> 195720 | AJ44: =T44*SUM(U44:AF44)*AH44 -> 2348640
A45: Gardner | B45: ='Landscape Y1'!N9 -> 526 | C45: 20 | D45: 20 | E45: 20 | F45: 20 | G45: 20 | H45: 20 | I45: 20 | J45: 20 | K45: 20 | L45: 20 | M45: 20 | N45: 20 | O45: 1 | P45: =O45*30 -> 30 | Q45: =B45*C45*P45 -> 315600 | R45: =B45*SUM(C45:N45)*P45 -> 3787200 | S45: Gardner | T45: ='Landscape Y2'!N9 -> 622 | U45: 60 | V45: 60 | W45: 60 | X45: 60 | Y45: 60 | Z45: 60 | AA45: 60 | AB45: 60 | AC45: 60 | AD45: 60 | AE45: 60 | AF45: 60 | AG45: 1 | AH45: =AG45*30 -> 30 | AI45: =T45*U45*AH45 -> 1119600 | AJ45: =T45*SUM(U45:AF45)*AH45 -> 13435200
A46: Total amount for Landscape /year 1 | B46: =SUM(R43:R45) -> 5643360 | S46: Total amount for Landscape /year 2 | T46: =SUM(AJ43:AJ45) -> 16568280
J47: Security Services | AB47: Security Services
...

Sheet Fianl All
B1: 1) Security Budget Scenarios
B2: Security Manpower | D2: Rate | E2: Qty | F2: Shift/Month | G2: Monthly | I2: Rate | J2: Qty | K2: Shift/Month | L2: Monthly | N2: Rate | O2: Qty | P2: Shift/Month | Q2: Monthly
B3: Security Manger | D3: 1374 | E3: 1 | F3: 30 | G3: =F3*E3*D3 -> 41220 | I3: 1456 | J3: 1 | K3: 30 | L3: =I3*F3*E3 -> 43680 | N3: 1456 | O3: 1 | P3: 30 | Q3: =P3*O3*N3 -> 43680
B4: Safety Supervisor / Agent | D4: 916 | E4: 4 | F4: 30 | G4: =F4*E4*D4 -> 109920 | I4: 971 | J4: 4 | K4: 30 | L4: =I4*F4*E4 -> 116520 | N4: 971 | O4: 8 | P4: 30 | Q4: =P4*O4*N4 -> 233040
B5: Security Supervisor / per shift | D5: 620 | E5: 2 | F5: 30 | G5: =F5*E5*D5 -> 37200 | I5: 656 | J5: 2 | K5: 30 | L5: =I5*F5*E5 -> 39360 | N5: 656 | O5: 2 | P5: 30 | Q5: =P5*O5*N5 -> 39360
B6: Security Guards / per shift | D6: 344 | E6: 80 | F6: 30 | G6: =F6*E6*D6 -> 825600 | I6: 364 | J6: 80 | K6: 30 | L6: =I6*F6*E6 -> 873600 | N6: 364 | O6: 240 | P6: 30 | Q6: =P6*O6*N6 -> 2620800
B7: CCTV Operator | D7: 0 | E7: 0 | F7: 0 | G7: =F7*E7*D7 -> 0 | I7: 647 | J7: 0 | K7: 0 | L7: =I7*F7*E7 -> 0 | N7: 647 | O7: 4 | P7: 30 | Q7: =P7*O7*N7 -> 77640
B8: Total | D8: =Table1511[[#Totals],[Monthly]]/Table1511[[#Totals],[Qty]] -> 11654.483 | E8: =SUBTOTAL(109,Table1511[Qty]) -> 87 | G8: =SUBTOTAL(109,Table1511[Monthly]) -> 1013940 | I8: =Table2612[[#Totals],[Monthly]]/Table2612[[#Totals],[Qty]] -> 12335.172 | J8: =SUBTOTAL(109,Table2612[Qty]) -> 87 | L8: =SUBTOTAL(109,Table2612[Monthly]) -> 1073160 | N8: =Table3713[[#Totals],[Monthly]]/Table3713[[#Totals],[Qty]] -> 11821.647 | O8: =SUBTOTAL(109,Table3713[Qty]) -> 255 | Q8: =SUBTOTAL(109,Table3713[Monthly]) -> 3014520
B10: Transportation | D10: Rate | E10: Qty | F10: Shift/Month | G10: Monthly | I10: Rate | J10: Qty | K10: Shift/Month | L10: Monthly | N10: Rate | O10: Qty | P10: Shift/Month | Q10: Monthly
B11: Pickup Double Cabinet (1 security ) | D11: 2002 | E11: 0 | F11: 30 | G11: =D11*E11*F11 -> 0 | I11: 2249 | J11: 0 | K11: 30 | L11: =I11*J11*K11 -> 0 | N11: 2249 | O11: 0 | P11: 30 | Q11: =N11*O11*P11 -> 0
B12: Golf Car | D12: 2310 | E12: 1 | F12: 30 | G12: =D12*E12*F12 -> 69300 | I12: 2595 | J12: 1 | K12: 30 | L12: =I12*J12*K12 -> 77850 | N12: 2595 | O12: 1 | P12: 30 | Q12: =N12*O12*P12 -> 77850
B13: Security Patrol Motorcycles / Tricycles | D13: 507 | E13: 2 | F13: 30 | G13: =D13*E13*F13 -> 30420 | I13: 570 | J13: 2 | K13: 30 | L13: =I13*J13*K13 -> 34200 | N13: 570 | O13: 2 | P13: 30 | Q13: =N13*O13*P13 -> 34200
B14: Total | G14: =SUBTOTAL(109,Table15[Monthly]) -> 99720 | L14: =SUBTOTAL(109,Table16[Monthly]) -> 112050 | Q14: =SUBTOTAL(109,Table17[Monthly]) -> 112050
B16: Total Revenue | D16: =G16/Table1511[[#Totals],[Qty]] -> 12800.69 | G16: =Table15[[#Totals],[Monthly]]+Table1511[[#Totals],[Monthly]] -> 1113660 | I16: =L16/Table2612[[#Totals],[Qty]] -> 13623.103 | L16: =Table16[[#Totals],[Monthly]]+Table2612[[#Totals],[Monthly]] -> 1185210 | N16: =Q16/Table3713[[#Totals],[Qty]] -> 12261.059 | Q16: =Table17[[#Totals],[Monthly]]+Table3713[[#Totals],[Monthly]] -> 3126570
B18: Security Manpower | D18: Rate | E18: Qty | F18: Shift/Month | G18: Monthly | I18: Rate | J18: Qty | K18: Shift/Month | L18: Monthly | N18: Rate | O18: Qty | P18: Shift/Month | Q18: Monthly
B19: Security Manger | D19: 29000 | E19: 1 | F19: 30 | G19: ='Fianl All'!$D19*'Fianl All'!$E19 -> 29000 | I19: 29000 | J19: 1 | K19: 30 | L19: ='Fianl All'!$I19*'Fianl All'!$J19 -> 29000 | N19: 29000 | O19: 1 | P19: 30 | Q19: ='Fianl All'!$N19*'Fianl All'!$O19 -> 29000 | S19: =('Fianl All'!$D19/30)*(16/12) -> 1288.8889 | T19: =S19*'Fianl All'!$E19 -> 1288.8889 | U19: =('Fianl All'!$I19/30)*(16/12) -> 1288.8889 | V19: =U19*'Fianl All'!$J19 -> 1288.8889 | W19: =('Fianl All'!$N19/30)*(16/12) -> 1288.8889 | X19: =W19*'Fianl All'!$O19 -> 1288.8889
B20: Safety Supervisor / Agent | D20: 14000 | E20: 5 | F20: 30 | G20: ='Fianl All'!$D20*'Fianl All'!$E20 -> 70000 | I20: 14000 | J20: 5 | K20: 30 | L20: ='Fianl All'!$I20*'Fianl All'!$J20 -> 70000 | N20: 14000 | O20: 9 | P20: 30 | Q20: ='Fianl All'!$N20*'Fianl All'!$O20 -> 126000 | S20: =('Fianl All'!$D20/30)*(16/12) -> 622.22222 | T20: =S20*'Fianl All'!$E20 -> 3111.1111 | U20: =('Fianl All'!$I20/30)*(16/12) -> 622.22222 | V20: =U20*'Fianl All'!$J20 -> 3111.1111 | W20: =('Fianl All'!$N20/30)*(16/12) -> 622.22222 | X20: =W20*'Fianl All'!$O20 -> 5600
B21: Security Supervisor / per shift | D21: 9000 | E21: 3 | F21: 30 | G21: ='Fianl All'!$D21*'Fianl All'!$E21 -> 27000 | I21: 9500 | J21: 3 | K21: 30 | L21: ='Fianl All'!$I21*'Fianl All'!$J21 -> 28500 | N21: 9500 | O21: 3 | P21: 30 | Q21: ='Fianl All'!$N21*'Fianl All'!$O21 -> 28500 | S21: =('Fianl All'!$D21/30)*(16/12) -> 400 | T21: =S21*'Fianl All'!$E21 -> 1200 | U21: =('Fianl All'!$I21/30)*(16/12) -> 422.22222 | V21: =U21*'Fianl All'!$J21 -> 1266.6667 | W21: =('Fianl All'!$N21/30)*(16/12) -> 422.22222 | X21: =W21*'Fianl All'!$O21 -> 1266.6667
B22: Security Guards / per shift | D22: 7000 | E22: 96 | F22: 30 | G22: ='Fianl All'!$D22*'Fianl All'!$E22 -> 672000 | I22: 8000 | J22: 96 | K22: 30 | L22: ='Fianl All'!$I22*'Fianl All'!$J22 -> 768000 | N22: 8200 | O22: 288 | P22: 30 | Q22: ='Fianl All'!$N22*'Fianl All'!$O22 -> 2361600 | S22: =('Fianl All'!$D22/30)*(16/12) -> 311.11111 | T22: =S22*'Fianl All'!$E22 -> 29866.667 | U22: =('Fianl All'!$I22/30)*(16/12) -> 355.55556 | V22: =U22*'Fianl All'!$J22 -> 34133.333 | W22: =('Fianl All'!$N22/30)*(16/12) -> 364.44444 | X22: =W22*'Fianl All'!$O22 -> 104960
B23: CCTV Operator | D23: 8000 | E23: 0 | F23: 0 | G23: ='Fianl All'!$D23*'Fianl All'!$E23 -> 0 | I23: 9000 | J23: 0 | K23: 0 | L23: ='Fianl All'!$I23*'Fianl All'!$J23 -> 0 | N23: 9000 | O23: 0 | P23: 0 | Q23: ='Fianl All'!$N23*'Fianl All'!$O23 -> 0
B24: Eid Vacation Allowance | D24: =T24 -> 35466.667 | E24: 1 | F24: 30 | G24: ='Fianl All'!$D24*'Fianl All'!$E24 -> 35466.667 | I24: =V24 -> 39800 | J24: 1 | K24: 30 | L24: ='Fianl All'!$I24*'Fianl All'!$J24 -> 39800 | N24: =X24 -> 113115.56 | O24: 1 | P24: 0 | Q24: ='Fianl All'!$N24*'Fianl All'!$O24 -> 113115.56 | S24: =SUM(S19:S23) -> 2622.2222 | T24: =SUM(T19:T23) -> 35466.667 | U24: =SUM(U19:U23) -> 2688.8889 | V24: =SUM(V19:V23) -> 39800 | W24: =SUM(W19:W23) -> 2697.7778 | X24: =SUM(X19:X23) -> 113115.56
B25: Total | D25: ='Fianl All'!$G$25/'Fianl All'!$E$25 -> 8907.619 | E25: =SUBTOTAL(109,'Fianl All'!$E$19:$E$23) -> 105 | F25: ='Fianl All'!$G$25/G16 -> 0.8398434 | G25: =SUBTOTAL(109,'Fianl All'!$L$19:$L$24) -> 935300 | I25: ='Fianl All'!$L$25/'Fianl All'!$J$25 -> 8907.619 | J25: =SUBTOTAL(109,'Fianl All'!$J$19:$J$23) -> 105 | K25: ='Fianl All'!$L$25/L16 -> 0.78914285 | L25: =SUBTOTAL(109,'Fianl All'!$L$19:$L$24) -> 935300 | N25: ='Fianl All'!$Q$25/'Fianl All'!$O$25 -> 8831.2809 | O25: =SUBTOTAL(109,'Fianl All'!$O$19:$O$23) -> 301 | P25: ='Fianl All'!$Q$25/Q16 -> 0.85020184 | Q25: =SUM(Q19:Q24) -> 2658215.6
B27: Security Tools&Consumabls&uniform | D27: Rate | E27: Qty | F27: . | G27: Monthly | I27: Rate | J27: Qty | K27: . | L27: Monthly | N27: Rate | O27: Qty | P27: . | Q27: Monthly
B28: Depreciation tools | D28: 2750 | E28: 1 | G28: =D28*E28 -> 2750 | I28: =Table23[[#This Row],[Rate]] -> 2750 | J28: 1 | K28: 0 | L28: =I28*J28 -> 2750 | N28: =Table23[[#This Row],[Rate]] -> 2750 | O28: 3 | P28: 0 | Q28: =N28*O28 -> 8250
B29: Consumtion documentation | D29: 10000 | E29: 1 | G29: =D29*E29 -> 10000 | I29: =Table23[[#This Row],[Rate]] -> 10000 | J29: 1 | K29: 0 | L29: =I29*J29 -> 10000 | N29: =Table23[[#This Row],[Rate]] -> 10000 | O29: 3 | P29: 0 | Q29: =N29*O29 -> 30000
B30: Depreciation uniform | D30: 600 | E30: ='Fianl All'!$E$25-E19 -> 104 | G30: =D30*E30 -> 62400 | I30: =Table23[[#This Row],[Rate]] -> 600 | J30: ='Fianl All'!$J$25-J19 -> 104 | K30: 0 | L30: =I30*J30 -> 62400 | N30: =Table23[[#This Row],[Rate]] -> 600 | O30: ='Fianl All'!$O$25-O19 -> 300 | P30: 0 | Q30: =N30*O30 -> 180000
B31: Total | F31: =Table23[[#Totals],[Monthly]]/G16 -> 0.0674802 | G31: =SUBTOTAL(109,Table24[Monthly]) -> 75150 | K31: =Table24[[#Totals],[Monthly]]/L16 -> 0.063406485 | L31: =SUBTOTAL(109,Table24[Monthly]) -> 75150 | P31: =Table25[[#Totals],[Monthly]]/Q16 -> 0.06980493 | Q31: =SUBTOTAL(109,Table25[Monthly]) -> 218250
B33: ICT & Others | D33: Rate | E33: Qty | F33: . | G33: Monthly | I33: Rate | J33: Qty | K33: . | L33: Monthly | N33: Rate | O33: Qty | P33: . | Q33: Monthly
B34: Software Account | D34: 8000 | E34: 1 | F34: 0 | G34: =D34*E34 -> 8000 | I34: =D34 -> 8000 | J34: 1 | L34: =I34*J34 -> 8000 | N34: =D34 -> 8000 | O34: 1 | Q34: =N34*O34 -> 8000 | T34: =D19/30 -> 966.66667
B35: Depreciation ICT | D35: 2500 | E35: 1 | F35: 0 | G35: =D35*E35 -> 2500 | I35: =D35 -> 2500 | J35: 1 | L35: =I35*J35 -> 2500 | N35: =D35 -> 2500 | O35: 2 | Q35: =N35*O35 -> 5000 | T35: =T34*16 -> 15466.667
B36: Arab Fees | D36: 16250 | E36: 1 | F36: 0 | G36: =D36*E36 -> 16250 | I36: =D36 -> 16250 | J36: 1 | L36: =I36*J36 -> 16250 | N36: =D36 -> 16250 | O36: 1.5 | Q36: =N36*O36 -> 24375 | T36: =T35/12 -> 1288.8889
B37: Over Head | D37: 30000 | E37: 1 | F37: 0 | G37: =D37*E37 -> 30000 | I37: =D37 -> 30000 | J37: 1 | L37: =I37*J37 -> 30000 | N37: =D37 -> 30000 | O37: 1.5 | Q37: =N37*O37 -> 45000
B38: Meals | D38: =30*30 -> 900 | E38: =Table1511[[#Totals],[Qty]] -> 87 | F38: 0 | G38: =D38*E38 -> 78300 | I38: =D38 -> 900 | J38: =Table2612[[#Totals],[Qty]] -> 87 | L38: =I38*J38 -> 78300 | N38: =D38 -> 900 | O38: =Table3713[[#Totals],[Qty]] -> 255 | Q38: =N38*O38 -> 229500
B39: Ramadan Meals (140-30)=110 Per Meals | D39: =110*30 -> 3300 | E39: =Table1511[[#Totals],[Qty]] -> 87 | G39: =(D39*E39)/12 -> 23925 | I39: =D39 -> 3300 | J39: =Table2612[[#Totals],[Qty]] -> 87 | L39: =(I39*J39)/12 -> 23925 | N39: =D39 -> 3300 | O39: =Table3713[[#Totals],[Qty]] -> 255 | Q39: =(N39*O39)/12 -> 70125
B40: Total | F40: =G40/G16 -> 0.12126681 | G40: =SUM(G34:G38) -> 135050 | K40: =L40/L16 -> 0.11394605 | L40: =SUM(L34:L38) -> 135050 | P40: =Q40/Q16 -> 0.099749886 | Q40: =SUM(Q34:Q38) -> 311875
B42: Accoumedation | D42: Rate | E42: Qty | F42: . | G42: Monthly | I42: Rate | J42: Qty | K42: . | L42: Monthly | N42: Rate | O42: Qty | P42: . | Q42: Monthly
B43: Rent Appartment | D43: 10000 | E43: 5 | F43: 0 | G43: =Table29[[#This Row],[Rate]]*Table29[[#This Row],[Qty]] -> 50000 | I43: =Table29[[#This Row],[Rate]] -> 10000 | J43: 5 | K43: 0 | L43: =Table2931[[#This Row],[Rate]]*Table2931[[#This Row],[Qty]] -> 50000 | N43: =Table29[[#This Row],[Rate]] -> 10000 | O43: 12 | P43: 0 | Q43: =Table2932[[#This Row],[Rate]]*Table2932[[#This Row],[Qty]] -> 120000
B44: Elec,Water,,, | D44: 1000 | E44: 5 | F44: 0 | G44: =Table29[[#This Row],[Rate]]*Table29[[#This Row],[Qty]] -> 5000 | I44: =Table29[[#This Row],[Rate]] -> 1000 | J44: 5 | K44: 0 | L44: =Table2931[[#This Row],[Rate]]*Table2931[[#This Row],[Qty]] -> 5000 | N44: =Table29[[#This Row],[Rate]] -> 1000 | O44: 12 | P44: 0 | Q44: =Table2932[[#This Row],[Rate]]*Table2932[[#This Row],[Qty]] -> 12000
B45: Depreciataion Furniture | D45: 10000 | E45: 1 | F45: 0 | G45: =Table29[[#This Row],[Rate]]*Table29[[#This Row],[Qty]] -> 10000 | I45: =Table29[[#This Row],[Rate]] -> 10000 | J45: 1 | K45: 0 | L45: =Table2931[[#This Row],[Rate]]*Table2931[[#This Row],[Qty]] -> 10000 | N45: =Table29[[#This Row],[Rate]] -> 10000 | O45: 4 | P45: 0 | Q45: =Table2932[[#This Row],[Rate]]*Table2932[[#This Row],[Qty]] -> 40000
B46: Total | F46: =Table29[[#Totals],[Monthly]]/G16 -> 0.058366108 | G46: =SUBTOTAL(109,Table29[Monthly]) -> 65000 | K46: =Table2931[[#Totals],[Monthly]]/L16 -> 0.054842602 | L46: =SUBTOTAL(109,Table2931[Monthly]) -> 65000 | P46: =Table2932[[#Totals],[Monthly]]/Q16 -> 0.055012362 | Q46: =SUBTOTAL(109,Table2932[Monthly]) -> 172000
...

Sheet MEP
B2: MEP Manpower | D2: Rate | E2: Qty | F2: Shift/Month | G2: Monthly | I2: Rate | J2: Qty | K2: Shift/Month | L2: Monthly | N2: Rate | O2: Qty | P2: Shift/Month | Q2: Monthly
B3: FM Manager | D3: 2419 | E3: 1 | F3: 30 | G3: =F3*E3*D3 -> 72570 | I3: 2760 | J3: 1 | K3: 30 | L3: =I3*F3*E3 -> 82800 | N3: 2760 | O3: 1 | P3: 30 | Q3: =P3*O3*N3 -> 82800
B4: Senior Engineer MEP | D4: 1573 | E4: 1 | F4: 30 | G4: =F4*E4*D4 -> 47190 | I4: 1794 | J4: 1 | K4: 30 | L4: =I4*F4*E4 -> 53820 | N4: 1794 | O4: 2 | P4: 30 | Q4: =P4*O4*N4 -> 107640
B5: Supervisor - Electrical | D5: 883 | E5: 1 | F5: 30 | G5: =F5*E5*D5 -> 26490 | I5: 1008 | J5: 1 | K5: 30 | L5: =I5*F5*E5 -> 30240 | N5: 1008 | O5: 2 | P5: 30 | Q5: =P5*O5*N5 -> 60480
B6: Supervisor - Mechanical | D6: 883 | E6: 1 | F6: 30 | G6: =F6*E6*D6 -> 26490 | I6: 1008 | J6: 1 | K6: 30 | L6: =I6*F6*E6 -> 30240 | N6: 1008 | O6: 2 | P6: 30 | Q6: =P6*O6*N6 -> 60480
B7: Supervisor - Light Current | D7: 883 | E7: 1 | F7: 30 | G7: =F7*E7*D7 -> 26490 | I7: 1008 | J7: 1 | K7: 30 | L7: =I7*F7*E7 -> 30240 | N7: 1008 | O7: 1 | P7: 30 | Q7: =P7*O7*N7 -> 30240
B8: Technician - Electrical | D8: 500 | E8: 3 | F8: 30 | G8: =F8*E8*D8 -> 45000 | I8: 577 | J8: 3 | K8: 30 | L8: =I8*F8*E8 -> 51930 | N8: 577 | O8: 5 | P8: 30 | Q8: =P8*O8*N8 -> 86550
B9: Technician - Mechanical | D9: 530 | E9: 1 | F9: 30 | G9: =F9*E9*D9 -> 15900 | I9: 604 | J9: 1 | K9: 30 | L9: =I9*F9*E9 -> 18120 | N9: 604 | O9: 2 | P9: 30 | Q9: =P9*O9*N9 -> 36240
B10: Technician - Pluming | D10: 491 | E10: 3 | F10: 30 | G10: =F10*E10*D10 -> 44190 | I10: 567 | J10: 3 | K10: 30 | L10: =I10*F10*E10 -> 51030 | N10: 567 | O10: 5 | P10: 30 | Q10: =P10*O10*N10 -> 85050
B11: Technician - light Current | D11: 545 | E11: 1 | F11: 30 | G11: =F11*E11*D11 -> 16350 | I11: 621 | J11: 1 | K11: 30 | L11: =I11*F11*E11 -> 18630 | N11: 621 | O11: 1 | P11: 30 | Q11: =P11*O11*N11 -> 18630
B12: CAFM - Coordinator | D12: 744 | E12: 1 | F12: 30 | G12: =F12*E12*D12 -> 22320 | I12: 849 | J12: 1 | K12: 30 | L12: =I12*F12*E12 -> 25470 | N12: 849 | O12: 1 | P12: 30 | Q12: =P12*O12*N12 -> 25470
B13: Painter | D13: 514 | E13: 1 | F13: 30 | G13: =F13*E13*D13 -> 15420 | I13: 587 | J13: 1 | K13: 30 | L13: =I13*F13*E13 -> 17610 | N13: 587 | O13: 2 | P13: 30 | Q13: =P13*O13*N13 -> 35220
B14: Carpenter | D14: 514 | E14: 1 | F14: 30 | G14: =F14*E14*D14 -> 15420 | I14: 587 | J14: 1 | K14: 30 | L14: =I14*F14*E14 -> 17610 | N14: 587 | O14: 2 | P14: 30 | Q14: =P14*O14*N14 -> 35220
... B19: Manlift | D19: 3628 | E19: 0 | F19: 30 | G19: =F19*E19*D19 -> 0 | I19: 4140 | J19: 0 | K19: 30 | L19: =I19*F19*E19 -> 0 | N19: 4140 | O19: 0 | P19: 30 | Q19: =P19*O19*N19 -> 0
B20: Total | E20: =SUBTOTAL(109,Table1[Qty]) -> 23 | G20: =SUBTOTAL(109,Table1[Monthly]) -> 501330 | J20: =SUBTOTAL(109,Table2[Qty]) -> 23 | L20: =SUBTOTAL(109,Table2[Monthly]) -> 572790 | O20: =SUBTOTAL(109,Table3[Qty]) -> 35 | Q20: =SUBTOTAL(109,Table3[Monthly]) -> 839670

Sheet Mobilization Budget
A2: City Gate - FMPLus Mobilization Area
A4: 1 | B4: Mobilization Area
B6: A | C6: Caravans
B8: # | C8: Caravan For | D8: Dimensions | E8: Cost | F8: Dep. Period | G8: Monthly Cost
B9: 1 | C9: Head Of Operations | D9: 3*6 M | E9: 50000 | F9: 24 | G9: =E9/F9 -> 2083.3333
B10: 2 | C10: Engineering Team | D10: 3*9 M | E10: 65000 | F10: 24 | G10: =E10/F10 -> 2708.3333
B11: 3 | C11: Helpdesk & admins | D11: 3*9 M | E11: 65000 | F11: 24 | G11: =E11/F11 -> 2708.3333
B12: 4 | C12: Quality Team | D12: 3*6 M | E12: 40000 | F12: 24 | G12: =E12/F12 -> 1666.6667
B13: 5 | C13: Meeting Room | D13: 3*6 M | E13: 40000 | F13: 24 | G13: =E13/F13 -> 1666.6667
B14: 6 | C14: Houskeeping Team | D14: 3*6 M | E14: 40000 | F14: 24 | G14: =E14/F14 -> 1666.6667
B15: 7 | C15: LS Team | D15: 3*6 M | E15: 40000 | F15: 24 | G15: =E15/F15 -> 1666.6667
B16: 8 | C16: Centralized Kitchen | D16: 3*6 M | E16: 40000 | F16: 24 | G16: =E16/F16 -> 1666.6667
B17: 9 | C17: Maintenance Team (Lockers Caravan) | D17: 3*12 M | E17: 105000 | F17: 24 | G17: =E17/F17 -> 4375
B18: 10 | C18: HK Team (Lockers Caravan) - Male | D18: 3*12 M | E18: 105000 | F18: 24 | G18: =E18/F18 -> 4375
B19: 11 | C19: HK Team (Lockers Caravan) - Female | D19: 3*3 M | E19: 50000 | F19: 24 | G19: =E19/F19 -> 2083.3333
B20: 12 | C20: LS Team (Lockers Caravan) | D20: 3*12 M | E20: 85000 | F20: 24 | G20: =E20/F20 -> 3541.6667
B21: 13 | C21: Security Management Team | D21: 3*9 M | E21: 85000 | F21: 24 | G21: =E21/F21 -> 3541.6667
B22: 14 | C22: Public Toilets Male | D22: 12 | E22: 12000 | F22: 24 | G22: =D22*E22/F22 -> 6000
B23: 15 | C23: Public Toilets Female | D23: 2 | E23: 15000 | F23: 24 | G23: =D23*E23/F23 -> 1250
B24: TOTAL | G24: =SUM(G9:G23) -> 41000
B26: B | C26: Containers / Stores
B28: # | C28: Container For | D28: Dimensions | E28: Cost | F28: Dep. Period | G28: Monthly Cost
B29: 1 | C29: MEP | D29: 3*12 M | E29: 60000 | F29: 24 | G29: =E29/F29 -> 2500
B30: 2 | C30: HK & Security | D30: 3*12 M | E30: 60000 | F30: 24 | G30: =E30/F30 -> 2500
B31: 3 | C31: Landscape | D31: 3*12 M | E31: 60000 | F31: 24 | G31: =E31/F31 -> 2500
B32: 4 | C32: Pest Control | D32: 3*6 M | E32: 60000 | F32: 24 | G32: =E32/F32 -> 2500
B33: 5 | C33: Uniform | D33: 3*12 M | E33: 60000 | F33: 24 | G33: =E33/F33 -> 2500
B34: TOTAL | G34: =SUM(G29:G33) -> 12500
B36: C | C36: Outdoor Area
B38: # | C38: Container For | D38: Dimensions | E38: Cost | F38: Dep. Period | G38: Monthly Cost
B39: 1 | C39: Car Parking Shade | D39: 3*16 M | E39: 123000 | F39: 24 | G39: =E39/F39 -> 5125
B40: 2 | C40: Outdoor Electrical Sockets | D40: LUM | E40: 20000 | F40: 24 | G40: =E40/F40 -> 833.33333
B41: 3 | C41: Outdoor Lighting | D41: LUM | E41: 20000 | F41: 24 | G41: =E41/F41 -> 833.33333
B42: 4 | C42: Outdoor Interlock & Landscape | D42: LUM | E42: 50000 | F42: 24 | G42: =E42/F42 -> 2083.3333
B43: 5 | C43: Concerete Base & Installation | D43: LUM | E43: 120000 | F43: 24 | G43: =E43/F43 -> 5000
B44: TOTAL | G44: =SUM(G39:G43) -> 13875
B46: D | C46: Furniture
B48: # | C48: Container For | D48: QTY | E48: Cost | F48: Dep. Period | G48: Monthly Cost
B49: 1 | C49: Office | D49: 6 | E49: 5000 | F49: 12 | G49: =(D49*E49)/F49 -> 2500
B50: 2 | C50: WorkSpace | D50: 10 | E50: 14000 | F50: 12 | G50: =(D50*E50)/F50 -> 11666.667
...

Sheet MEP Budget-Y1
B2: City Gate - MEP Budget (Year 1)
D4: Head Count | F4: Head Cost / CTC | H4: Monthly | J4: Annualy
B6: Direct Costs - As per Pricing Sheet | D6: Sheet HC | E6: Budget HC | L6: FMPlus Rate | N6: Rate / Shift
A7: 1 | B7: FM Manager | D7: 1 | E7: =ROUNDUP(D7+(D7/6),1) -> 1.2 | F7: 40000 | H7: =F7*E7 -> 48000 | J7: =H7*12 -> 576000 | L7: =H7/(1-D$68) -> 72558.647 | N7: =ROUNDUP(L7/D7/30,0) -> 2419
A8: 2 | B8: Senior Engineer MEP | D8: 1 | E8: =ROUNDUP(D8+(D8/6),1) -> 1.2 | F8: 26000 | H8: =F8*E8 -> 31200 | J8: =H8*12 -> 374400 | L8: =H8/(1-D$68) -> 47163.12 | N8: =ROUNDUP(L8/D8/30,0) -> 1573
A9: 3 | B9: Supervisor - Electrical | D9: 1 | E9: =ROUNDUP(D9+(D9/6),1) -> 1.2 | F9: 14600 | H9: =F9*E9 -> 17520 | J9: =H9*12 -> 210240 | L9: =H9/(1-D$68) -> 26483.906 | N9: =ROUNDUP(L9/D9/30,0) -> 883
A10: 4 | B10: Supervisor - Mechanical | D10: 1 | E10: =ROUNDUP(D10+(D10/6),1) -> 1.2 | F10: 14600 | H10: =F10*E10 -> 17520 | J10: =H10*12 -> 210240 | L10: =H10/(1-D$68) -> 26483.906 | N10: =ROUNDUP(L10/D10/30,0) -> 883
A11: 5 | B11: Supervisor - Light Current | D11: 1 | E11: =ROUNDUP(D11+(D11/6),1) -> 1.2 | F11: 14600 | H11: =F11*E11 -> 17520 | J11: =H11*12 -> 210240 | L11: =H11/(1-D$68) -> 26483.906 | N11: =ROUNDUP(L11/D11/30,0) -> 883
A12: 6 | B12: Technician - Electrical | D12: 3 | E12: =ROUNDUP(D12+(D12/6),1) -> 3.5 | F12: 8500 | H12: =F12*E12 -> 29750 | J12: =H12*12 -> 357000 | L12: =H12/(1-D$68) -> 44971.245 | N12: =ROUNDUP(L12/D12/30,0) -> 500
A13: 7 | B13: Technician - Mechanical | D13: 1 | E13: =ROUNDUP(D13+(D13/6),1) -> 1.2 | F13: 8750 | H13: =F13*E13 -> 10500 | J13: =H13*12 -> 126000 | L13: =H13/(1-D$68) -> 15872.204 | N13: =ROUNDUP(L13/D13/30,0) -> 530
A14: 8 | B14: Technician - Pluming | D14: 3 | E14: =ROUNDUP(D14+(D14/6),1) -> 3.5 | F14: 8350 | H14: =F14*E14 -> 29225 | J14: =H14*12 -> 350700 | L14: =H14/(1-D$68) -> 44177.634 | N14: =ROUNDUP(L14/D14/30,0) -> 491
A15: 9 | B15: Technician - light Current | D15: 1 | E15: =ROUNDUP(D15+(D15/6),1) -> 1.2 | F15: 9000 | H15: =F15*E15 -> 10800 | J15: =H15*12 -> 129600 | L15: =H15/(1-D$68) -> 16325.696 | N15: =ROUNDUP(L15/D15/30,0) -> 545
A16: 10 | B16: CAFM - Coordinator | D16: 1 | E16: =ROUNDUP(D16+(D16/6),1) -> 1.2 | F16: 12300 | H16: =F16*E16 -> 14760 | J16: =H16*12 -> 177120 | L16: =H16/(1-D$68) -> 22311.784 | N16: =ROUNDUP(L16/D16/30,0) -> 744
A17: 11 | B17: Painter | D17: 1 | E17: =ROUNDUP(D17+(D17/6),1) -> 1.2 | F17: 8500 | H17: =F17*E17 -> 10200 | J17: =H17*12 -> 122400 | L17: =H17/(1-D$68) -> 15418.712 | N17: =ROUNDUP(L17/D17/30,0) -> 514
A18: 12 | B18: Carpenter | D18: 1 | E18: =ROUNDUP(D18+(D18/6),1) -> 1.2 | F18: 8500 | H18: =F18*E18 -> 10200 | J18: =H18*12 -> 122400 | L18: =H18/(1-D$68) -> 15418.712 | N18: =ROUNDUP(L18/D18/30,0) -> 514
... A23: 17 | B23: Manlift | D23: 1 | E23: =ROUNDUP(D23+(D23/6),1) -> 1.2 | F23: 60000 | H23: =F23*E23 -> 72000 | J23: =H23*12 -> 864000 | L23: =H23/(1-D$68) -> 108837.97 | N23: =ROUNDUP(L23/D23/30,0) -> 3628
B24: Total Direct Manpower - As Per Pricing Sheet | D24: =SUM(D7:D23) -> 24 | E24: =SUM(E7:E23) -> 28.5 | H24: =SUM(H7:H23) -> 403515 | J24: =SUM(J7:J23) -> 4842180 | L24: =SUM(L7:L23) -> 609968.8 | N24: Should Be Same
B26: Indirect Costs
A27: A | B27: MEP - Tools + Equipment
A28: 1 | B28: Electrical Tools | E28: 1 | F28: 2000 | H28: =E28*F28 -> 2000 | J28: =H28*12 -> 24000
A29: 2 | B29: Carpentry Tools | E29: 1 | F29: 1500 | H29: =E29*F29 -> 1500 | J29: =H29*12 -> 18000
A30: 3 | B30: Plumbing Tools | E30: 1 | F30: 1500 | H30: =E30*F30 -> 1500 | J30: =H30*12 -> 18000
A31: 4 | B31: Light Current Tools | E31: 1 | F31: 1500 | H31: =E31*F31 -> 1500 | J31: =H31*12 -> 18000
A32: 5 | B32: Mechanical Tools | E32: 1 | F32: 3300 | H32: =E32*F32 -> 3300 | J32: =H32*12 -> 39600
A33: 6 | B33: Water features Tools | E33: 1 | F33: 3300 | H33: =E33*F33 -> 3300 | J33: =H33*12 -> 39600
A34: 7 | B34: MEP Shared Equipment | E34: 1 | F34: 9000 | H34: =E34*F34 -> 9000 | J34: =H34*12 -> 108000
A35: B | B35: MEP - Consumables
A36: 1 | B36: Electrical | E36: 1 | F36: 2000 | H36: =F36*E36 -> 2000 | J36: =H36*12 -> 24000
A37: 2 | B37: Plumbing | E37: 1 | F37: 2000 | H37: =F37*E37 -> 2000 | J37: =H37*12 -> 24000
A38: 3 | B38: Civil | E38: 1 | F38: 1000 | H38: =F38*E38 -> 1000 | J38: =H38*12 -> 12000
A39: 4 | B39: LC | E39: 1 | F39: 1500 | H39: =F39*E39 -> 1500 | J39: =H39*12 -> 18000
A40: 5 | B40: Mechanical Including Oil Filters …etc | E40: 1 | F40: 7500 | H40: =F40*E40 -> 7500 | J40: =H40*12 -> 90000
A41: C | B41: Chemicals - Consumables
A42: 1 | B42: Chlorine | E42: 1 | F42: 5600 | H42: =F42*E42 -> 5600 | J42: =H42*12 -> 67200
A43: 2 | B43: Aliga Cide | E43: 1 | F43: 2300 | H43: =F43*E43 -> 2300 | J43: =H43*12 -> 27600
A44: 3 | B44: PH Modifier | E44: 1 | F44: 3000 | H44: =F44*E44 -> 3000 | J44: =H44*12 -> 36000
A45: 4 | B45: Water Softner | E45: 1 | F45: 1000 | H45: =F45*E45 -> 1000 | J45: =H45*12 -> 12000
A46: 5 | B46: Others | E46: 1 | F46: 2000 | H46: =F46*E46 -> 2000 | J46: =H46*12 -> 24000
A47: D | B47: Water Tanks - Cleaning & Disinfection
A48: 1 | B48: Zone 2D | E48: 1 | F48: 13000 | H48: =F48*E48 -> 13000 | J48: =H48*12 -> 156000
...

Sheet MEP Budget-Y2
B2: City Gate - MEP Budget (Year 2)
D4: Head Count | F4: Head Cost / CTC | H4: Monthly | J4: Annualy
B6: Direct Costs - As per Pricing Sheet | D6: Sheet HC | E6: Budget HC | L6: FMPlus Rate | N6: Rate / Shift
A7: 1 | B7: FM Manager | D7: 1 | E7: =ROUNDUP(D7+(D7/6),1) -> 1.2 | F7: ='MEP Budget-Y1'!F7*1.1 -> 44000 | H7: =F7*E7 -> 52800 | J7: =H7*12 -> 633600 | L7: =H7/(1-D$69) -> 82788.457 | N7: =ROUNDUP(L7/D7/30,0) -> 2760
A8: 2 | B8: Senior Engineer MEP | D8: 2 | E8: =ROUNDUP(D8+(D8/6),1) -> 2.4 | F8: ='MEP Budget-Y1'!F8*1.1 -> 28600 | H8: =F8*E8 -> 68640 | J8: =H8*12 -> 823680 | L8: =H8/(1-D$69) -> 107624.99 | N8: =ROUNDUP(L8/D8/30,0) -> 1794
A9: 3 | B9: Supervisor - Electrical | D9: 2 | E9: =ROUNDUP(D9+(D9/6),1) -> 2.4 | F9: ='MEP Budget-Y1'!F9*1.1 -> 16060 | H9: =F9*E9 -> 38544 | J9: =H9*12 -> 462528 | L9: =H9/(1-D$69) -> 60435.574 | N9: =ROUNDUP(L9/D9/30,0) -> 1008
