Workbook
Name Datew: '[1]12%'!$A$6:$A$101

Sheet HK Budget (2)
B3: UTC HK Budget
B4: Items | D4: Total Amount/ Month | I4: Sierras | J4: Alto | K4: Aurora | L4: Fourteen | M4: Reyna | N4: Eleva | O4: Isadore | P4: Alba's Aliyah | Q4: Alba's Spendia | R4: Commercial Area "UTC-Golf club house | S4: Public Roads | T4: Crossing gates | U4: Mobilization areas " water station " | V4: Managament"sales center"
B6: Head Count Cost | D6: ='Manpower Cost'!F16 -> 1251640 | F6: =D6-(I6+J6+K6+L6+M6+N6+O6+P6+Q6+R6+S6+T6+U6+V6) -> 0 | I6: ='Manpower Cost'!L16 -> 209286.45 | J6: ='Manpower Cost'!N16 -> 105385.54 | K6: ='Manpower Cost'!P16 -> 110169.34 | L6: ='Manpower Cost'!R16 -> 204832.57 | M6: ='Manpower Cost'!T16 -> 49635.278 | N6: ='Manpower Cost'!V16 -> 37223.651 | O6: ='Manpower Cost'!X16 -> 27917.738 | P6: ='Manpower Cost'!Z16 -> 36447.222 | Q6: ='Manpower Cost'!AB16 -> 36447.222 | R6: ='Manpower Cost'!AD16 -> 99270.556 | S6: ='Manpower Cost'!AF16 -> 9111.8056 | T6: ='Manpower Cost'!AH16 -> 54670.833 | U6: ='Manpower Cost'!AJ16 -> 9111.8056 | V6: ='Manpower Cost'!AL16 -> 262130
B7: Equipment & Tools Cost | D7: ='Equipment & Tools Cost'!G52 -> 448150.28 | F7: =D7-(I7+J7+K7+L7+M7+N7+O7+P7+Q7+R7+S7+T7+U7+V7) -> 0 | I7: ='Equipment & Tools Cost'!M52 -> 75883.604 | J7: ='Equipment & Tools Cost'!O52 -> 40131.834 | K7: ='Equipment & Tools Cost'!Q52 -> 41549.942 | L7: ='Equipment & Tools Cost'!S52 -> 73702.856 | M7: ='Equipment & Tools Cost'!U52 -> 16526.184 | N7: ='Equipment & Tools Cost'!W52 -> 13030.725 | O7: ='Equipment & Tools Cost'!Y52 -> 10375.266 | P7: ='Equipment & Tools Cost'!AA52 -> 12655.725 | Q7: ='Equipment & Tools Cost'!AC52 -> 11905.725 | R7: ='Equipment & Tools Cost'!AE52 -> 35356.256 | S7: ='Equipment & Tools Cost'!AG52 -> 4262.6812 | T7: ='Equipment & Tools Cost'!AI52 -> 15687.754 | U7: ='Equipment & Tools Cost'!AK52 -> 3044.6256 | V7: ='Equipment & Tools Cost'!AM52 -> 94037.101
B8: Consumables Cost | D8: ='Consumables Cost '!G33 -> 71385 | F8: =D8-(I8+J8+K8+L8+M8+N8+O8+P8+Q8+R8+S8+T8+U8+V8) -> 0 | I8: ='Consumables Cost '!M33 -> 10000 | J8: ='Consumables Cost '!O33 -> 5150 | K8: ='Consumables Cost '!Q33 -> 5850 | L8: ='Consumables Cost '!S33 -> 10150 | M8: ='Consumables Cost '!U33 -> 2175 | N8: ='Consumables Cost '!W33 -> 1750 | O8: ='Consumables Cost '!Y33 -> 1750 | P8: ='Consumables Cost '!AA33 -> 1750 | Q8: ='Consumables Cost '!AC33 -> 2125 | R8: ='Consumables Cost '!AE33 -> 12725 | S8: ='Consumables Cost '!AG33 -> 870 | T8: ='Consumables Cost '!AI33 -> 2225 | U8: ='Consumables Cost '!AK33 -> 340 | V8: ='Consumables Cost '!AM33 -> 14525
B9: Transportation Cost | D9: ='Transportation Cost'!G14 -> 369000 | F9: =D9-(I9+J9+K9+L9+M9+N9+O9+P9+Q9+R9+S9+T9+U9+V9) -> 0 | I9: ='Transportation Cost'!M14 -> 62182.701 | J9: ='Transportation Cost'!O14 -> 31347.364 | K9: ='Transportation Cost'!Q14 -> 32997.225 | L9: ='Transportation Cost'!S14 -> 60646.623 | M9: ='Transportation Cost'!U14 -> 13369.565 | N9: ='Transportation Cost'!W14 -> 10695.652 | O9: ='Transportation Cost'!Y14 -> 8021.7391 | P9: ='Transportation Cost'!AA14 -> 10695.652 | Q9: ='Transportation Cost'!AC14 -> 10695.652 | R9: ='Transportation Cost'!AE14 -> 26739.13 | S9: ='Transportation Cost'!AG14 -> 2673.913 | T9: ='Transportation Cost'!AI14 -> 16043.478 | U9: ='Transportation Cost'!AK14 -> 2673.913 | V9: ='Transportation Cost'!AM14 -> 80217.391
B10: Mobilization & Over Head Cost | D10: ='Mobilization & Over Head Cost'!G14 -> 34444.444 | F10: =D10-(I10+J10+K10+L10+M10+N10+O10+P10+Q10+R10+S10+T10+U10+V10) -> 0 | I10: ='Mobilization & Over Head Cost'!M14 -> 5804.4677 | J10: ='Mobilization & Over Head Cost'!O14 -> 2926.1315 | K10: ='Mobilization & Over Head Cost'!Q14 -> 3080.1384 | L10: ='Mobilization & Over Head Cost'!S14 -> 5661.082 | M10: ='Mobilization & Over Head Cost'!U14 -> 1247.9871 | N10: ='Mobilization & Over Head Cost'!W14 -> 998.38969 | O10: ='Mobilization & Over Head Cost'!Y14 -> 748.79227 | P10: ='Mobilization & Over Head Cost'!AA14 -> 998.38969 | Q10: ='Mobilization & Over Head Cost'!AC14 -> 998.38969 | R10: ='Mobilization & Over Head Cost'!AE14 -> 2495.9742 | S10: ='Mobilization & Over Head Cost'!AG14 -> 249.59742 | T10: ='Mobilization & Over Head Cost'!AI14 -> 1497.5845 | U10: ='Mobilization & Over Head Cost'!AK14 -> 249.59742 | V10: ='Mobilization & Over Head Cost'!AM14 -> 7487.9227
B11: Others Cost | D11: ='Others Cost '!G12 -> 37500 | F11: =D11-(I11+J11+K11+L11+M11+N11+O11+P11+Q11+R11+S11+T11+U11+V11) -> 0 | I11: ='Others Cost '!M12 -> 6319.3802 | J11: ='Others Cost '!O12 -> 3185.7077 | K11: ='Others Cost '!Q12 -> 3353.3765 | L11: ='Others Cost '!S12 -> 6163.2747 | M11: ='Others Cost '!U12 -> 1358.6957 | N11: ='Others Cost '!W12 -> 1086.9565 | O11: ='Others Cost '!Y12 -> 815.21739 | P11: ='Others Cost '!AA12 -> 1086.9565 | Q11: ='Others Cost '!AC12 -> 1086.9565 | R11: ='Others Cost '!AE12 -> 2717.3913 | S11: ='Others Cost '!AG12 -> 271.73913 | T11: ='Others Cost '!AI12 -> 1630.4348 | U11: ='Others Cost '!AK12 -> 271.73913 | V11: ='Others Cost '!AM12 -> 8152.1739
B12: Facades Cleaning | D12: ='Facades Cleaning Cost'!G14 -> 134750 | F12: =D12-(I12+J12+K12+L12+M12+N12+O12+P12+Q12+R12+S12+T12+U12+V12) -> 0 | I12: ='Facades Cleaning Cost'!M14 -> 63250 | J12: ='Facades Cleaning Cost'!O14 -> 14625 | K12: ='Facades Cleaning Cost'!Q14 -> 11375 | L12: ='Facades Cleaning Cost'!S14 -> 45500
B13: Total Cost | D13: =SUM(D6:D12) -> 2346869.7 | F13: =D13-(I13+J13+K13+L13+M13+N13+O13+P13+Q13+R13+S13+T13+U13+V13) -> 0 | I13: =SUM(I6:I12) -> 432726.6 | J13: =SUM(J6:J12) -> 202751.57 | K13: =SUM(K6:K12) -> 208375.02 | L13: =SUM(L6:L12) -> 406656.4 | M13: =SUM(M6:M12) -> 84312.709 | N13: =SUM(N6:N12) -> 64785.374 | O13: =SUM(O6:O12) -> 49628.753 | P13: =SUM(P6:P12) -> 63633.945 | ... V13: =SUM(V6:V12) -> 466549.59
B14: Gross Margin & Contingency 2% | C14: 0.08 | D14: =D13*$C$14 -> 187749.58 | F14: =D14-(I14+J14+K14+L14+M14+N14+O14+P14+Q14+R14+S14+T14+U14+V14) -> -14752.18 | I14: =I13*$C$14 -> 34618.128 | J14: =J13*$C$14 -> 16220.126 | K14: =K13*$C$14 -> 16670.002 | L14: =L13*$C$14 -> 32532.512 | M14: =M13*$C$14 -> 6745.0167 | N14: =N13*$C$14 -> 5182.8299 | O14: =O13*$C$14 -> 3970.3002 | P14: =P13*$C$14 -> 5090.7156 | Q14: =Q13*$C$14 -> 5060.7156 | R14: =R13*10% -> 17930.431 | S14: =S13*$C$14 -> 1395.1789 | T14: =T13*10% -> 9175.5085 | U14: =U13*$C$14 -> 1255.3345 | V14: =V13*10% -> 46654.959
B15: Total | D15: =SUM(D13:D14) -> 2534619.3 | F15: =D15-(I15+J15+K15+L15+M15+N15+O15+P15+Q15+R15+S15+T15+U15+V15) -> -14752.18 | I15: =SUM(I13:I14) -> 467344.73 | J15: =SUM(J13:J14) -> 218971.7 | K15: =SUM(K13:K14) -> 225045.02 | L15: =SUM(L13:L14) -> 439188.91 | M15: =SUM(M13:M14) -> 91057.726 | N15: =SUM(N13:N14) -> 69968.204 | O15: =SUM(O13:O14) -> 53599.053 | P15: =SUM(P13:P14) -> 68724.661 | ... V15: =SUM(V13:V14) -> 513204.55
B16: Insurance | C16: 0.014 | D16: =D15*$C$16 -> 35484.67 | E16: =D16*36 -> 1277448.1 | F16: =D16-(I16+J16+K16+L16+M16+N16+O16+P16+Q16+R16+S16+T16+U16+V16) -> -206.53051 | I16: =I15*$C$16 -> 6542.8262 | J16: =J15*$C$16 -> 3065.6038 | K16: =K15*$C$16 -> 3150.6303 | L16: =L15*$C$16 -> 6148.6448 | M16: =M15*$C$16 -> 1274.8082 | N16: =N15*$C$16 -> 979.55485 | O16: =O15*$C$16 -> 750.38674 | P16: =P15*$C$16 -> 962.14525 | ... V16: =V15*$C$16 -> 7184.8637
B17: Total Revenue | D17: =SUM(D15:D16) -> 2570104 | F17: =D17-(I17+J17+K17+L17+M17+N17+O17+P17+Q17+R17+S17+T17+U17+V17) -> -14958.71 | I17: =SUM(I15:I16) -> 473887.56 | J17: =SUM(J15:J16) -> 222037.3 | K17: =SUM(K15:K16) -> 228195.65 | L17: =SUM(L15:L16) -> 445337.56 | M17: =SUM(M15:M16) -> 92332.534 | N17: =SUM(N15:N16) -> 70947.759 | O17: =SUM(O15:O16) -> 54349.44 | P17: =SUM(P15:P16) -> 69686.806 | ... V17: =SUM(V15:V16) -> 520389.41
B18: VAT | C18: 0.14 | D18: =D17*$C$18 -> 359814.56 | F18: =D18-(I18+J18+K18+L18+M18+N18+O18+P18+Q18+R18+S18+T18+U18+V18) -> -2094.2194 | I18: =I17*$C$18 -> 66344.258 | J18: =J17*$C$18 -> 31085.223 | K18: =K17*$C$18 -> 31947.391 | L18: =L17*$C$18 -> 62347.258 | M18: =M17*$C$18 -> 12926.555 | N18: =N17*$C$18 -> 9932.6862 | O18: =O17*$C$18 -> 7608.9215 | P18: =P17*$C$18 -> 9756.1529 | ... V18: =V17*$C$18 -> 72854.518
B19: Total W VAT | D19: =D17+D18 -> 2929918.5 | E19: =D19-2999479.74459467 -> -69561.219 | F19: =D19-(I19+J19+K19+L19+M19+N19+O19+P19+Q19+R19+S19+T19+U19+V19) -> -17052.93 | I19: =I17+I18 -> 540231.81 | J19: =J17+J18 -> 253122.53 | K19: =K17+K18 -> 260143.04 | L19: =L17+L18 -> 507684.82 | M19: =M17+M18 -> 105259.09 | N19: =N17+N18 -> 80880.445 | O19: =O17+O18 -> 61958.361 | P19: =P17+P18 -> 79442.959 | ... V19: =V17+V18 -> 593243.93
D20: =3000000 -> 3000000 | E20: =D20*36*0.02 -> 2160000
D21: =D19-D20 -> -70081.474
C22: =C23+C49+C43+F36+F37+F38+F39 -> 2929918.5 | D22: =D21/D19 -> -0.023919257
C23: =C24+C36+C31 -> 1586411.5
B24: Direct Cost | C24: =C25+C26+C27+C28+C29+C30+C32+C33+C34 -> 1447462.5 | J24: Unit Rate
B25: Labors Morning Shift | C25: ='Manpower Cost'!AS6 -> 741671.33 | D25: =C25/$C$24 -> 0.51239417 | F25: =(D25*$C$36)+(D25*$F$36)+(D25*$F$37)+(D25*$F$38)+(D25*$F$39) -> 79840.281 | H25: ='Manpower Cost'!C6 -> 94 | I25: =C25+F25 -> 821511.62 | J25: =I25/H25 -> 8739.4853
B26: Labors Noon Shift | C26: ='Manpower Cost'!AS7 -> 110461.69 | D26: =C26/$C$24 -> 0.076314025 | F26: =(D26*$C$36)+(D26*$F$36)+(D26*$F$37)+(D26*$F$38)+(D26*$F$39) -> 11891.106 | H26: ='Manpower Cost'!C7 -> 14 | I26: =C26+F26 -> 122352.79 | J26: =I26/H26 -> 8739.4853
B27: Supervisor Morning Shift | C27: ='Manpower Cost'!AS8 -> 149275.59 | D27: =C27/$C$24 -> 0.10312916 | F27: =(D27*$C$36)+(D27*$F$36)+(D27*$F$37)+(D27*$F$38)+(D27*$F$39) -> 16069.389 | H27: ='Manpower Cost'!C8 -> 11 | I27: =C27+F27 -> 165344.98 | J27: =I27/H27 -> 15031.362
B28: Supervisor Noon Shift | C28: ='Manpower Cost'!AS9 -> 40711.524 | D28: =C28/$C$24 -> 0.028126134 | F28: =(D28*$C$36)+(D28*$F$36)+(D28*$F$37)+(D28*$F$38)+(D28*$F$39) -> 4382.5605 | H28: ='Manpower Cost'!C9 -> 3 | I28: =C28+F28 -> 45094.085 | J28: =I28/H28 -> 15031.362
B29: Site Admin | C29: ='Manpower Cost'!AS10-10000 -> 32247.101 | D29: =C29/$C$24 -> 0.022278368 | F29: =(D29*$C$36)+(D29*$F$36)+(D29*$F$37)+(D29*$F$38)+(D29*$F$39) -> 3471.3727 | H29: ='Manpower Cost'!C10 -> 2 | I29: =C29+F29 -> 35718.474 | J29: =I29/H29 -> 17859.237
B30: Site Assistant | C30: ='Manpower Cost'!AS11-30000 -> 55842.514 | D30: =C30/$C$24 -> 0.038579593 | F30: =(D30*$C$36)+(D30*$F$36)+(D30*$F$37)+(D30*$F$38)+(D30*$F$39) -> 6011.3986 | H30: ='Manpower Cost'!C11 -> 3 | I30: =C30+F30 -> 61853.913 | J30: =I30/H30 -> 20617.971
B31: Site Manager | C31: =('Manpower Cost'!AS12-16000) -> 49130.948 | F31: =(D31*$C$36)+(D31*$F$36)+(D31*$F$37)+(D31*$F$38)+(D31*$F$39) -> 0 | H31: ='Manpower Cost'!C12 -> 1 | I31: =C31+F31 -> 49130.948 | J31: =I31/H31 -> 49130.948
B32: Sales Center Labor | C32: ='Manpower Cost'!AS13 -> 255430.17 | D32: =C32/$C$24 -> 0.17646756 | F32: =(D32*$C$36)+(D32*$F$36)+(D32*$F$37)+(D32*$F$38)+(D32*$F$39) -> 27496.838 | H32: ='Manpower Cost'!C13 -> 30 | I32: =C32+F32 -> 282927.01 | J32: =I32/H32 -> 9430.9002
B33: Sales Center supervisor | C33: ='Manpower Cost'!AS14 -> 42584.179 | D33: =C33/$C$24 -> 0.029419885 | F33: =(D33*$C$36)+(D33*$F$36)+(D33*$F$37)+(D33*$F$38)+(D33*$F$39) -> 4584.1503 | H33: ='Manpower Cost'!C14 -> 3 | I33: =C33+F33 -> 47168.33 | J33: =I33/H33 -> 15722.777
B34: Sales Center Assistant Manager | C34: ='Manpower Cost'!AS15-10000 -> 19238.39 | D34: =C34/$C$24 -> 0.013291115 | F34: =(D34*$C$36)+(D34*$F$36)+(D34*$F$37)+(D34*$F$38)+(D34*$F$39) -> 2070.9961 | H34: ='Manpower Cost'!C15 -> 1 | I34: =C34+F34 -> 21309.386 | J34: =I34/H34 -> 21309.386
B36: Indirect Cost | C36: =C37+C38+C39+C40 -> 89818.092 | F36: 16000 | I36: =SUM(I25:I35) -> 1652411.5
C37: =D10+D11 -> 71944.444 | F37: 30000
C38: =C37*C14 -> 5755.5556 | F38: 10000 | I38: =I39+I40+I41+I42 -> 2281311.6
C39: =(C37+C38)*C16 -> 1087.8 | F39: 10000 | I39: =D6+D9+D10+D11+D12 -> 1827334.4
C40: =(C37+C38+C39)*C18 -> 11030.292 | I40: =I39*C14 -> 146186.76
I41: =(I39+I40)*C16 -> 27629.297
I42: =(I39+I40+I41)*C18 -> 280161.07
B43: Equipmet, Tools & Consumables | C43: =SUM(C44:C47) -> 816833.82 | D43: =C43-V43 -> 681300.9 | E43: ='BOQ Basic -Residential'!D20+'BOQ Basic -Residential'!D21+'BOQ Basic -Residential'!D22+'BOQ Basic -Residential'!D23+'BOQ Basic -Residential'!D24+'BOQ Basic -Residential'!D25+'BOQ Basic -Residential'!D26+'BOQ Basic -Residential'!D27+'BOQ Basic -Residential'!D28+'BOQ Basic -Residential'!D29+'BOQ Basic -Residential'!D30+'BOQ Basic -Residential'!D31+'BOQ Basic -Residential'!D32+'BOQ Basic -Residential'!D33 -> 590228.86 | V43: =V44+V45+V46+V47 -> 135532.92 | W43: ='BOQ Basic -Residential'!D35+'BOQ Basic -Residential'!D36+'BOQ Basic -Residential'!D37+'BOQ Basic -Residential'!D38+'BOQ Basic -Residential'!D39+'BOQ Basic -Residential'!D40+'BOQ Basic -Residential'!D41+'BOQ Basic -Residential'!D42+'BOQ Basic -Residential'!D43+'BOQ Basic -Residential'!D44+'BOQ Basic -Residential'!D45+'BOQ Basic -Residential'!D46 -> 13123
C44: =D7+D8+D12 -> 654285.28 | V44: =V7+V8 -> 108562.1
...

Sheet BOQ Basic -Residential (2)
A4: Basic Scope Residential | B4: All Season | C4: Unit Rate | D4: Monthly Fee
A5: Item | B5: QTY
A6: Labors | B6: 94 | C6: 8739.4853 | D6: =C6*$B6 -> 821511.62 | E6: 8894.1264 | F6: 836047.89 | G6: =E6-C6 -> 154.64118 | H6: =F6-D6 -> 14536.271
A7: Supervisor | B7: 11 | C7: 15031.362 | D7: =C7*$B7 -> 165344.98 | E7: 15297.335 | F7: 168270.68 | H7: =F7-D7 -> 2925.7034
A8: Labors Night Shift | B8: 14 | C8: 8739.4853 | D8: =C8*$B8 -> 122352.79 | E8: 8894.1264 | F8: 124517.77 | H8: =F8-D8 -> 2164.9765
A9: Supervisor Night Shift | B9: 3 | C9: 15031.362 | D9: =C9*$B9 -> 45094.085 | E9: 15297.335 | F9: 45892.004 | H9: =F9-D9 -> 797.91911
A10: Site Manager | B10: 1 | C10: 49130.948 | D10: =C10*$B10 -> 49130.948 | E10: 50337.077 | F10: 50337.077 | H10: =F10-D10 -> 1206.1287
A11: Site Assistant | B11: 3 | C11: 20617.971 | D11: =C11*$B11 -> 61853.913 | E11: 21187.751 | F11: 63563.252 | H11: =F11-D11 -> 1709.3394
A12: Site Admin | B12: 2 | C12: 17859.237 | D12: =C12*$B12 -> 35718.474 | E12: 18277.725 | F12: 36555.45 | H12: =F12-D12 -> 836.97626
A13: Sales Center Labor- Morning Shift | B13: 19 | C13: 9597.7757 | D13: =C13*$B13 -> 182357.74 | E13: 9597.7757 | F13: 182357.74 | H13: =F13-D13 -> 0 | I13: In House team Mandatory
A14: Sales Center Labor- Night Shift | B14: 11 | C14: 9597.7757 | D14: =C14*$B14 -> 105575.53 | E14: 9597.7757 | F14: 105575.53 | H14: =F14-D14 -> 0
A15: Sales Center supervisor- Morning Shift | B15: 2 | C15: 16000.984 | D15: =C15*$B15 -> 32001.968 | E15: 16000.984 | F15: 32001.968 | H15: =F15-D15 -> 0
A16: Sales Center supervisor- Night Shift | B16: 1 | C16: 16000.984 | D16: =C16*$B16 -> 16000.984 | E16: 16000.984 | F16: 16000.984 | H16: =F16-D16 -> 0
A17: Sales Center Assistant Manager | B17: 1 | C17: 21891.4 | D17: =C17*$B17 -> 21891.4 | E17: 21891.4 | F17: 21891.4 | H17: =F17-D17 -> 0
A18: Transportation | B18: LS | C18: 469204.16 | D18: =C18 -> 469204.16 | E18: 469204.16 | F18: 469204.16 | H18: =F18-D18 -> 0
A19: Manpower | D19: =SUM(D6:D18) -> 2128038.6 | F19: 2152215.9 | H19: =F19-D19 -> 24177.314
A20: Façade Cleaning service " as per site need max. 168 buildings per year" | B20: 14 | C20: 12238.727 | D20: =C20*$B20 -> 171342.17 | E20: 12238.727 | F20: 171342.17 | H20: =F20-D20 -> 0 | I20: Total Buildings 56 & 3 times per year
A21: Single disk | B21: 5 | C21: 1249 | D21: =C21*$B21 -> 6245 | E21: 1272 | F21: 6360 | H21: =F21-D21 -> 115
A22: Vacuum | B22: 6 | C22: 729 | D22: =C22*$B22 -> 4374 | E22: 742 | F22: 4452 | H22: =F22-D22 -> 78
A23: Manual sweeper | B23: 10 | C23: 937 | D23: =C23*$B23 -> 9370 | E23: 954 | F23: 9540 | H23: =F23-D23 -> 170
A24: McClean Trolley | B24: 14 | C24: 387 | D24: =C24*$B24 -> 5418 | E24: 394 | F24: 5516 | H24: =F24-D24 -> 98
A25: Black Broom and Closed Ban | B25: 23 | C25: 94 | D25: =C25*$B25 -> 2162 | E25: 96 | F25: 2208 | H25: =F25-D25 -> 46
A26: Litter Picking Steak | B26: 12 | C26: 105 | D26: =C26*$B26 -> 1260 | E26: 106 | F26: 1272 | H26: =F26-D26 -> 12
A27: Mob Bucket with Cotton Cloth | B27: 25 | C27: 63 | D27: =C27*$B27 -> 1575 | E27: 64 | F27: 1600 | H27: =F27-D27 -> 25
A28: Water Fed Telescope (20 Meter) | B28: 2 | C28: 7907 | D28: =C28*$B28 -> 15814 | E28: 8054 | F28: 16108 | H28: =F28-D28 -> 294
A29: High Pressure Set One Car, Driver, 1K Liter tank" -30 days" | B29: 2 | C29: 64999 | D29: =C29*$B29 -> 129998 | E29: 64999 | F29: 129998 | H29: =F29-D29 -> 0
A30: Man Lift 15M" *30 days" | B30: 2 | C30: 68970 | D30: =C30*$B30 -> 137940 | E30: 68970 | F30: 137940 | H30: =F30-D30 -> 0
A31: Pick up Car with driver | B31: 2 | C31: 53406 | D31: =C31*$B31 -> 106812 | E31: 53406 | F31: 106812 | H31: =F31-D31 -> 0
A32: Public trolly for Building | B32: 25 | C32: 278 | D32: =C32*$B32 -> 6950 | E32: 283 | F32: 7075 | H32: =F32-D32 -> 125
... A47: Sales Center - Consumables & tools & Chemical Rates | B47: 1 | C47: 64044.588 | D47: =C47*$B47 -> 64044.588 | E47: 65244.96 | F47: 65244.96 | H47: =F47-D47 -> 1200.372
A48: Equipment | D48: =SUM(D20:D47) -> 826761.13 | F48: 831960.37 | H48: =F48-D48 -> 5199.24
A49: Grand Total | D49: =D48+D19 -> 2954799.7 | F49: 2984176.3 | H49: =F49-D49 -> 29376.554 | I49: =H49/F49 -> 0.0098441082
A50: First Year | D50: =D49*12 -> 35457597 | F50: 35810115 | H50: =F50-D50 -> 352518.65 | I50: =H50/F50 -> 0.0098441082
A51: Second Year | D51: =D50*1.1 -> 39003356
A52: Third Year | D52: =D51*1.1 -> 42903692 | G52: =D49-'BOQ A (2)'!G17 -> 0
A53: Grand Total | D53: =SUM(D50:D52) -> 1.1736464e+08

Sheet BOQ A (2)
B2: Scope | C2: # | D2: UPTWON CAIRO-ZONE A | E2: Description (Housekeeping) | F2: Duration | G2: Monthly Rate | H2: Amount
B3: Basic Scope | C3: 1 | D3: Sierras | E3: Sierras Building, Entrance,Furniture, Corridors, Stairs, Handrails, Walls, Elevators, Ceiling, Roofs and Roads, Parking, Asphalt, Walk Ways, as well as Littering in public landscape. | F3: 12 | G3: 542381.07 | H3: =G3*F3 -> 6508572.8 | I3: =G3*$Q$42 -> 0 | K3: 920624.36 | L3: =G3-K3 -> -378243.3 | M3: =L3/G3 -> -0.69737556 | O3: =G3+I3 -> 542381.07
C4: 2 | D4: Alto | E4: Alto Building, Entrance,Furniture, Corridors, Stairs, Handrails, Walls, Elevators, Ceiling, Roofs and Roads, Parking, Asphalt, Walk Ways, as well as Littering in public landscape. | F4: 12 | G4: 254129.55 | H4: =G4*F4 -> 3049554.6 | I4: =G4*$Q$42 -> 0 | K4: 371983.73 | L4: =G4-K4 -> -117854.18 | M4: =L4/G4 -> -0.46375632 | O4: =G4+I4 -> 254129.55
C5: 3 | D5: Aurora | E5: Aurora Building, Entrance,Furniture, Corridors, Stairs, Handrails, Walls, Elevators, Ceiling, Roofs and Roads, Parking, Asphalt, Walk Ways, as well as Littering in public landscape. | F5: 12 | G5: 261177.99 | H5: =G5*F5 -> 3134135.9 | I5: =G5*$Q$42 -> 0 | K5: 368133.47 | L5: =G5-K5 -> -106955.47 | M5: =L5/G5 -> -0.40951181 | O5: =G5+I5 -> 261177.99
C6: 4 | D6: Fourteen | E6: Fourteen Building, Entrance,Furniture, Corridors, Stairs, Handrails, Walls, Elevators, Ceiling, Roofs and Roads, Parking, Asphalt, Walk Ways, as well as Littering in public landscape. | F6: 12 | G6: 509704.58 | H6: =G6*F6 -> 6116455 | I6: =G6*$Q$42 -> 0 | K6: 806193.75 | L6: =G6-K6 -> -296489.16 | M6: =L6/G6 -> -0.58168824 | O6: =G6+I6 -> 509704.58
C7: 5 | D7: Reyna | E7: Reyna Village Roads, Parking, Asphalt, Walk Ways, Pergolas , play court as well as Littering in public landscape. | F7: 12 | G7: 105677.85 | H7: =G7*F7 -> 1268134.2 | I7: =G7*$Q$42 -> 0 | K7: 132229.96 | L7: =G7-K7 -> -26552.105 | M7: =L7/G7 -> -0.25125515 | O7: =G7+I7 -> 105677.85
C8: 6 | D8: Eleva | E8: Eleva Village Roads, Parking, Asphalt, Walk Ways,Pergolas as well as Littering in public landscape. | F8: 12 | G8: 81202.219 | H8: =G8*F8 -> 974426.62 | I8: =G8*$Q$42 -> 0 | K8: 102178.85 | L8: =G8-K8 -> -20976.629 | M8: =L8/G8 -> -0.25832581 | O8: =G8+I8 -> 81202.219
C9: 7 | D9: Isadore | E9: Isadore Village Roads, Parking, Asphalt, Walk Ways, Pergolas as well as Littering in public landscape. | F9: 12 | G9: 62204.856 | H9: =G9*F9 -> 746458.27 | I9: =G9*$Q$42 -> 0 | K9: 78508.912 | L9: =G9-K9 -> -16304.056 | M9: =L9/G9 -> -0.26210263 | O9: =G9+I9 -> 62204.856
C10: 8 | D10: Alba's Aliyah | E10: Alba Aliyah Village Roads, Parking, Asphalt, Walk Ways, as well as Littering in public landscape. | F10: 12 | G10: 79759.014 | H10: =G10*F10 -> 957108.17 | I10: =G10*$Q$42 -> 0 | K10: 100410.82 | L10: =G10-K10 -> -20651.81 | M10: =L10/G10 -> -0.2589276 | O10: =G10+I10 -> 79759.014
C11: 9 | D11: Alba's Spendia | E11: Alba Spendia Village Roads, Parking, Asphalt, Walk Ways, as well as Littering in public landscape. | F11: 12 | G11: 79288.988 | H11: =G11*F11 -> 951467.85 | I11: =G11*$Q$42 -> 0 | K11: 99151.035 | L11: =G11-K11 -> -19862.047 | M11: =L11/G11 -> -0.25050196 | O11: =G11+I11 -> 79288.988
C12: 10 | D12: Commercial Area "UTC-Golf club house | E12: UTC-Golf club house : Building, Entrance,Furniture, Corridors, Stairs, Handrails, Walls, Elevators, Ceiling, Roofs and Parking, Asphalt, Walk Ways, Littering in public landscape, Marble floor, Bathrooms, 3 Hubs at golf Area and golf Office | F12: 12 | G12: 227995.47 | H12: =G12*F12 -> 2735945.6 | K12: 276777.38 | L12: =G12-K12 -> -48781.913 | M12: =L12/G12 -> -0.21396001 | O12: =G12+I12 -> 227995.47
C13: 11 | D13: Public Roads | E13: Road 7, Parking, Landscape areas, utility bulidings,Walkways,Security guardhouse and Kiosks | F13: 12 | G13: 21772.409 | H13: =G13*F13 -> 261268.9 | K13: 27043.411 | L13: =G13-K13 -> -5271.0024 | M13: =L13/G13 -> -0.24209551 | O13: =G13+I13 -> 21772.409
C14: 12 | D14: Crossing gates | E14: all Consutation gates on site , Walkways,Security guardhouse and Kiosks | F14: 12 | G14: 116671.73 | H14: =G14*F14 -> 1400060.7 | K14: 142784.13 | L14: =G14-K14 -> -26112.399 | M14: =L14/G14 -> -0.22381085 | O14: =G14+I14 -> 116671.73
C15: 13 | D15: Mobilization areas " water station " | E15: Mobilization areas, with Caravans, public area | F15: 12 | G15: 19590.072 | H15: =G15*F15 -> 235080.86 | K15: 24358.381 | L15: =G15-K15 -> -4768.3089 | M15: =L15/G15 -> -0.24340436 | O15: =G15+I15 -> 19590.072
C16: 14 | D16: Managament"sales center" | E16: Head Quarter (Management building - sale center - customer excellence area - mock up apartments - garage - parking - public areas - landscape area - waste collection area) | F16: 12 | G16: 593243.93 | H16: =G16*F16 -> 7118927.2 | K16: 811438.67 | L16: =G16-K16 -> -218194.74 | M16: =L16/G16 -> -0.36779936 | O16: =G16+I16 -> 593243.93
C17: Total Basic Incl. VAT. | G17: =SUM(G3:G16) -> 2954799.7 | H17: =SUM(H3:H16) -> 35457597 | K17: =SUM(K3:K16) -> 4261816.8 | L17: =G17-K17 -> -1307017.1 | M17: =L17/G17 -> -0.44233696 | O17: =SUM(O3:O16) -> 2954799.7
B19: Optional Scope | C19: 1 | D19: Sierras | E19: Sierras Community Centre 1 : Swimming Spots, Community Buildings, Bathrooms , Pool area, Kids Area, Deck and Walk Ways, Litter Picking from Surroundings and Landscape . | F19: 12 | H19: =G19*F19 -> 0
C20: 2 | E20: Sierras Community Centre 15: Swimming Spots, Community Buildings, Bathrooms , Pool area, Kids Area, Deck and Walk Ways, Litter Picking from Surroundings and Landscape . | F20: 12 | H20: =G20*F20 -> 0
C21: 3 | E21: Sierras Community Centre 15: Swimming Spots, , Pool area, Kids Area, and Walk Ways, Litter Picking from Surroundings and Landscape . | F21: 12 | H21: =G21*F21 -> 0
C22: 4 | D22: Fourteen | E22: Fourteen Community Centre 15: Swimming Spots, Community Buildings, Bathrooms , Pool area, Kids Area, Deck and Walk Ways, Litter Picking from Surroundings and Landscape . | F22: 12 | H22: =G22*F22 -> 0
C23: 5 | E23: Fourteen Community Centre 15: Swimming Spots, , Pool area, Kids Area, and Walk Ways, Litter Picking from Surroundings and Landscape . | F23: 12 | H23: =G23*F23 -> 0
C24: 6 | D24: Alto | E24: Alto community center Swimming Spots, Community Buildings, Bathrooms , Pool area, Kids Area, Deck and Walk Ways, Litter Picking from Surroundings and Landscape . | F24: 12 | H24: =G24*F24 -> 0
C25: 7 | D25: Aurora | E25: Aurora Community Centre: Swimming Spots, Community Buildings, Bathrooms , Pool area, Kids Area, Deck and Walk Ways, Litter Picking from Surroundings and Landscape . | F25: 12 | H25: =G25*F25 -> 0
C26: 8 | D26: Reyna | E26: Reyna Community Centre: Swimming Spots, Community Buildings, Bathrooms , Pool area, Kids Area, Deck and Walk Ways, Litter Picking from Surroundings and Landscape . . | F26: 12 | H26: =G26*F26 -> 0
C27: 9 | D27: Eleva | E27: Eleva Community Centre: Swimming Spots, Community Buildings, Bathrooms , Pool area, Kids Area, Deck and Walk Ways, Litter Picking from Surroundings and Landscape . | F27: 12 | H27: =G27*F27 -> 0
C28: 10 | D28: Isadore | E28: Isadore Community Centre :Swimming Spots, Community Buildings, Bathrooms , Pool area, Kids Area, Deck and Walk Ways, Litter Picking from Surroundings and Landscape . | F28: 12 | H28: =G28*F28 -> 0
C29: 11 | D29: Alba's | E29: Alba Spendia Community Centre:Swimming Spots, Community Buildings, Bathrooms , Pool area, Kids Area, Deck and Walk Ways, Litter Picking from Surroundings and Landscape . | F29: 12 | H29: =G29*F29 -> 0
C30: 12 | D30: Fountain Side | E30: Fountain Side Community Centre :Swimming Spots, Community Buildings, Bathrooms , Pool area, Kids Area, Deck and Walk Ways, Litter Picking from Surroundings and Landscape . | F30: 12 | H30: =G30*F30 -> 0
C31: 13 | D31: Celesta | E31: Celesta Community Centre :Swimming Spots, Community Buildings, Bathrooms , Pool area, Kids Area, Deck and Walk Ways, Litter Picking from Surroundings and Landscape . | F31: 12 | H31: =G31*F31 -> 0
C32: 14 | D32: Terencia | E32: Terencia Community Centre :Swimming Spots, Community Buildings, Bathrooms , Pool area, Kids Area, Deck and Walk Ways, Litter Picking from Surroundings and Landscape . | F32: 12 | H32: =G32*F32 -> 0
C33: 15 | D33: Levana | E33: Levana Community Centre :Swimming Spots, Community Buildings, Bathrooms , Pool area, Kids Area, Deck and Walk Ways, Litter Picking from Surroundings and Landscape . | F33: 12 | H33: =G33*F33 -> 0
C34: 16 | D34: Commercial Area "UTC-Plaza" | E34: UTC-Plaza, Parking, Asphalt, Walk Ways, Littering in public landscape, Marble floor, Bathrooms, Football pitch | F34: 12 | H34: =G34*F34 -> 0
C35: 17 | D35: Commercial Area "UTC-Golf Plaza" | E35: UTC- Golf Plaza, Parking, Asphalt, Walk Ways, Littering in public landscape, Marble floor, Bathrooms, Football pitch | F35: 12 | H35: =G35*F35 -> 0
... C38: 20 | D38: Azzurra | E38: Azzura Village Roads, Parking, Asphalt, Walk Ways, as well as Littering in public landscape. | F38: 12 | H38: =G38*F38 -> 0
C39: 21 | D39: Azzurra | E39: Azzurra Community Centre :Swimming Spots, Community Buildings, Bathrooms , Pool area, Kids Area, Deck and Walk Ways, Litter Picking from Surroundings and Landscape .
C40: 22 | D40: Polo club | F40: 12 | H40: =G40*F40 -> 0
C41: Total Basic Incl. VAT. | H41: =SUM(H19:H40) -> 0
B42: First Year Main Scope | G42: =G17 -> 2954799.7 | H42: =G42*12 -> 35457597 | I42: =H42-J42 -> 0 | J42: =G42*12 -> 35457597 | K42: 4261816.8 | L42: =G42-K42 -> -1307017.1 | M42: =L42/G42 -> -0.44233696 | O42: ='BOQ Basic -Residential (2)'!D49-'BOQ A (2)'!G42 -> 0 | P42: =G3+G4+G5+G6+G7+G8+G9+G10+G11 -> 1975526.1 | Q42: =O42/P42 -> 0
B43: First Year Optional Scope | G43: =G41 -> 0 | H43: =G43*12 -> 0 | I43: =H43-J43 -> 0 | J43: =G43*12 -> 0 | K43: 0 | L43: =G43-K43 -> 0 | M43: =L43/G43 -> #DIV/0!
B44: First Year (Main+Optional) Scope | G44: =SUM(G42:G43) -> 2954799.7 | H44: =SUM(H42:H43) -> 35457597 | I44: =H44-J44 -> 0 | J44: =G44*12 -> 35457597 | K44: 4261816.8 | L44: =G44-K44 -> -1307017.1 | M44: =L44/G44 -> -0.44233696
...

Sheet Sheet1
B4: 11101135
B5: ='BOQ Basic -Residential'!D50-Sheet1!B4 -> 24057887
B10: 15000

Sheet BOQ Basic -Residential
A4: Basic Scope Residential | B4: All Season | C4: Unit Rate | D4: Monthly Fee
A5: Item | B5: QTY
A6: Labors | B6: 94 | C6: ='HK Budget (2)'!J25 -> 8739.4853 | D6: =C6*$B6 -> 821511.62 | E6: 8894.1264 | F6: 836047.89
A7: Supervisor | B7: 11 | C7: ='HK Budget (2)'!J27 -> 15031.362 | D7: =C7*$B7 -> 165344.98 | E7: 15297.335 | F7: 168270.68
A8: Labors Night Shift | B8: 14 | C8: ='HK Budget (2)'!J26 -> 8739.4853 | D8: =C8*$B8 -> 122352.79 | E8: 8894.1264 | F8: 124517.77
A9: Supervisor Night Shift | B9: 3 | C9: ='HK Budget (2)'!J28 -> 15031.362 | D9: =C9*$B9 -> 45094.085 | E9: 15297.335 | F9: 45892.004
A10: Site Manager | B10: 1 | C10: ='HK Budget (2)'!J31 -> 49130.948 | D10: =C10*$B10 -> 49130.948 | E10: 50337.077 | F10: 50337.077
A11: Site Assistant | B11: 3 | C11: ='HK Budget (2)'!J30 -> 20617.971 | D11: =C11*$B11 -> 61853.913 | E11: 21187.751 | F11: 63563.252
A12: Site Admin | B12: 2 | C12: ='HK Budget (2)'!J29 -> 17859.237 | D12: =C12*$B12 -> 35718.474 | E12: 18277.725 | F12: 36555.45
A13: Sales Center Labor- Morning Shift | B13: 19 | C13: ='HK Budget (2)'!J32 -> 9430.9002 | D13: =C13*$B13 -> 179187.1 | E13: 9597.7757 | F13: 182357.74 | H13: In House team Mandatory
A14: Sales Center Labor- Night Shift | B14: 11 | C14: ='HK Budget (2)'!J32 -> 9430.9002 | D14: =C14*$B14 -> 103739.9 | E14: 9597.7757 | F14: 105575.53
A15: Sales Center supervisor- Morning Shift | B15: 2 | C15: ='HK Budget (2)'!J33 -> 15722.777 | D15: =C15*$B15 -> 31445.553 | E15: 16000.984 | F15: 32001.968
A16: Sales Center supervisor- Night Shift | B16: 1 | C16: ='HK Budget (2)'!J33 -> 15722.777 | D16: =C16*$B16 -> 15722.777 | E16: 16000.984 | F16: 16000.984
A17: Sales Center Assistant Manager | B17: 1 | C17: ='HK Budget (2)'!J34 -> 21309.386 | D17: =C17*$B17 -> 21309.386 | E17: 21891.4 | F17: 21891.4
A18: Transportation | B18: LS | C18: ='HK Budget (2)'!C49 -> 460673.18 | D18: =C18 -> 460673.18 | E18: 469204.16 | F18: 469204.16
A19: Manpower | D19: =SUM(D6:D18) -> 2113084.7 | F19: 2152215.9
A20: Façade Cleaning service " as per site need max. 168 buildings per year" | B20: 14 | C20: ='Facades Cleaning Cost'!G22 -> 12016.204 | D20: =C20*$B20 -> 168226.86 | E20: 12238.727 | F20: 171342.17 | H20: Total Buildings 56 & 3 times per year
A21: Single disk | B21: 5 | C21: ='Equipment & Tools Cost'!AU6 -> 1249 | D21: =C21*$B21 -> 6245 | E21: 1272 | F21: 6360
A22: Vacuum | B22: 6 | C22: ='Equipment & Tools Cost'!AU8 -> 729 | D22: =C22*$B22 -> 4374 | E22: 742 | F22: 4452
A23: Manual sweeper | B23: 10 | C23: ='Equipment & Tools Cost'!AU11 -> 937 | D23: =C23*$B23 -> 9370 | E23: 954 | F23: 9540
A24: McClean Trolley | B24: 14 | C24: ='Equipment & Tools Cost'!AU12 -> 387 | D24: =C24*$B24 -> 5418 | E24: 394 | F24: 5516
A25: Black Broom and Closed Ban | B25: 23 | C25: ='Equipment & Tools Cost'!AU13 -> 94 | D25: =C25*$B25 -> 2162 | E25: 96 | F25: 2208
A26: Litter Picking Steak | B26: 12 | C26: ='Equipment & Tools Cost'!AU14 -> 105 | D26: =C26*$B26 -> 1260 | E26: 106 | F26: 1272
A27: Mob Bucket with Cotton Cloth | B27: 25 | C27: ='Equipment & Tools Cost'!AU15 -> 63 | D27: =C27*$B27 -> 1575 | E27: 64 | F27: 1600
A28: Water Fed Telescope (20 Meter) | B28: 2 | C28: ='Equipment & Tools Cost'!AU17 -> 7907 | D28: =C28*$B28 -> 15814 | E28: 8054 | F28: 16108
A29: High Pressure Set One Car, Driver, 1K Liter tank" -30 days" | B29: 2 | C29: ='Equipment & Tools Cost'!AU18 -> 63818 | D29: =C29*$B29 -> 127636 | E29: 64999 | F29: 129998
A30: Man Lift 15M" *30 days" | B30: 2 | C30: ='Equipment & Tools Cost'!AU19 -> 67716 | D30: =C30*$B30 -> 135432 | E30: 68970 | F30: 137940
A31: Pick up Car with driver | B31: 2 | C31: ='Equipment & Tools Cost'!AU20 -> 52435 | D31: =C31*$B31 -> 104870 | E31: 53406 | F31: 106812
A32: Public trolly for Building | B32: 25 | C32: ='Equipment & Tools Cost'!AU10 -> 278 | D32: =C32*$B32 -> 6950 | E32: 283 | F32: 7075
A33: Cary cady " As per site Need" | B33: 56 | C33: ='Equipment & Tools Cost'!AU16 -> 16 | D33: =C33*$B33 -> 896 | E33: 16 | F33: 896
A34: Consumables & tools & Chemical Rates | B34: 1 | C34: ='Equipment & Tools Cost'!M65 -> 149437.37 | D34: =C34*$B34 -> 149437.37 | E34: 152238.24 | F34: 152238.24
A35: Sales Center - Single disk | B35: 3 | C35: ='Equipment & Tools Cost'!AU6 -> 1249 | D35: =C35*$B35 -> 3747 | E35: 1272 | F35: 3816
A36: Sales Center - Vacuum | B36: 2 | C36: ='Equipment & Tools Cost'!AU8 -> 729 | D36: =C36*$B36 -> 1458 | E36: 742 | F36: 1484
A37: Sales Center - Manual sweeper | B37: 2 | C37: ='Equipment & Tools Cost'!AU11 -> 937 | D37: =C37*$B37 -> 1874 | E37: 954 | F37: 1908
A38: Sales Center - McClean Trolley | B38: 3 | C38: ='Equipment & Tools Cost'!AU12 -> 387 | D38: =C38*$B38 -> 1161 | E38: 394 | F38: 1182
A39: Sales Center - Black Broom and Closed Ban | B39: 10 | C39: ='Equipment & Tools Cost'!AU13 -> 94 | D39: =C39*$B39 -> 940 | E39: 96 | F39: 960
A40: Sales Center - Litter Picking Steak | B40: 3 | C40: ='Equipment & Tools Cost'!AU14 -> 105 | D40: =C40*$B40 -> 315 | E40: 106 | F40: 318
A41: Sales Center - Mob Bucket with Cotton Cloth | B41: 10 | C41: ='Equipment & Tools Cost'!AU15 -> 63 | D41: =C41*$B41 -> 630 | E41: 64 | F41: 640
A42: Sales Center - Ladder | B42: 2 | C42: ='Equipment & Tools Cost'!AU22 -> 132 | D42: =C42*$B42 -> 264 | E42: 135 | F42: 270
A43: Sales Center - telescope | B43: 1 | C43: ='Equipment & Tools Cost'!AU24 -> 131 | D43: =C43*$B43 -> 131 | E43: 133 | F43: 133
...

Sheet BOQ A
B2: Scope | C2: # | D2: UPTWON CAIRO-ZONE A | E2: Description (Housekeeping) | F2: Duration | G2: Monthly Rate | H2: Amount
B3: Basic Scope | C3: 1 | D3: Sierras | E3: Sierras Building, Entrance,Furniture, Corridors, Stairs, Handrails, Walls, Elevators, Ceiling, Roofs and Roads, Parking, Asphalt, Walk Ways, as well as Littering in public landscape. | F3: 12 | G3: ='HK Budget (2)'!I19 -> 540231.81 | H3: =G3*F3 -> 6482781.8 | K3: 920624.36 | L3: =G3-K3 -> -380392.55 | M3: =L3/G3 -> -0.70412838
C4: 2 | D4: Alto | E4: Alto Building, Entrance,Furniture, Corridors, Stairs, Handrails, Walls, Elevators, Ceiling, Roofs and Roads, Parking, Asphalt, Walk Ways, as well as Littering in public landscape. | F4: 12 | G4: ='HK Budget (2)'!J19 -> 253122.53 | H4: =G4*F4 -> 3037470.3 | K4: 371983.73 | L4: =G4-K4 -> -118861.2 | M4: =L4/G4 -> -0.46957971
C5: 3 | D5: Aurora | E5: Aurora Building, Entrance,Furniture, Corridors, Stairs, Handrails, Walls, Elevators, Ceiling, Roofs and Roads, Parking, Asphalt, Walk Ways, as well as Littering in public landscape. | F5: 12 | G5: ='HK Budget (2)'!K19 -> 260143.04 | H5: =G5*F5 -> 3121716.5 | K5: 368133.47 | L5: =G5-K5 -> -107990.42 | M5: =L5/G5 -> -0.4151194
C6: 4 | D6: Fourteen | E6: Fourteen Building, Entrance,Furniture, Corridors, Stairs, Handrails, Walls, Elevators, Ceiling, Roofs and Roads, Parking, Asphalt, Walk Ways, as well as Littering in public landscape. | F6: 12 | G6: ='HK Budget (2)'!L19 -> 507684.82 | H6: =G6*F6 -> 6092217.8 | K6: 806193.75 | L6: =G6-K6 -> -298508.93 | M6: =L6/G6 -> -0.58798081
C7: 5 | D7: Reyna | E7: Reyna Village Roads, Parking, Asphalt, Walk Ways, Pergolas , play court as well as Littering in public landscape. | F7: 12 | G7: ='HK Budget (2)'!M19 -> 105259.09 | H7: =G7*F7 -> 1263109.1 | K7: 132229.96 | L7: =G7-K7 -> -26970.866 | M7: =L7/G7 -> -0.25623313
C8: 6 | D8: Eleva | E8: Eleva Village Roads, Parking, Asphalt, Walk Ways,Pergolas as well as Littering in public landscape. | F8: 12 | G8: ='HK Budget (2)'!N19 -> 80880.445 | H8: =G8*F8 -> 970565.34 | K8: 102178.85 | L8: =G8-K8 -> -21298.403 | M8: =L8/G8 -> -0.26333192
C9: 7 | D9: Isadore | E9: Isadore Village Roads, Parking, Asphalt, Walk Ways, Pergolas as well as Littering in public landscape. | F9: 12 | G9: ='HK Budget (2)'!O19 -> 61958.361 | H9: =G9*F9 -> 743500.33 | K9: 78508.912 | L9: =G9-K9 -> -16550.551 | M9: =L9/G9 -> -0.26712377
C10: 8 | D10: Alba's Aliyah | E10: Alba Aliyah Village Roads, Parking, Asphalt, Walk Ways, as well as Littering in public landscape. | F10: 12 | G10: ='HK Budget (2)'!P19 -> 79442.959 | H10: =G10*F10 -> 953315.51 | K10: 100410.82 | L10: =G10-K10 -> -20967.865 | M10: =L10/G10 -> -0.2639361
C11: 9 | D11: Alba's Spendia | E11: Alba Spendia Village Roads, Parking, Asphalt, Walk Ways, as well as Littering in public landscape. | F11: 12 | G11: ='HK Budget (2)'!Q19 -> 78974.795 | H11: =G11*F11 -> 947697.54 | K11: 99151.035 | L11: =G11-K11 -> -20176.24 | M11: =L11/G11 -> -0.25547695
C12: 10 | D12: Commercial Area "UTC-Golf club house | E12: UTC-Golf club house : Building, Entrance,Furniture, Corridors, Stairs, Handrails, Walls, Elevators, Ceiling, Roofs and Parking, Asphalt, Walk Ways, Littering in public landscape, Marble floor, Bathrooms, 3 Hubs at golf Area and golf Office | F12: 12 | G12: ='HK Budget (2)'!R19 -> 227995.47 | H12: =G12*F12 -> 2735945.6 | K12: 276777.38 | L12: =G12-K12 -> -48781.913 | M12: =L12/G12 -> -0.21396001
C13: 11 | D13: Public Roads | E13: Road 7, Parking, Landscape areas, utility bulidings,Walkways,Security guardhouse and Kiosks | F13: 12 | G13: ='HK Budget (2)'!S19 -> 21772.409 | H13: =G13*F13 -> 261268.9 | K13: 27043.411 | L13: =G13-K13 -> -5271.0024 | M13: =L13/G13 -> -0.24209551
C14: 12 | D14: Crossing gates | E14: all Consutation gates on site , Walkways,Security guardhouse and Kiosks | F14: 12 | G14: ='HK Budget (2)'!T19 -> 116671.73 | H14: =G14*F14 -> 1400060.7 | K14: 142784.13 | L14: =G14-K14 -> -26112.399 | M14: =L14/G14 -> -0.22381085
C15: 13 | D15: Mobilization areas " water station " | E15: Mobilization areas, with Caravans, public area | F15: 12 | G15: ='HK Budget (2)'!U19 -> 19590.072 | H15: =G15*F15 -> 235080.86 | K15: 24358.381 | L15: =G15-K15 -> -4768.3089 | M15: =L15/G15 -> -0.24340436
C16: 14 | D16: Managament"sales center" | E16: Head Quarter (Management building - sale center - customer excellence area - mock up apartments - garage - parking - public areas - landscape area - waste collection area) | F16: 12 | G16: ='HK Budget (2)'!V19 -> 593243.93 | H16: =G16*F16 -> 7118927.2 | K16: 811438.67 | L16: =G16-K16 -> -218194.74 | M16: =L16/G16 -> -0.36779936
C17: Total Basic Incl. VAT. | G17: =SUM(G3:G16) -> 2946971.5 | H17: =SUM(H3:H16) -> 35363657 | K17: =SUM(K3:K16) -> 4261816.8 | L17: =G17-K17 -> -1314845.4 | M17: =L17/G17 -> -0.44616835
B19: Optional Scope | C19: 1 | D19: Sierras | E19: Sierras Community Centre 1 : Swimming Spots, Community Buildings, Bathrooms , Pool area, Kids Area, Deck and Walk Ways, Litter Picking from Surroundings and Landscape . | F19: 12 | H19: =G19*F19 -> 0
C20: 2 | E20: Sierras Community Centre 15: Swimming Spots, Community Buildings, Bathrooms , Pool area, Kids Area, Deck and Walk Ways, Litter Picking from Surroundings and Landscape . | F20: 12 | H20: =G20*F20 -> 0
C21: 3 | E21: Sierras Community Centre 15: Swimming Spots, , Pool area, Kids Area, and Walk Ways, Litter Picking from Surroundings and Landscape . | F21: 12 | H21: =G21*F21 -> 0
C22: 4 | D22: Fourteen | E22: Fourteen Community Centre 15: Swimming Spots, Community Buildings, Bathrooms , Pool area, Kids Area, Deck and Walk Ways, Litter Picking from Surroundings and Landscape . | F22: 12 | H22: =G22*F22 -> 0
C23: 5 | E23: Fourteen Community Centre 15: Swimming Spots, , Pool area, Kids Area, and Walk Ways, Litter Picking from Surroundings and Landscape . | F23: 12 | H23: =G23*F23 -> 0
C24: 6 | D24: Alto | E24: Alto community center Swimming Spots, Community Buildings, Bathrooms , Pool area, Kids Area, Deck and Walk Ways, Litter Picking from Surroundings and Landscape . | F24: 12 | H24: =G24*F24 -> 0
C25: 7 | D25: Aurora | E25: Aurora Community Centre: Swimming Spots, Community Buildings, Bathrooms , Pool area, Kids Area, Deck and Walk Ways, Litter Picking from Surroundings and Landscape . | F25: 12 | H25: =G25*F25 -> 0
C26: 8 | D26: Reyna | E26: Reyna Community Centre: Swimming Spots, Community Buildings, Bathrooms , Pool area, Kids Area, Deck and Walk Ways, Litter Picking from Surroundings and Landscape . . | F26: 12 | H26: =G26*F26 -> 0
C27: 9 | D27: Eleva | E27: Eleva Community Centre: Swimming Spots, Community Buildings, Bathrooms , Pool area, Kids Area, Deck and Walk Ways, Litter Picking from Surroundings and Landscape . | F27: 12 | H27: =G27*F27 -> 0
C28: 10 | D28: Isadore | E28: Isadore Community Centre :Swimming Spots, Community Buildings, Bathrooms , Pool area, Kids Area, Deck and Walk Ways, Litter Picking from Surroundings and Landscape . | F28: 12 | H28: =G28*F28 -> 0
C29: 11 | D29: Alba's | E29: Alba Spendia Community Centre:Swimming Spots, Community Buildings, Bathrooms , Pool area, Kids Area, Deck and Walk Ways, Litter Picking from Surroundings and Landscape . | F29: 12 | H29: =G29*F29 -> 0
C30: 12 | D30: Fountain Side | E30: Fountain Side Community Centre :Swimming Spots, Community Buildings, Bathrooms , Pool area, Kids Area, Deck and Walk Ways, Litter Picking from Surroundings and Landscape . | F30: 12 | H30: =G30*F30 -> 0
C31: 13 | D31: Celesta | E31: Celesta Community Centre :Swimming Spots, Community Buildings, Bathrooms , Pool area, Kids Area, Deck and Walk Ways, Litter Picking from Surroundings and Landscape . | F31: 12 | H31: =G31*F31 -> 0
C32: 14 | D32: Terencia | E32: Terencia Community Centre :Swimming Spots, Community Buildings, Bathrooms , Pool area, Kids Area, Deck and Walk Ways, Litter Picking from Surroundings and Landscape . | F32: 12 | H32: =G32*F32 -> 0
C33: 15 | D33: Levana | E33: Levana Community Centre :Swimming Spots, Community Buildings, Bathrooms , Pool area, Kids Area, Deck and Walk Ways, Litter Picking from Surroundings and Landscape . | F33: 12 | H33: =G33*F33 -> 0
C34: 16 | D34: Commercial Area "UTC-Plaza" | E34: UTC-Plaza, Parking, Asphalt, Walk Ways, Littering in public landscape, Marble floor, Bathrooms, Football pitch | F34: 12 | H34: =G34*F34 -> 0
C35: 17 | D35: Commercial Area "UTC-Golf Plaza" | E35: UTC- Golf Plaza, Parking, Asphalt, Walk Ways, Littering in public landscape, Marble floor, Bathrooms, Football pitch | F35: 12 | H35: =G35*F35 -> 0
... C38: 20 | D38: Azzurra | E38: Azzura Village Roads, Parking, Asphalt, Walk Ways, as well as Littering in public landscape. | F38: 12 | H38: =G38*F38 -> 0
C39: 21 | D39: Azzurra | E39: Azzurra Community Centre :Swimming Spots, Community Buildings, Bathrooms , Pool area, Kids Area, Deck and Walk Ways, Litter Picking from Surroundings and Landscape .
C40: 22 | D40: Polo club | F40: 12 | H40: =G40*F40 -> 0
C41: Total Basic Incl. VAT. | H41: =SUM(H19:H40) -> 0
B42: First Year Main Scope | G42: =G17 -> 2946971.5 | H42: =G42*12 -> 35363657 | I42: =H42-J42 -> 0 | J42: =G42*12 -> 35363657 | K42: 4261816.8 | L42: =G42-K42 -> -1314845.4 | M42: =L42/G42 -> -0.44616835
B43: First Year Optional Scope | G43: =G41 -> 0 | H43: =G43*12 -> 0 | I43: =H43-J43 -> 0 | J43: =G43*12 -> 0 | K43: 0 | L43: =G43-K43 -> 0 | M43: =L43/G43 -> #DIV/0!
B44: First Year (Main+Optional) Scope | G44: =SUM(G42:G43) -> 2946971.5 | H44: =SUM(H42:H43) -> 35363657 | I44: =H44-J44 -> 0 | J44: =G44*12 -> 35363657 | K44: 4261816.8 | L44: =G44-K44 -> -1314845.4 | M44: =L44/G44 -> -0.44616835
...

Sheet Manpower Cost
B3: UTC HK Budget
B4: Items | C4: Head Count | D4: Net Salary | E4: CTC | F4: Total Amount/ Month | K4: Sierras | M4: Alto | O4: Aurora | Q4: Fourteen | S4: Reyna | U4: Eleva | W4: Isadore | Y4: Alba's Aliyah | AA4: Alba's Spendia | AC4: Commercial Area "UTC-Golf club house | AE4: Public Roads | AG4: Crossing gates | AI4: Mobilization areas " water station " | AK4: Managament"sales center" | AM4: Total Head Count Cost | AN4: Gross Margin | AO4: Total | AP4: Contingency | AQ4: Total | AR4: VAT | AS4: Total W VAT | AT4: Unit Rate
B5: Head Count | K5: Head Count | L5: Monthly Cost | M5: Head Count | N5: Monthly Cost | O5: Head Count | P5: Monthly Cost | Q5: Head Count | R5: Monthly Cost | S5: Head Count | T5: Monthly Cost | U5: Head Count | V5: Monthly Cost | W5: Head Count | X5: Monthly Cost | Y5: Head Count | Z5: Monthly Cost | AA5: Head Count | AB5: Monthly Cost | AC5: Head Count | AD5: Monthly Cost | AE5: Head Count | AF5: Monthly Cost | AG5: Head Count | AH5: Monthly Cost | AI5: Head Count | AJ5: Monthly Cost | AK5: Head Count | AL5: Monthly Cost
B6: ='Manpower CTC'!B5 -> Labors Morning Shift | C6: =K6+M6+O6+Q6+S6+U6+W6+Y6+AA6+AC6+AE6+AG6+AI6 -> 94 | E6: ='Manpower CTC'!C5 -> 6320 | F6: =C6*E6 -> 594080 | H6: =C6-(K6+M6+O6+Q6+S6+U6+W6+Y6+AA6+AC6+AE6+AG6+AI6+AK6) -> 0 | I6: =F6-(L6+N6+P6+R6+T6+V6+X6+Z6+AB6+AD6+AF6+AH6+AJ6+AL6) -> 0 | K6: =Maning!F6 -> 20 | L6: =E6*K6 -> 126400 | M6: =Maning!G6 -> 10 | N6: =M6*E6 -> 63200 | O6: =Maning!H6 -> 11 | P6: =O6*E6 -> 69520 | Q6: =Maning!I6 -> 20 | R6: =Q6*E6 -> 126400 | S6: =Maning!J6 -> 5 | T6: =S6*E6 -> 31600 | U6: =Maning!K6 -> 4 | V6: =U6*E6 -> 25280 | W6: =Maning!L6 -> 3 | X6: =W6*E6 -> 18960 | Y6: =Maning!M6 -> 4 | Z6: =Y6*E6 -> 25280 | AA6: =Maning!N6 -> 4 | AB6: =AA6*E6 -> 25280 | AC6: =Maning!O6 -> 5 | AD6: =AC6*E6 -> 31600 | AE6: =Maning!P6 -> 1 | AF6: =AE6*E6 -> 6320 | AG6: =Maning!Q6 -> 6 | AH6: =AG6*E6 -> 37920 | AI6: =Maning!R6 -> 1 | AJ6: =AI6*E6 -> 6320 | AK6: =Maning!S6 -> 0 | AL6: =AK6*E6 -> 0 | AM6: =SUM(L6+N6+P6+R6+T6+V6+X6+Z6+AB6+AD6+AF6+AH6+AJ6+AL6) -> 594080 | AN6: =AM6*$E$17 -> 47526.4 | AO6: =AM6+AN6 -> 641606.4 | AP6: =AO6*$E$19 -> 8982.4896 | AQ6: =AO6+AP6 -> 650588.89 | AR6: =AQ6*$E$21 -> 91082.445 | AS6: =AQ6+AR6 -> 741671.33 | AT6: =AS6/C6 -> 7890.1206
B7: ='Manpower CTC'!B6 -> Labors Noon Shift | C7: =K7+M7+O7+Q7+S7+U7+W7+Y7+AA7+AC7+AE7+AG7+AI7 -> 14 | E7: ='Manpower CTC'!C6 -> 6320 | F7: =C7*E7 -> 88480 | H7: =C7-(K7+M7+O7+Q7+S7+U7+W7+Y7+AA7+AC7+AE7+AG7+AI7+AK7) -> 0 | I7: =F7-(L7+N7+P7+R7+T7+V7+X7+Z7+AB7+AD7+AF7+AH7+AJ7+AL7) -> 0 | K7: =Maning!F7 -> 3.2553191 | L7: =E7*K7 -> 20573.617 | M7: =Maning!G7 -> 1.7234043 | N7: =M7*E7 -> 10891.915 | O7: =Maning!H7 -> 1.3404255 | P7: =O7*E7 -> 8471.4894 | Q7: =Maning!I7 -> 2.6808511 | R7: =Q7*E7 -> 16942.979 | S7: =Maning!J7 -> 0 | T7: =S7*E7 -> 0 | U7: =Maning!K7 -> 0 | V7: =U7*E7 -> 0 | W7: =Maning!L7 -> 0 | X7: =W7*E7 -> 0 | Y7: =Maning!M7 -> 0 | Z7: =Y7*E7 -> 0 | AA7: =Maning!N7 -> 0 | AB7: =AA7*E7 -> 0 | AC7: =Maning!O7 -> 5 | AD7: =AC7*E7 -> 31600 | AE7: =Maning!P7 -> 0 | AF7: =AE7*E7 -> 0 | AG7: =Maning!Q7 -> 0 | AH7: =AG7*E7 -> 0 | AI7: =Maning!R7 -> 0 | AJ7: =AI7*E7 -> 0 | AK7: =Maning!S7 -> 0 | AL7: =AK7*E7 -> 0 | AM7: =SUM(L7+N7+P7+R7+T7+V7+X7+Z7+AB7+AD7+AF7+AH7+AJ7+AL7) -> 88480 | AN7: =AM7*$E$17 -> 7078.4 | AO7: =AM7+AN7 -> 95558.4 | AP7: =AO7*$E$19 -> 1337.8176 | AQ7: =AO7+AP7 -> 96896.218 | AR7: =AQ7*$E$21 -> 13565.47 | AS7: =AQ7+AR7 -> 110461.69 | AT7: =AS7/C7 -> 7890.1206
B8: ='Manpower CTC'!B7 -> Supervisor Morning Shift | C8: =K8+M8+O8+Q8+S8+U8+W8+Y8+AA8+AC8+AE8+AG8+AI8 -> 11 | E8: ='Manpower CTC'!C7 -> 10870 | F8: =C8*E8 -> 119570 | H8: =C8-(K8+M8+O8+Q8+S8+U8+W8+Y8+AA8+AC8+AE8+AG8+AI8+AK8) -> 0 | I8: =F8-(L8+N8+P8+R8+T8+V8+X8+Z8+AB8+AD8+AF8+AH8+AJ8+AL8) -> 0 | K8: =Maning!F8 -> 2 | L8: =E8*K8 -> 21740 | M8: =Maning!G8 -> 1 | N8: =M8*E8 -> 10870 | O8: =Maning!H8 -> 1 | P8: =O8*E8 -> 10870 | Q8: =Maning!I8 -> 2 | R8: =Q8*E8 -> 21740 | S8: =Maning!J8 -> 1 | T8: =S8*E8 -> 10870 | U8: =Maning!K8 -> 0.57142857 | V8: =U8*E8 -> 6211.4286 | W8: =Maning!L8 -> 0.42857143 | X8: =W8*E8 -> 4658.5714 | Y8: =Maning!M8 -> 0.5 | Z8: =Y8*E8 -> 5435 | AA8: =Maning!N8 -> 0.5 | AB8: =AA8*E8 -> 5435 | AC8: =Maning!O8 -> 1 | AD8: =AC8*E8 -> 10870 | AE8: =Maning!P8 -> 0.125 | AF8: =AE8*E8 -> 1358.75 | AG8: =Maning!Q8 -> 0.75 | AH8: =AG8*E8 -> 8152.5 | AI8: =Maning!R8 -> 0.125 | AJ8: =AI8*E8 -> 1358.75 | AK8: =Maning!S8 -> 0 | AL8: =AK8*E8 -> 0 | AM8: =SUM(L8+N8+P8+R8+T8+V8+X8+Z8+AB8+AD8+AF8+AH8+AJ8+AL8) -> 119570 | AN8: =AM8*$E$17 -> 9565.6 | AO8: =AM8+AN8 -> 129135.6 | AP8: =AO8*$E$19 -> 1807.8984 | AQ8: =AO8+AP8 -> 130943.5 | AR8: =AQ8*$E$21 -> 18332.09 | AS8: =AQ8+AR8 -> 149275.59 | AT8: =AS8/C8 -> 13570.508
B9: ='Manpower CTC'!B8 -> Supervisor Noon Shift | C9: =K9+M9+O9+Q9+S9+U9+W9+Y9+AA9+AC9+AE9+AG9+AI9 -> 3 | E9: ='Manpower CTC'!C8 -> 10870 | F9: =C9*E9 -> 32610 | H9: =C9-(K9+M9+O9+Q9+S9+U9+W9+Y9+AA9+AC9+AE9+AG9+AI9+AK9) -> 0 | I9: =F9-(L9+N9+P9+R9+T9+V9+X9+Z9+AB9+AD9+AF9+AH9+AJ9+AL9) -> 0 | K9: =Maning!F9 -> 0.66666667 | L9: =E9*K9 -> 7246.6667 | M9: =Maning!G9 -> 0.33333333 | N9: =M9*E9 -> 3623.3333 | O9: =Maning!H9 -> 0.33333333 | P9: =O9*E9 -> 3623.3333 | Q9: =Maning!I9 -> 0.66666667 | R9: =Q9*E9 -> 7246.6667 | S9: =Maning!J9 -> 0 | T9: =S9*E9 -> 0 | U9: =Maning!K9 -> 0 | V9: =U9*E9 -> 0 | W9: =Maning!L9 -> 0 | X9: =W9*E9 -> 0 | Y9: =Maning!M9 -> 0 | Z9: =Y9*E9 -> 0 | AA9: =Maning!N9 -> 0 | AB9: =AA9*E9 -> 0 | AC9: =Maning!O9 -> 1 | AD9: =AC9*E9 -> 10870 | AE9: =Maning!P9 -> 0 | AF9: =AE9*E9 -> 0 | AG9: =Maning!Q9 -> 0 | AH9: =AG9*E9 -> 0 | AI9: =Maning!R9 -> 0 | AJ9: =AI9*E9 -> 0 | AK9: =Maning!S9 -> 0 | AL9: =AK9*E9 -> 0 | AM9: =SUM(L9+N9+P9+R9+T9+V9+X9+Z9+AB9+AD9+AF9+AH9+AJ9+AL9) -> 32610 | AN9: =AM9*$E$17 -> 2608.8 | AO9: =AM9+AN9 -> 35218.8 | AP9: =AO9*$E$19 -> 493.0632 | AQ9: =AO9+AP9 -> 35711.863 | AR9: =AQ9*$E$21 -> 4999.6608 | AS9: =AQ9+AR9 -> 40711.524 | AT9: =AS9/C9 -> 13570.508
B10: ='Manpower CTC'!B9 -> Site Admin | C10: =K10+M10+O10+Q10+S10+U10+W10+Y10+AA10+AC10+AE10+AG10+AI10 -> 2 | E10: ='Manpower CTC'!C9 -> 16920 | F10: =C10*E10 -> 33840 | H10: =C10-(K10+M10+O10+Q10+S10+U10+W10+Y10+AA10+AC10+AE10+AG10+AI10+AK10) -> 0 | I10: =F10-(L10+N10+P10+R10+T10+V10+X10+Z10+AB10+AD10+AF10+AH10+AJ10+AL10) -> 0 | K10: =Maning!F10 -> 0.43065406 | L10: =E10*K10 -> 7286.6667 | M10: =Maning!G10 -> 0.21710008 | N10: =M10*E10 -> 3673.3333 | O10: =Maning!H10 -> 0.2285264 | P10: =O10*E10 -> 3866.6667 | Q10: =Maning!I10 -> 0.42001576 | R10: =Q10*E10 -> 7106.6667 | S10: =Maning!J10 -> 0.092592593 | T10: =S10*E10 -> 1566.6667 | U10: =Maning!K10 -> 0.074074074 | V10: =U10*E10 -> 1253.3333 | W10: =Maning!L10 -> 0.055555556 | X10: =W10*E10 -> 940 | Y10: =Maning!M10 -> 0.074074074 | Z10: =Y10*E10 -> 1253.3333 | AA10: =Maning!N10 -> 0.074074074 | AB10: =AA10*E10 -> 1253.3333 | AC10: =Maning!O10 -> 0.18518519 | AD10: =AC10*E10 -> 3133.3333 | AE10: =Maning!P10 -> 0.018518519 | AF10: =AE10*E10 -> 313.33333 | AG10: =Maning!Q10 -> 0.11111111 | AH10: =AG10*E10 -> 1880 | AI10: =Maning!R10 -> 0.018518519 | AJ10: =AI10*E10 -> 313.33333 | AK10: =Maning!S10 -> 0 | AL10: =AK10*E10 -> 0 | AM10: =SUM(L10+N10+P10+R10+T10+V10+X10+Z10+AB10+AD10+AF10+AH10+AJ10+AL10) -> 33840 | AN10: =AM10*$E$17 -> 2707.2 | AO10: =AM10+AN10 -> 36547.2 | AP10: =AO10*$E$19 -> 511.6608 | AQ10: =AO10+AP10 -> 37058.861 | AR10: =AQ10*$E$21 -> 5188.2405 | AS10: =AQ10+AR10 -> 42247.101 | AT10: =AS10/C10 -> 21123.551
B11: ='Manpower CTC'!B10 -> Site Assistant | C11: =K11+M11+O11+Q11+S11+U11+W11+Y11+AA11+AC11+AE11+AG11+AI11 -> 3 | E11: ='Manpower CTC'!C10 -> 22920 | F11: =C11*E11 -> 68760 | H11: =C11-(K11+M11+O11+Q11+S11+U11+W11+Y11+AA11+AC11+AE11+AG11+AI11+AK11) -> 0 | I11: =F11-(L11+N11+P11+R11+T11+V11+X11+Z11+AB11+AD11+AF11+AH11+AJ11+AL11) -> 0 | K11: =Maning!F11 -> 0.64598109 | L11: =E11*K11 -> 14805.887 | M11: =Maning!G11 -> 0.32565012 | N11: =M11*E11 -> 7463.9007 | O11: =Maning!H11 -> 0.3427896 | P11: =O11*E11 -> 7856.7376 | Q11: =Maning!I11 -> 0.63002364 | R11: =Q11*E11 -> 14440.142 | S11: =Maning!J11 -> 0.13888889 | T11: =S11*E11 -> 3183.3333 | U11: =Maning!K11 -> 0.11111111 | V11: =U11*E11 -> 2546.6667 | W11: =Maning!L11 -> 0.083333333 | X11: =W11*E11 -> 1910 | Y11: =Maning!M11 -> 0.11111111 | Z11: =Y11*E11 -> 2546.6667 | AA11: =Maning!N11 -> 0.11111111 | AB11: =AA11*E11 -> 2546.6667 | AC11: =Maning!O11 -> 0.27777778 | AD11: =AC11*E11 -> 6366.6667 | AE11: =Maning!P11 -> 0.027777778 | AF11: =AE11*E11 -> 636.66667 | AG11: =Maning!Q11 -> 0.16666667 | AH11: =AG11*E11 -> 3820 | AI11: =Maning!R11 -> 0.027777778 | AJ11: =AI11*E11 -> 636.66667 | AK11: =Maning!S11 -> 0 | AL11: =AK11*E11 -> 0 | AM11: =SUM(L11+N11+P11+R11+T11+V11+X11+Z11+AB11+AD11+AF11+AH11+AJ11+AL11) -> 68760 | AN11: =AM11*$E$17 -> 5500.8 | AO11: =AM11+AN11 -> 74260.8 | AP11: =AO11*$E$19 -> 1039.6512 | AQ11: =AO11+AP11 -> 75300.451 | AR11: =AQ11*$E$21 -> 10542.063 | AS11: =AQ11+AR11 -> 85842.514 | AT11: =AS11/C11 -> 28614.171
B12: ='Manpower CTC'!B11 -> Site Manager | C12: =K12+M12+O12+Q12+S12+U12+W12+Y12+AA12+AC12+AE12+AG12+AI12 -> 1 | E12: ='Manpower CTC'!C11 -> 52170 | F12: =C12*E12 -> 52170 | H12: =C12-(K12+M12+O12+Q12+S12+U12+W12+Y12+AA12+AC12+AE12+AG12+AI12+AK12) -> 0 | I12: =F12-(L12+N12+P12+R12+T12+V12+X12+Z12+AB12+AD12+AF12+AH12+AJ12+AL12) -> 0 | K12: =Maning!F12 -> 0.21532703 | L12: =E12*K12 -> 11233.611 | M12: =Maning!G12 -> 0.10855004 | N12: =M12*E12 -> 5663.0556 | O12: =Maning!H12 -> 0.1142632 | P12: =O12*E12 -> 5961.1111 | Q12: =Maning!I12 -> 0.21000788 | R12: =Q12*E12 -> 10956.111 | S12: =Maning!J12 -> 0.046296296 | T12: =S12*E12 -> 2415.2778 | U12: =Maning!K12 -> 0.037037037 | V12: =U12*E12 -> 1932.2222 | W12: =Maning!L12 -> 0.027777778 | X12: =W12*E12 -> 1449.1667 | Y12: =Maning!M12 -> 0.037037037 | Z12: =Y12*E12 -> 1932.2222 | AA12: =Maning!N12 -> 0.037037037 | AB12: =AA12*E12 -> 1932.2222 | AC12: =Maning!O12 -> 0.092592593 | AD12: =AC12*E12 -> 4830.5556 | AE12: =Maning!P12 -> 0.0092592593 | AF12: =AE12*E12 -> 483.05556 | AG12: =Maning!Q12 -> 0.055555556 | AH12: =AG12*E12 -> 2898.3333 | AI12: =Maning!R12 -> 0.0092592593 | AJ12: =AI12*E12 -> 483.05556 | AK12: =Maning!S12 -> 0 | AL12: =AK12*E12 -> 0 | AM12: =SUM(L12+N12+P12+R12+T12+V12+X12+Z12+AB12+AD12+AF12+AH12+AJ12+AL12) -> 52170 | AN12: =AM12*$E$17 -> 4173.6 | AO12: =AM12+AN12 -> 56343.6 | AP12: =AO12*$E$19 -> 788.8104 | AQ12: =AO12+AP12 -> 57132.41 | AR12: =AQ12*$E$21 -> 7998.5375 | AS12: =AQ12+AR12 -> 65130.948 | AT12: =AS12/C12 -> 65130.948
B13: ='Manpower CTC'!B12 -> Sales Center Labor | C13: =AK13 -> 30 | E13: ='Manpower CTC'!C12 -> 6820 | F13: =C13*E13 -> 204600 | H13: =C13-(K13+M13+O13+Q13+S13+U13+W13+Y13+AA13+AC13+AE13+AG13+AI13+AK13) -> 0 | I13: =F13-(L13+N13+P13+R13+T13+V13+X13+Z13+AB13+AD13+AF13+AH13+AJ13+AL13) -> 0 | K13: =Maning!F13 -> 0 | L13: =E13*K13 -> 0 | M13: =Maning!G13 -> 0 | N13: =M13*E13 -> 0 | O13: =Maning!H13 -> 0 | P13: =O13*E13 -> 0 | Q13: =Maning!I13 -> 0 | R13: =Q13*E13 -> 0 | S13: =Maning!J13 -> 0 | T13: =S13*E13 -> 0 | U13: =Maning!K13 -> 0 | V13: =U13*E13 -> 0 | W13: =Maning!L13 -> 0 | X13: =W13*E13 -> 0 | Y13: =Maning!M13 -> 0 | Z13: =Y13*E13 -> 0 | AA13: =Maning!N13 -> 0 | AB13: =AA13*E13 -> 0 | AC13: =Maning!O13 -> 0 | AD13: =AC13*E13 -> 0 | AE13: =Maning!P13 -> 0 | AF13: =AE13*E13 -> 0 | AG13: =Maning!Q13 -> 0 | AH13: =AG13*E13 -> 0 | AI13: =Maning!R13 -> 0 | AJ13: =AI13*E13 -> 0 | AK13: =Maning!S13 -> 30 | AL13: =AK13*E13 -> 204600 | AM13: =SUM(L13+N13+P13+R13+T13+V13+X13+Z13+AB13+AD13+AF13+AH13+AJ13+AL13) -> 204600 | AN13: =AM13*$E$17 -> 16368 | AO13: =AM13+AN13 -> 220968 | AP13: =AO13*$E$19 -> 3093.552 | AQ13: =AO13+AP13 -> 224061.55 | AR13: =AQ13*$E$21 -> 31368.617 | AS13: =AQ13+AR13 -> 255430.17 | AT13: =AS13/C13 -> 8514.339
B14: ='Manpower CTC'!B13 -> Sales Center supervisor | C14: =AK14 -> 3 | E14: ='Manpower CTC'!C13 -> 11370 | F14: =C14*E14 -> 34110 | H14: =C14-(K14+M14+O14+Q14+S14+U14+W14+Y14+AA14+AC14+AE14+AG14+AI14+AK14) -> 0 | I14: =F14-(L14+N14+P14+R14+T14+V14+X14+Z14+AB14+AD14+AF14+AH14+AJ14+AL14) -> 0 | K14: =Maning!F14 -> 0 | L14: =E14*K14 -> 0 | M14: =Maning!G14 -> 0 | N14: =M14*E14 -> 0 | O14: =Maning!H14 -> 0 | P14: =O14*E14 -> 0 | Q14: =Maning!I14 -> 0 | R14: =Q14*E14 -> 0 | S14: =Maning!J14 -> 0 | T14: =S14*E14 -> 0 | U14: =Maning!K14 -> 0 | V14: =U14*E14 -> 0 | W14: =Maning!L14 -> 0 | X14: =W14*E14 -> 0 | Y14: =Maning!M14 -> 0 | Z14: =Y14*E14 -> 0 | AA14: =Maning!N14 -> 0 | AB14: =AA14*E14 -> 0 | AC14: =Maning!O14 -> 0 | AD14: =AC14*E14 -> 0 | AE14: =Maning!P14 -> 0 | AF14: =AE14*E14 -> 0 | AG14: =Maning!Q14 -> 0 | AH14: =AG14*E14 -> 0 | AI14: =Maning!R14 -> 0 | AJ14: =AI14*E14 -> 0 | AK14: =Maning!S14 -> 3 | AL14: =AK14*E14 -> 34110 | AM14: =SUM(L14+N14+P14+R14+T14+V14+X14+Z14+AB14+AD14+AF14+AH14+AJ14+AL14) -> 34110 | AN14: =AM14*$E$17 -> 2728.8 | AO14: =AM14+AN14 -> 36838.8 | AP14: =AO14*$E$19 -> 515.7432 | AQ14: =AO14+AP14 -> 37354.543 | AR14: =AQ14*$E$21 -> 5229.636 | AS14: =AQ14+AR14 -> 42584.179 | AT14: =AS14/C14 -> 14194.726
B15: ='Manpower CTC'!B14 -> Sales Center Assistant Manager | C15: =AK15 -> 1 | E15: ='Manpower CTC'!C14 -> 23420 | F15: =C15*E15 -> 23420 | H15: =C15-(K15+M15+O15+Q15+S15+U15+W15+Y15+AA15+AC15+AE15+AG15+AI15+AK15) -> 0 | I15: =F15-(L15+N15+P15+R15+T15+V15+X15+Z15+AB15+AD15+AF15+AH15+AJ15+AL15) -> 0 | K15: =Maning!F15 -> 0 | L15: =E15*K15 -> 0 | M15: =Maning!G15 -> 0 | N15: =M15*E15 -> 0 | O15: =Maning!H15 -> 0 | P15: =O15*E15 -> 0 | Q15: =Maning!I15 -> 0 | R15: =Q15*E15 -> 0 | S15: =Maning!J15 -> 0 | T15: =S15*E15 -> 0 | U15: =Maning!K15 -> 0 | V15: =U15*E15 -> 0 | W15: =Maning!L15 -> 0 | X15: =W15*E15 -> 0 | Y15: =Maning!M15 -> 0 | Z15: =Y15*E15 -> 0 | AA15: =Maning!N15 -> 0 | AB15: =AA15*E15 -> 0 | AC15: =Maning!O15 -> 0 | AD15: =AC15*E15 -> 0 | AE15: =Maning!P15 -> 0 | AF15: =AE15*E15 -> 0 | AG15: =Maning!Q15 -> 0 | AH15: =AG15*E15 -> 0 | AI15: =Maning!R15 -> 0 | AJ15: =AI15*E15 -> 0 | AK15: =Maning!S15 -> 1 | AL15: =AK15*E15 -> 23420 | AM15: =SUM(L15+N15+P15+R15+T15+V15+X15+Z15+AB15+AD15+AF15+AH15+AJ15+AL15) -> 23420 | AN15: =AM15*$E$17 -> 1873.6 | AO15: =AM15+AN15 -> 25293.6 | AP15: =AO15*$E$19 -> 354.1104 | AQ15: =AO15+AP15 -> 25647.71 | AR15: =AQ15*$E$21 -> 3590.6795 | AS15: =AQ15+AR15 -> 29238.39 | AT15: =AS15/C15 -> 29238.39
B16: Total Head Count | C16: =SUM(C6:C15) -> 162 | F16: =SUM(F6:F15) -> 1251640 | H16: =C16-(K16+M16+O16+Q16+S16+U16+W16+Y16+AA16+AC16+AE16+AG16+AI16+AK16) -> 0 | I16: =F16-(L16+N16+P16+R16+T16+V16+X16+Z16+AB16+AD16+AF16+AH16+AJ16+AL16) -> 0 | K16: =SUM(K6:K15) -> 27.213948 | L16: =SUM(L6:L15) -> 209286.45 | M16: =SUM(M6:M15) -> 13.708038 | N16: =SUM(N6:N15) -> 105385.54 | O16: =SUM(O6:O15) -> 14.359338 | P16: =SUM(P6:P15) -> 110169.34 | Q16: =SUM(Q6:Q15) -> 26.607565 | R16: =SUM(R6:R15) -> 204832.57 | ... AS16: =SUM(AS6:AS15) -> 1562593.4
B17: Gross Margin & Contingency | E17: ='HK Budget (2)'!C14 -> 0.08 | F17: =F16*$E$17 -> 100131.2 | H17: =C17-(K17+M17+O17+Q17+S17+U17+W17+Y17+AA17+AC17+AE17+AG17+AI17+AK17) -> 0 | I17: =F17-(L17+N17+P17+R17+T17+V17+X17+Z17+AB17+AD17+AF17+AH17+AJ17+AL17) -> 0 | L17: =L16*$E$17 -> 16742.916 | N17: =N16*$E$17 -> 8430.843 | P17: =P16*$E$17 -> 8813.547 | R17: =R16*$E$17 -> 16386.605 | T17: =T16*$E$17 -> 3970.8222 | V17: =V16*$E$17 -> 2977.8921 | X17: =X16*$E$17 -> 2233.419 | Z17: =Z16*$E$17 -> 2915.7778 | AB17: =AB16*$E$17 -> 2915.7778 | AD17: =AD16*$E$17 -> 7941.6444 | AF17: =AF16*$E$17 -> 728.94444 | AH17: =AH16*$E$17 -> 4373.6667 | AJ17: =AJ16*$E$17 -> 728.94444 | AL17: =AL16*$E$17 -> 20970.4
B18: Total | F18: =F16+F17 -> 1351771.2 | H18: =C18-(K18+M18+O18+Q18+S18+U18+W18+Y18+AA18+AC18+AE18+AG18+AI18+AK18) -> 0 | I18: =F18-(L18+N18+P18+R18+T18+V18+X18+Z18+AB18+AD18+AF18+AH18+AJ18+AL18) -> 0 | L18: =L16+L17 -> 226029.36 | N18: =N16+N17 -> 113816.38 | P18: =P16+P17 -> 118982.89 | R18: =R16+R17 -> 221219.17 | T18: =T16+T17 -> 53606.1 | V18: =V16+V17 -> 40201.543 | X18: =X16+X17 -> 30151.157 | Z18: =Z16+Z17 -> 39363 | AB18: =AB16+AB17 -> 39363 | AD18: =AD16+AD17 -> 107212.2 | AF18: =AF16+AF17 -> 9840.75 | AH18: =AH16+AH17 -> 59044.5 | AJ18: =AJ16+AJ17 -> 9840.75 | AL18: =AL16+AL17 -> 283100.4
B19: Insurance | E19: ='HK Budget (2)'!C16 -> 0.014 | F19: =F18*$E$19 -> 18924.797 | H19: =C19-(K19+M19+O19+Q19+S19+U19+W19+Y19+AA19+AC19+AE19+AG19+AI19+AK19) -> 0 | I19: =F19-(L19+N19+P19+R19+T19+V19+X19+Z19+AB19+AD19+AF19+AH19+AJ19+AL19) -> 0 | L19: =L18*$E$19 -> 3164.4111 | N19: =N18*$E$19 -> 1593.4293 | P19: =P18*$E$19 -> 1665.7604 | R19: =R18*$E$19 -> 3097.0684 | T19: =T18*$E$19 -> 750.4854 | V19: =V18*$E$19 -> 562.8216 | X19: =X18*$E$19 -> 422.1162 | Z19: =Z18*$E$19 -> 551.082 | AB19: =AB18*$E$19 -> 551.082 | AD19: =AD18*$E$19 -> 1500.9708 | AF19: =AF18*$E$19 -> 137.7705 | AH19: =AH18*$E$19 -> 826.623 | AJ19: =AJ18*$E$19 -> 137.7705 | AL19: =AL18*$E$19 -> 3963.4056
B20: Total Revenue | F20: =F18+F19 -> 1370696 | H20: =C20-(K20+M20+O20+Q20+S20+U20+W20+Y20+AA20+AC20+AE20+AG20+AI20+AK20) -> 0 | I20: =F20-(L20+N20+P20+R20+T20+V20+X20+Z20+AB20+AD20+AF20+AH20+AJ20+AL20) -> 0 | L20: =L18+L19 -> 229193.77 | N20: =N18+N19 -> 115409.81 | P20: =P18+P19 -> 120648.65 | R20: =R18+R19 -> 224316.24 | T20: =T18+T19 -> 54356.585 | V20: =V18+V19 -> 40764.364 | X20: =X18+X19 -> 30573.273 | Z20: =Z18+Z19 -> 39914.082 | AB20: =AB18+AB19 -> 39914.082 | AD20: =AD18+AD19 -> 108713.17 | AF20: =AF18+AF19 -> 9978.5205 | AH20: =AH18+AH19 -> 59871.123 | AJ20: =AJ18+AJ19 -> 9978.5205 | AL20: =AL18+AL19 -> 287063.81
