Workbook

Sheet General Notes & SOW Summary
A1: General Notes:- 1- Total Area of the tender of phase one 11 feddan with total 6 clusters ( 30 buildings ) and total number of units 398 2- Msquared will provide furnished offices and store and 2 caravans for night shift accomodation 3- Laptops and internet connections will be supplied by service provider 4- Offer includes staff insurance and transportation to site 5- Gate and the main road will be within service provider responsibilty 6- CAFM system will be an optional item with separate price 7- Storage Cycle:- All trades spare parts mentioned in the attached files will be provided monthly by the service provider and to enter Msquared ready storage area by reciepts and direct approval for issuing, discharging and using by Msquared to be used by the service provider on site and automatically re-purchased each month as needed and mentioned in the BOQ 8- Any Additional Spare parts or consumbales will be sent from the service provider as a Separate invoice i=with markup 9- Check in and out machine will be provided by service provider for all staff to be shared daily with Msquared a full report for all service provider staff attendance 10- Data sheets, MSDS of the used materials and vendors lists to be shared by the service provider. 11- Payment terms to be within 60 days from invoice recieve by Msquared 12- Asset register, list and zone coding, action plans, weekly and monthly reports to be done by service provider upon starting, In addition to check lists and PPMs for all trades.
A3: House Keeping
A5: 1- Scope | B5: Detailed SOW is attached in files Annex (C) while the below is the summary for the general scope:- a- Daily cleaning of streets, walkways, landscaped areas and waste collection across phase one. b- Daily cleaning and polishing of building entrances, lobbies, staircases, elevators and common areas will be carried out. c-Basements and gates to be maintained through sweeping, mopping, polishing and high-pressure washing. d-Weekly and monthly tasks include façade cleaning, deep cleaning of floors, glass and grills. e-Public facilities such as Community Center, padel courts, commercial areas and offices will be cleaned, sanitized and polished regularly. f-Garbage collection, Litter control, segregation and transfer to designated disposal points will be ensured on a daily basis.
A6: 2- Manpower & Working Shift | B6: Total Janitors = 75 (69 Morning shift + 6 Night Shift) Total Supervisors = 3 (2 Morning shift + 1 Night Shift) Morning Shift (8 AM to 5 PM) (Including 1 Hour Break from 12pm to 1pm) Night shift (5 PM to 12 AM)
A8: 3- General HK Notes | B8: 1- Scope will be including staff uniform with logo Msquared and Service provider, tools, machines and monthly consumables (for quantities please refer to the HK BOQ Annex (C) attached) and performed by well-trained and appropriately dressed staff mentioned above. 2-Grabage pin will be supplied by M Squared, However the garbage bags will be supplied by the service provider (for quantities please refer to the HK BOQ Annex (C) 3-Disposing watse outside the project is the service provider reponsability, also the same for the agricultural waste. 4-There will be periodicaly facade cleaning as mentioned in detailed in the HK BOQ Annex (C) (When and How to perform it) 5-Supplying tissues mentioned in the zones mentioned in the HK BOQ Annex (C) consumables file only monthly will be in service provider scope 6-HK orders inside the tenants units will be included in the offer and will be performed by the staff requested and mentioned above by Msquared using the tools and Consumables required mentioned in details in the HK BOQ in Annex (C) and to included in the offer. 7-Cleaning bed, mattress, curtains sheets in the project mockup will be service provider scope and will be performed twice monthly as mentioned in the HK BOQ. 8- Plantings and agricultural wastes collecting will be performed by the service provider through LS workers, However collecting litter from landscape areas will be included in HK scope. 9-Implement zone coding for efficient management and tracking, In addition to providing weekly and monthly reports on cleaning performance and maintenance
A15: Total HK
A17: MEP + Civil + Pump Station (Public)
A18: 1- Scope | B18: The service provider shall be responsible for the operation, preventive and corrective maintenance of all MEP and Civil systems within the compound’s public and common areas. Detailed SOW attached with other files in Annex (F) and below is the summary of the scope covers the following disciplines: 1. MEP (Mechanical, Electrical, Plumbing & Fire) a- Mechanical (HVAC & General) • Ensuring proper operation of all mechanical systems in accordance with maintenance schedules. • Preventive maintenance for all HVAC units (ACs in gym, offices, gates, etc.) • Maintenance of pumps & Mechanical parts: pool, Domestic, fire pumps, irrigation, fountains, ventilation fans, sump pumps, Garbage chute, etc. • Generator fluid checks (oil, water, fuel), inspection & cleaning. • Firefighting checks including (Extinguishers, sprinklers, cabins, etc.) • Daily reporting and coordination with multi-disciplinary team. b- Electrical & Light Current • Daily inspection of transformers, MDBs and distribution panels. • Monitoring and logging of generator operation and loads. • Maintenance of lighting: landscape, staircases, ramps and common areas. • Elevators, intercom, access control, CCTV and automation systems. • Monthly preventive maintenance for panels and backup systems. • Fire alarm system checks (panels, detectors, sounders, etc.). c- Plumbing • Inspection and maintenance of stormwater and all drainage networks. • Inspection and maintenance of Submersible pumps. • Daily inspection of all water valves. • ensuring leak-free operation of water supply, irrigation, and sewage systems. • Water tank disinfection and filter cleaning. • Fire plumbing systems: hydrants, cabinets, sprinklers, etc. • Maintenance of sanitary systems in gym, offices, Mockup and public toilets. d- Fire System • Back-to-back contract with fire system specialist (Bavaria). • Monthly drills and staff training. • Full inspection of fire valves, fire cabinets, extinguishers, sprinklers, CO sensors and alarm systems. • Testing of control panels, pressure and emergency systems. e- Swimming Pools & Fountains • Daily cleaning and chemical treatment with PH & Chlorine level checks of ~150 private pools + 3 fountains. • Daily inspection and reporting for Electrical panel/Timer operation, lighting, skimmers, motor and room leakage with weekly and monthly reports. ________________________________________ 2. Civil (Public Area Maintenance) • Inspection and maintenance of doors (fire cabinets, rubbish rooms, etc.). • Checking and fixing signage (EXIT signs, directional boards). • Inspection of interlock tiles, Façades, marble, gypsum, aluminum and paint finishes across common areas. • Repairs to woodworks, pergolas, and decorative elements in landscape. • Maintenance of ramps, manhole covers, drainage grates, mirrors, and stair railings. • Reporting structural damages, cracked floors, loose elements, etc. • Ensuring secure fixing of electrical/communication panels and systems in public areas. ________________________________________ 3. Water Pump Station • Full-time operation and monitoring of potable, irrigation and fire water pumping stations. • Scheduled preventive maintenance for all pumps and electrical panels. • Monitoring pump performance, pressures and motor temperatures. • Leak detection and valve operation checks. • Float valve and ultrasonic level control inspections. • Coordination with external vendors for disinfection every 3 months. • Emergency generator support, panel inspection and safety system maintenance. • Safety measures: locked panels, no unauthorized access, air vent and vent mesh checks.
A56: 2- General MEP + Civil Public Notes | B56: *Diesel supply will be provided through msquared. *Diesel Filling will be done through the service provider. *For refilling fire extinguishers, within Service provider scope (refer to Annex (F) *Service provider will responsible for the disinfection of water tanks and swimming pools ( 3 Fountains and around 113 private swimming pools 12 m3 each) *The cleaning and disinfection of the water tanks (Pump room or Temperoray tanks) are within the service provider scope each quarter *Service provider will responsible for RO system, sewage, water supply and pump station *Electricity will be provided by owned and rented generators (service provider operation and maintenance responsibility) while the solar will be provided by Msquared and filled by service provider while water will be provided from both goverement main line and arabs. *Maintenance visits for the specialized systems like (Kone, fire system, shira, Smart Home Automation System) will be within service provider scope by Back-to-Back contract, while supplying the required spare parts if needed and agreed by Msquared will be with additional price with the agreed markup% *Providing Scaffoldings and spider equipment to be approved by service provider safety manager and will be supplied by service provider refer to Annex (F) *Back to back contract will be done by service provider with Fire system and Safety company and to be revised by Msquared including all fire system with specialezed company to provide 1 technician with the tools needed for morning and night shift (12 hours) to be with direct audit from service provider, any additional parts or consumables will be as a variation quotation to be paid by msquared. *Back to back elevators contract with kone to be revised by Msquared for monthly maintenance of 30 elevators in all phase one + providing a technician available on site from kone morning and night shift (12 hours), any additional parts or consumables will be as a variation quotation to be paid by msquared. *Back to back generators contract with Elreyada and Taka companies to be revised by Msquared for monthly maintenance including oil and filters of owned and rented generators + providing one technician from each company available on site from morning and night shift (12 hours), any additional parts or consumables will be as a variation quotation to be paid by msquared.
A57: Total MEP + Civil + Pump Station (Public)
A58: Inside Units MEP + Civil
A59: 1- Scope | B59: Detailed SOW attached with other files in Annex (G) and below is the summary of the scope covers the following disciplines A. Maintenance Services (Civil, MEP, Pools, Gardening) • Handle all internal client maintenance requests for Civil, MEP, Swimming Pools, and Gardening including (painting, carpentry, plumbing, electrical, aluminum works, marble, ceramics, grouting, AC servicing, etc.) • Service response and closure to follow attached SLA timelines, with documented client satisfaction survey and to be compiled and submitted (signed). • Technicians to be equipped with necessary consumables, hand tools, and machines (e.g., drill machine, compressor, disc cutter). • Paid services inside units to be collected by service provider and to be recorded with official receipts issued and amounts deducted from monthly invoice. • Daily, weekly and monthly maintenance reports to be submitted to M-squared Representative. B. Spare Parts & Extra Work • All required spare parts and materials to be purchased by the service provider at market price within 24 hours. • Any work in public/common areas requires: *A separate quotation. *A Work Order issued by M-squared Representative. *A separate invoice after technical and financial approval. C. Technical & Operational Requirements • Technicians and laborers must be qualified and trained, wearing unified, approved uniform (subject to M-squared approval) and follow safe working practices and procedures. • Transportation (to/from site and within site) and indirect overheads are provider’s responsibility. While accommodation for night shift is provided by M-squared in on-site caravans. • M-squared is responsible to provide Furnished storage area on site for tools and spare part and furnished caravans for offices while service provider to supply laptops and internet. • Staff must be: *Qualified, experienced and fully trained to work inside residential units. *Equipped with overshoes, plastic gloves and masks (included in offer). • No absenteeism or crew shortage allowed during crew changes. • Provider must: *Manage vacations and relievers to maintain full operational staff year-round. *Submit CVs of engineers, supervisors, and management for M-squared approval. • M-squared retains the right to: *Adjust staffing and resource levels based on occupancy rates and cluster opening timelines.
A81: 2- General Inside Units MEP + Civil Notes | B81: *Inside units paid service requests is within the scope and the cost as per the price list that will be agreed by Msquared and shared with the clients will be collected by the service provider and then will be deducted from the monthly invoice *Experienced staff and equipment and tools suitable for working inside units *Overshoes + Plastic gloves + masks for technicians inside the units with clients included *Back to Back contract with LS company to be revised by Msquared for smart home automation system to provide 1 techncian in a morning shift 8am to 8pm with the needed tools for operating and maintian inside units systems, any additional parts or consumables will be as a variation quotation to be paid by msquared. *Back to Back contract with Shira company to be revised by Msquared for private gardens irrigation system to provide 1 techncian morning shift 8am to 8pm with the needed tools for operating and maintian inside units irrigation systems including batteries, valves, irrigation fittings and any devices from Hunter company in the gardens, any additional parts or consumables will be as a variation quotation to be paid by msquared. *Scaffoldings and spider tools is included inside the scope under supervision of safety engineer included with service provider staff needded and applying safety rules. *Clients staisfaction forms and NPS is crutial and will be with a high score for evaluating service provider in the monthly KPI
A82: Total Inside Units (MEP + Civil)
A83: Landscape (Public + Internal Gardens)
A85: Scope Landscape Public + Inside Gardens | B85: 1- Regarding detailed scope of work for Landscape public common areas, inside gardens and type of plants and areas please refer to files of Annex (E) 2- Detailed machines, tools and machines required for both public and inside units are mentioned in details in Annex (E) 3- Monthly and yearly consumables used for fertilization and pesticides are mentioned in details in Annex (E) consumables needed 4-Working Days for all the required manpower 6 days (All week Except Friday) morning shift only from 8am to 5pm
A105: Total Landscape (Public + Internal)
A106: Pest Control
A107: Scope Pest Control | B107: 1- Regarding detailed scope of work for pest control please refer to files of Annex (D) 2- Stray animal control should be provided when needed on site accoridng to regulation of Animal welfare association 3- Detailed machines, tools and machines required for both public and inside units are mentioned in details in Annex (D) tools and machines 4- Monthly and needed consumables used for traps and pesticides are mentioned in details in Annex (D) consumables
A117: Total Pest Control
A118: Back Office & Helpdesk
A119: Scope Back office & Helpdesk | B119: 1- Helpdesk with 2 hotline numbers available 24/7 will be responsible for recieving public and internal requests at morning and night shift 2- Requests to be dispatched by the dispatcher to the concerned trade public or internal with tickets, priorties and SLAs 3- Admin will be responsible for admin works, reports and dc files 4- Duty night shift manager will be responsible for all the site at night shift

Sheet Budget Summary
A3: Service Line | B3: Annual Ex. VAT | C3: Annual Including VAT | F3: OLD | H3: Target Annual | J3: Equation | K3: Target Monthly
A4: Houskeeping | B4: {='Housekeeping Scope BOQ'!G4:I4} -> 12391373 | C4: 0 | D4: 0 | F4: 13767521 | H4: =B4+(B4*B$15) -> 11023826 | I4: =H4-B4 -> -1367546.6 | J4: =I4/12 -> -113962.22 | K4: -94052.735
A5: MEP | B5: {='MEP Scope BOQ '!G4:I4} -> 14171832 | C5: 0 | D5: 0 | F5: 12832044 | H5: =B5+(B5*B$15) -> 12607789 | I5: =H5-B5 -> -1564043 | J5: =I5/12 -> -130336.92 | K5: -93544.446
A6: Landscape | B6: {='Landscape BOQ'!G4:I4} -> 4740720 | C6: 0 | D6: 0 | F6: 4928940 | H6: =B6+(B6*B$15) -> 4217520.9 | I6: =H6-B6 -> -523199.12 | J6: =I6/12 -> -43599.927 | K6: -35931.529
A7: Pest Conrol | B7: {='Pest Control BOQ'!G4:I4} -> 855360 | C7: 0 | D7: 0 | F7: 870912 | H7: =B7+(B7*B$15) -> 760960.08 | I7: =H7-B7 -> -94399.923 | J7: =I7/12 -> -7866.6602 | K7: -6348.8701
A8: Backoffice & Admin | B8: {='Backoffice & Admin BOQ'!G4:I4} -> 2351136 | C8: 0 | D8: 0 | F8: 2111316 | H8: =B8+(B8*B$15) -> 2091658.1 | I8: =H8-B8 -> -259477.95 | J8: =I8/12 -> -21623.162 | K8: -15391.304
B9: =SUM(B4:B8) -> 34510421 | F9: =SUM(F4:F8) -> 34510733 | G9: =F9-B9 -> 312 | H9: =B9+(B9*B$15) -> 30701754 | I9: =H9-B9 -> -3808666.6 | J9: =I9/12 -> -317388.88
B10: =B9*1.14 -> 39341880 | C10: =B10/12 -> 3278490 | H10: =H9*1.14 -> 35000000
B11: 35000000 | H11: =H9/12 -> 2558479.5
B12: =B11-B10 -> -4341879.9
B13: =B12/12 -> -361823.33
B15: =B13/(B10/12) -> -0.1103628

Sheet Housekeeping Scope BOQ
A1: TFM Package for TRIO 2025 housekeeping section | G1: FMPlus
F2: Total Incl VAT | G2: =G4+G3 -> 14126165
F3: VAT | G3: =G4*0.14 -> 1734792.2
F4: Total | G4: =SUM(I8:I12)+SUM(I14:I32) -> 12391373 | J4: =G4/12 -> 1032614.4 | K4: 0.02 | L4: =K4*J4 -> 20652.288
A6: Service Provider Manpower Resource | D6: Shifts | E6: Qty/month | F6: Months | G6: Monthly rate | H6: Monthly Total fees | I6: Annual Total Fees
A7: The fee includes the salaries, Taxes, internal transportation, external transportation, uniform, light tools (ANNEX 4) ,
A8: TFM Site Manager ( MEP Engineer with 5-7 Years Experience ) | D8: Morning 5 days aweek 8:00 AM - 4:00 PM | E8: 1 | F8: 12 | G8: ='HK Budget'!K5 -> 89480 | H8: =G8*E8 -> 89480 | I8: =H8*F8 -> 1073760
A9: HK Manager (4-6 years experience) | D9: Morning (6 days aweek 8:00 AM - 5:00 PM | E9: 1 | F9: 12 | G9: ='HK Budget'!K6 -> 43746 | H9: =G9*E9 -> 43746 | I9: =H9*F9 -> 524952
A10: HK Janitors | D10: Morning (7 days aweek 8:00 AM - 4:00 PM | E10: 44 | F10: 12 | G10: ='HK Budget'!K7 -> 11675 | H10: =G10*E10 -> 513700 | I10: =H10*F10 -> 6164400
A11: HK Janitors | D11: Night (7 days aweek 4:00 PM - 12:00 PM | E11: 5 | F11: 12 | G11: ='HK Budget'!K8 -> 11675 | H11: =G11*E11 -> 58375 | I11: =H11*F11 -> 700500
A12: HK Supervisors | D12: Morning (7 days aweek 8:00 AM - 5:00 PM (Break 12PM - 1PM) | E12: 2 | F12: 12 | G12: ='HK Budget'!K9 -> 25353 | H12: =G12*E12 -> 50706 | I12: =H12*F12 -> 608472
A13: Major Equipment, Tools (ANNEX 3 For referance &"Photos") RENTAL BASIS
A14: عربة كنس الشوارع Sweeper | E14: 2 | F14: 12 | G14: ='HK Budget'!H44 -> 42916.667 | H14: =G14*E14 -> 85833.333 | I14: =H14*F14 -> 1030000
A15: Ride On | E15: 1 | G15: ='HK Budget'!H45 -> 22316.667 | H15: =G15*E15 -> 22316.667 | I15: =H15*F14 -> 267800
A16: سلم هيدروليك كهرباء 10 او 12 متر | B16: One Week / Month | E16: 1 | F16: 12 | G16: ='HK Budget'!H46 -> 80000 | H16: =G16*E16 -> 80000 | I16: =H16*F16 -> 960000
A17: manlift بارتفاع 20 الي 30 متر | B17: One Week / Month | E17: 1 | F17: 12 | G17: ='HK Budget'!H47 -> 45000 | H17: =G17*E17 -> 45000 | I17: =H17*F17 -> 540000
A18: Single Disc | E18: 5 | F18: 12 | G18: ='HK Budget'!H48 -> 1630.8333 | H18: =G18*E18 -> 8154.1667 | I18: =H18*F18 -> 97850
A19: لبادة حمراء شهريا | E19: 6 | F19: 12 | G19: ='HK Budget'!H49 -> 278.1 | H19: =G19*E19 -> 1668.6 | I19: =H19*F19 -> 20023.2
A20: لبادة بيضاء شهريا | E20: 6 | F20: 12 | G20: ='HK Budget'!H50 -> 278.1 | H20: =G20*E20 -> 1668.6 | I20: =H20*F20 -> 20023.2
A21: لبادة سوداء شهريا | E21: 6 | F21: 12 | G21: ='HK Budget'!H51 -> 23.175 | H21: =G21*E21 -> 139.05 | I21: =H21*F21 -> 1668.6
A22: Hoover 6 Liter مكنسة | E22: 6 | F22: 12 | G22: ='HK Budget'!H52 -> 1287.5 | H22: =G22*E22 -> 7725 | I22: =H22*F22 -> 92700
A23: بلاور | E23: 3 | F23: 12 | G23: ='HK Budget'!H53 -> 515 | H23: =G23*E23 -> 1545 | I23: =H23*F23 -> 18540
A24: High Pressure | E24: 2 | F24: 12 | G24: ='HK Budget'!H54 -> 3862.5 | H24: =G24*E24 -> 7725 | I24: =H24*F24 -> 92700
A25: ترولي كبير public area لوضع العدة | E25: 7 | F25: 12 | G25: ='HK Budget'!H55 -> 729.58333 | H25: =G25*E25 -> 5107.0833 | I25: =H25*F25 -> 61285
A26: ترولي كبير 770 لتر | E26: 2 | F26: 12 | G26: ='HK Budget'!H56 -> 1459.1667 | H26: =G26*E26 -> 2918.3333 | I26: =H26*F26 -> 35020
A27: ترولي صغير 240 لتر | E27: 2 | F27: 12 | G27: ='HK Budget'!H57 -> 214.58333 | H27: =G27*E27 -> 429.16667 | I27: =H27*F27 -> 5150
A28: ترولي بجردلين و عصارة (الجردل 2 عين) بالشرشوبة او الموب | E28: 6 | F28: 12 | G28: ='HK Budget'!H58 -> 386.25 | H28: =G28*E28 -> 2317.5 | I28: =H28*F28 -> 27810
A29: سلم الومنيوم مجوز 2 متر | E29: 6 | F29: 12 | G29: ='HK Budget'!H59 -> 227.45833 | H29: =G29*E29 -> 1364.75 | I29: =H29*F29 -> 16377
... A32: ترولي كبير 770 لتر | E32: 1 | F32: 12 | G32: ='HK Budget'!H62 -> 1459.1667 | H32: =G32*E32 -> 1459.1667 | I32: =H32*F32 -> 17510
A33: Markup percentage on Separate invoices (consumables "ANNEX 2", back to back contracts. Emergencies) | E33: 0.1
A34: Annual Increasing Percentage | E34: 0.1

Sheet HK Budget
A2: 1 | B2: Manpower | F2: 0.2
B4: # | C4: Position / Designation | D4: Working Hours | E4: Net Rate | F4: CTC Rate | G4: Head Count (Required) | H4: Head Count (Budget) | I4: Total CTC | K4: Offer Rate | M4: Totals
B5: 1 | C5: ='Housekeeping Scope BOQ'!A8 -> TFM Site Manager ( MEP Engineer with 5-7 Years Experience ) | D5: ='Housekeeping Scope BOQ'!D8 -> Morning 5 days aweek 8:00 AM - 4:00 PM | E5: 45000 | F5: =E5+(F$2*E5) -> 54000 | G5: ='Housekeeping Scope BOQ'!E8 -> 1 | H5: =G5 -> 1 | I5: =H5*F5 -> 54000 | K5: =ROUND((I5/(1-F$36))/G5,0) -> 89480 | M5: =K5*G5 -> 89480
B6: 2 | C6: ='Housekeeping Scope BOQ'!A9 -> HK Manager (4-6 years experience) | D6: ='Housekeeping Scope BOQ'!D9 -> Morning (6 days aweek 8:00 AM - 5:00 PM | E6: 22000 | F6: =E6+(F$2*E6) -> 26400 | G6: ='Housekeeping Scope BOQ'!E9 -> 1 | H6: =G6 -> 1 | I6: =H6*F6 -> 26400 | K6: =ROUND((I6/(1-F$36))/G6,0) -> 43746 | M6: =K6*G6 -> 43746
B7: 3 | C7: ='Housekeeping Scope BOQ'!A10 -> HK Janitors | D7: ='Housekeeping Scope BOQ'!D10 -> Morning (7 days aweek 8:00 AM - 4:00 PM | E7: 5500 | F7: 6200 | G7: ='Housekeeping Scope BOQ'!E10 -> 44 | H7: 50 | I7: =H7*F7 -> 310000 | K7: =ROUND((I7/(1-F$36))/G7,0) -> 11675 | M7: =K7*G7 -> 513700
B8: 4 | C8: ='Housekeeping Scope BOQ'!A11 -> HK Janitors | D8: ='Housekeeping Scope BOQ'!D11 -> Night (7 days aweek 4:00 PM - 12:00 PM | E8: 5500 | F8: 6200 | G8: ='Housekeeping Scope BOQ'!E11 -> 5 | H8: =ROUNDUP(G8+(G8/6),0) -> 6 | I8: =H8*F8 -> 37200 | K8: =K7 -> 11675 | M8: =K8*G8 -> 58375
B9: 5 | C9: ='Housekeeping Scope BOQ'!A12 -> HK Supervisors | D9: ='Housekeeping Scope BOQ'!D12 -> Morning (7 days aweek 8:00 AM - 5:00 PM (Break 12PM - 1PM) | E9: 8500 | F9: =E9+(F$2*E9) -> 10200 | G9: ='Housekeeping Scope BOQ'!E12 -> 2 | H9: 3 | I9: =H9*F9 -> 30600 | K9: =ROUND((I9/(1-F$36))/G9,0) -> 25353 | M9: =K9*G9 -> 50706
B10: 6 | C10: ='[1]Housekeeping Scope BOQ'!A13 -> HK Supervisors | E10: 9500 | F10: =E10+(F$2*E10) -> 11400 | G10: ='Housekeeping Scope BOQ'!E13 -> 0 | H10: =ROUNDUP(G10+(G10/3),1) -> 0 | I10: =H10*F10 -> 0 | K10: =IFERROR(ROUND((I10/(1-F$36))/G10,0),0) -> 0 | M10: =K10*G10 -> 0
H12: Total Manpower | I12: =SUM(I5:I10) -> 458200 | M12: =SUM(M5:M10) -> 756007
A15: 2 | B15: List Of Indirects
B17: # | C17: Item | D17: QTY | E17: Monthly Cost | F17: Total Costs
B18: 2.1 | C18: Uniform | D18: =SUM(H6:H10) -> 60 | E18: 500 | F18: =E18*D18 -> 30000
B19: 2.2 | C19: HK Light Consumables | D19: 0 | E19: ='HK - Light Tools & Cons'!$E$18 -> 65665 | F19: =E19*D19 -> 0
B20: 2.3 | C20: HK Light Tools | D20: 1 | E20: ='HK - Light Tools & Cons'!E46 -> 43029 | F20: =E20*D20 -> 43029
B21: 2.4 | C21: HK Equipment | D21: 0 | F21: =E21*D21 -> 0
B22: 2.5 | C22: HK Transportation - Inside Site With Fuel | D22: 0 | E22: 38500 | F22: =E22*D22 -> 0
B23: 2.6 | C23: HK Transportation - Outside Site | D23: =SUM(G6:G10) -> 52 | E23: 3000 | F23: =E23*D23 -> 156000
B24: 2.7 | C24: HK IT, Laptop, Printers | D24: 1 | E24: 3000 | F24: =E24*D24 -> 3000
E26: Total InD | F26: =SUM(F18:F24) -> 232029
A28: 3 | B28: Project OVH & GM
B30: # | C30: Item | D30: % | E30: Costs | F30: Total Costs
B31: 3.1 | C31: OVH | D31: 0 | E31: =(I12+F26) -> 690229 | F31: =E31*D31 -> 0
B32: 3.2 | C32: Gross Profit % | D32: 0.1 | E32: =E31 -> 690229 | F32: =E32*D32 -> 69022.9
E34: OVH&GM - Value | F34: =SUM(F31:F32) -> 69022.9
E36: InD % | F36: =(F34+F26)/(F34+F26+I12) -> 0.39651122
E38: Total With Profit | F38: =F34+F26+I12 -> 759251.9
A41: 4 | B41: List Of Heavy Equipment | F41: 0.03
B43: # | C43: Item | D43: QTY | E43: Cost / Item | F43: Profit | G43: Selling Price / Unit | H43: Monthly Rate / Unit
B44: 4.1 | C44: ='Housekeeping Scope BOQ'!A14 -> عربة كنس الشوارع Sweeper | D44: ='Housekeeping Scope BOQ'!E14 -> 2 | E44: 1000000 | F44: =E44*F$41 -> 30000 | G44: =F44+E44 -> 1030000 | H44: =G44/24 -> 42916.667 | I44: =H44/D44 -> 21458.333
B45: 4.2 | C45: ='Housekeeping Scope BOQ'!A15 -> Ride On | D45: ='Housekeeping Scope BOQ'!E15 -> 1 | E45: 1300000 | F45: =E45*F$41 -> 39000 | G45: =F45+E45 -> 1339000 | H45: =G45/60 -> 22316.667 | I45: =H45/D45 -> 22316.667
B46: 4.3 | C46: ='Housekeeping Scope BOQ'!A16 -> سلم هيدروليك كهرباء 10 او 12 متر | D46: ='Housekeeping Scope BOQ'!E16 -> 1 | E46: =7500*30 -> 225000 | F46: =E46*F$41 -> 6750 | G46: =F46+E46 -> 231750 | H46: 80000 | I46: =H46/D46 -> 80000
B47: 4.4 | C47: ='Housekeeping Scope BOQ'!A17 -> manlift بارتفاع 20 الي 30 متر | D47: ='Housekeeping Scope BOQ'!E17 -> 1 | F47: =E48*F$41 -> 1710 | G47: =F47+E48 -> 58710 | H47: 45000 | I47: =H47/D47 -> 45000
B48: 4.5 | C48: ='Housekeeping Scope BOQ'!A18 -> Single Disc | D48: ='Housekeeping Scope BOQ'!E18 -> 5 | E48: 57000 | F48: =E48*F$41 -> 1710 | G48: =F48+E48 -> 58710 | H48: =G48/36 -> 1630.8333 | I48: =H48/D48 -> 326.16667
B49: 4.6 | C49: ='Housekeeping Scope BOQ'!A19 -> لبادة حمراء شهريا | D49: ='Housekeeping Scope BOQ'!E19 -> 6 | E49: 270 | F49: =E49*F$41 -> 8.1 | G49: =F49+E49 -> 278.1 | H49: =G49 -> 278.1 | I49: =H49/D49 -> 46.35
B50: 4.7 | C50: ='Housekeeping Scope BOQ'!A20 -> لبادة بيضاء شهريا | D50: ='Housekeeping Scope BOQ'!E20 -> 6 | E50: 270 | F50: =E50*F$41 -> 8.1 | G50: =F50+E50 -> 278.1 | H50: =G50 -> 278.1 | I50: =H50/D50 -> 46.35
B51: 4.8 | C51: ='Housekeeping Scope BOQ'!A21 -> لبادة سوداء شهريا | D51: ='Housekeeping Scope BOQ'!E21 -> 6 | E51: 270 | F51: =E51*F$41 -> 8.1 | G51: =F51+E51 -> 278.1 | H51: =G51/12 -> 23.175 | I51: =H51/D51 -> 3.8625
B52: 4.9 | C52: ='Housekeeping Scope BOQ'!A22 -> Hoover 6 Liter مكنسة | D52: ='Housekeeping Scope BOQ'!E22 -> 6 | E52: 15000 | F52: =E52*F$41 -> 450 | G52: =F52+E52 -> 15450 | H52: =G52/12 -> 1287.5 | I52: =H52/D52 -> 214.58333
B53: 4.1 | C53: ='Housekeeping Scope BOQ'!A23 -> بلاور | D53: ='Housekeeping Scope BOQ'!E23 -> 3 | E53: 6000 | F53: =E53*F$41 -> 180 | G53: =F53+E53 -> 6180 | H53: =G53/12 -> 515 | I53: =H53/D53 -> 171.66667
B54: 4.11 | C54: ='Housekeeping Scope BOQ'!A24 -> High Pressure | D54: ='Housekeeping Scope BOQ'!E24 -> 2 | E54: 90000 | F54: =E54*F$41 -> 2700 | G54: =F54+E54 -> 92700 | H54: =G54/24 -> 3862.5 | I54: =H54/D54 -> 1931.25
B55: 4.12 | C55: ='Housekeeping Scope BOQ'!A25 -> ترولي كبير public area لوضع العدة | D55: ='Housekeeping Scope BOQ'!E25 -> 7 | E55: 8500 | F55: =E55*F$41 -> 255 | G55: =F55+E55 -> 8755 | H55: =G55/12 -> 729.58333 | I55: =H55/D55 -> 104.22619
...

Sheet HK - Light Tools & Cons
A1: 1 | B1: Monthly Consumables
B3: Light consumables included in the manpwer rate
B4: Consumables | C4: uom | D4: Quantity/Month | E4: Total / Month
B5: زجاجة جلانس ملمع | C5: 45 | D5: 153 | E5: =D5*C5 -> 6885
B6: زجاجة Techno Plus من شركة TCL | C6: 110 | D6: 197 | E6: =D6*C6 -> 21670
B7: زجاجة بليدج ملمع للخشب | C7: 65 | D7: 195 | E7: =D7*C7 -> 12675
B8: زجاجة ملمع ستيانليس ستيل من شركة TCL | C8: 135 | D8: 90 | E8: =D8*C8 -> 12150
B9: علبة جوانتيات طبية | C9: 190 | D9: 3 | E9: =D9*C9 -> 570
B10: جيركن مزيل اسمنت | C10: 60 | D10: 1 | E10: =D10*C10 -> 60
B11: زجاجة كلور ابيض Clorex | C11: 30 | D11: 96 | E11: =D11*C11 -> 2880
B12: ملح ليمون بالكيلو | C12: 100 | D12: 10 | E12: =D12*C12 -> 1000
B13: بخاخة معطر فريدة | C13: 65 | D13: 17 | E13: =D13*C13 -> 1105
B14: كور نفتالين بلي لقواعد الحمام | C14: 120 | D14: 28 | E14: =D14*C14 -> 3360
B15: زجاجة ديتول مطهر | C15: 175 | D15: 12 | E15: =D15*C15 -> 2100
B16: جيركن صابون | C16: 160 | D16: 4 | E16: =D16*C16 -> 640
B17: علب جوانتيات بلاستيك | C17: 190 | D17: 3 | E17: =D17*C17 -> 570
D18: Grand Total Consumables | E18: =SUM(E5:E17) -> 65665
A21: 2 | B21: Monthly Tools
B23: light tools Included with Manpower prices
B24: Tools | C24: Quantity | D24: Unit Price | E24: Total / Month
B25: مقشات سلك عريضة | C25: 9 | D25: 50 | E25: =D25*C25 -> 450
B26: جاروف صاج | C26: 11 | D26: 200 | E26: =D26*C26 -> 2200
B27: فوطة (طرشونة) | C27: 82 | D27: 22 | E27: =D27*C27 -> 1804
B28: ماسك مخلفات (ملقاط) | C28: 9 | D28: 400 | E28: =D28*C28 -> 3600
B29: مساحات حديد عريضة | C29: 2 | D29: 125 | E29: =D29*C29 -> 250
B30: سكينة معجون | C30: 12 | D30: 45 | E30: =D30*C30 -> 540
B31: مقشة ناعمة | C31: 36 | D31: 50 | E31: =D31*C31 -> 1800
B32: جاروف بلاستيك بيد | C32: 6 | D32: 65 | E32: =D32*C32 -> 390
B33: زعافة رأس العبد | C33: 17 | D33: 75 | E33: =D33*C33 -> 1275
B34: بلة واسكويزر | C34: 16 | D34: 110 | E34: =D34*C34 -> 1760
B35: موب | C35: 12 | D35: 450 | E35: =D35*C35 -> 5400
B36: فورشة بلاط بلاستيك | C36: 6 | D36: 40 | E36: =D36*C36 -> 240
... B45: Sponge | C45: 26 | D45: 15 | E45: =D45*C45 -> 390
D46: Grand Total Tools | E46: =SUM(E25:E45) -> 43029

Sheet MEP Scope BOQ 
A1: TFM Package for TRIO 2025 MEP Section | G1: FMPlus
F2: Total Incl VAT | G2: =G4+G3 -> 16155888
F3: VAT | G3: =G4*0.14 -> 1984056.5
F4: Total | G4: =SUM(I8:I134) -> 14171832
A6: Service Provider Manpower Resource | D6: Shifts | E6: Qty/month | F6: Months | G6: Monthly rate | H6: Monthly Total fees | I6: Annual Total Fees
A7: The fee includes the salaries, Taxes, internal transportation, external transportation, uniform, light tools (ANNEX 25) , light consumables.(ANNEX 23) Etc,
A8: MEP Engineer (2-4 Years experience) | D8: Morning 8AM - 5PM | E8: 1 | F8: 12 | G8: ='MEP Budget'!K7 -> 44085 | H8: =G8*E8 -> 44085 | I8: =H8*F8 -> 529020
A9: Safety Engineer | D9: Morning 8AM - 5PM | E9: 1 | F9: 12 | G9: ='MEP Budget'!K8 -> 62979 | H9: =G9*E9 -> 62979 | I9: =H9*F9 -> 755748
A10: Plumber | D10: Morning 8AM - 8PM | E10: 4 | F10: 12 | G10: ='MEP Budget'!K9 -> 21255 | H10: =G10*E10 -> 85020 | I10: =H10*F10 -> 1020240
A11: Mechanical | E11: 2 | F11: 12 | G11: ='MEP Budget'!K10 -> 18205 | H11: =G11*E11 -> 36410 | I11: =H11*F11 -> 436920
A12: Swimming pools | E12: 3 | F12: 12 | G12: ='MEP Budget'!K11 -> 18448 | H12: =G12*E12 -> 55344 | I12: =H12*F12 -> 664128
A13: Electrcian | E13: 3 | F13: 12 | G13: ='MEP Budget'!K12 -> 23554 | H13: =G13*E13 -> 70662 | I13: =H13*F13 -> 847944
A14: Light Current | E14: 1 | F14: 12 | G14: ='MEP Budget'!K13 -> 20468 | H14: =G14*E14 -> 20468 | I14: =H14*F14 -> 245616
A15: Control | E15: 1 | F15: 12 | G15: ='MEP Budget'!K14 -> 21491 | H15: =G15*E15 -> 21491 | I15: =H15*F15 -> 257892
A16: Generators Tech. | E16: 0 | F16: 12 | G16: ='MEP Budget'!K15 -> 0 | H16: =G16*E16 -> 0 | I16: =H16*F16 -> 0
A17: Painters | E17: 1 | F17: 12 | G17: ='MEP Budget'!K16 -> 18421 | H17: =G17*E17 -> 18421 | I17: =H17*F17 -> 221052
A18: Carpenter | E18: 0 | F18: 12 | G18: ='MEP Budget'!K17 -> 0 | H18: =G18*E18 -> 0 | I18: =H18*F18 -> 0
A19: Civil Workers | E19: 1 | F19: 12 | G19: ='MEP Budget'!K18 -> 32591 | H19: =G19*E19 -> 32591 | I19: =H19*F19 -> 391092
A20: Labors | E20: 3 | F20: 12 | G20: ='MEP Budget'!K19 -> 14957 | H20: =G20*E20 -> 44871 | I20: =H20*F20 -> 538452
A21: Aluminum | E21: 1 | F21: 12 | G21: ='MEP Budget'!K20 -> 18421 | H21: =G21*E21 -> 18421 | I21: =H21*F21 -> 221052
A22: Gypsum Board (Instead of Interlock) | E22: 1 | F22: 12 | G22: ='MEP Budget'!K21 -> 18421 | H22: =G22*E22 -> 18421 | I22: =H22*F22 -> 221052
... A25: Electrical Supervisor | E25: 1 | F25: 12 | G25: ='MEP Budget'!K24 -> 29679 | H25: =G25*E25 -> 29679 | I25: =H25*F25 -> 356148
A26: Plumber | D26: Night 8PM-8AM | E26: 2 | F26: 12 | G26: ='MEP Budget'!K25 -> 24798 | H26: =G26*E26 -> 49596 | I26: =H26*F26 -> 595152
A27: Electrcian | E27: 2 | F27: 12 | G27: ='MEP Budget'!K26 -> 25762 | H27: =G27*E27 -> 51524 | I27: =H27*F27 -> 618288
A28: Control | E28: 1 | F28: 12 | G28: ='MEP Budget'!K27 -> 21491 | H28: =G28*E28 -> 21491 | I28: =H28*F28 -> 257892
A29: Generators Tech. | E29: 0 | F29: 12 | G29: ='MEP Budget'!K28 -> 0 | H29: =G29*E29 -> 0 | I29: =H29*F29 -> 0
A30: Water pump station
A31: Electrcian | D31: 8AM-4PM | E31: 1 | F31: 12 | G31: ='MEP Budget'!K62 -> 15854 | H31: =G31*E31 -> 15854 | I31: =H31*F31 -> 190248
A32: Mechanical | E32: 1 | F32: 12 | G32: ='MEP Budget'!K63 -> 31369 | H32: =G32*E32 -> 31369 | I32: =H32*F32 -> 376428
A33: Control | E33: 1 | F33: 12 | G33: ='MEP Budget'!K64 -> 17804 | H33: =G33*E33 -> 17804 | I33: =H33*F33 -> 213648
A34: Mechanical | D34: 4PM-12AM | E34: 1 | F34: 12 | G34: ='MEP Budget'!K65 -> 15685 | H34: =G34*E34 -> 15685 | I34: =H34*F34 -> 188220
A35: Control | E35: 1 | F35: 12 | G35: ='MEP Budget'!K66 -> 35609 | H35: =G35*E35 -> 35609 | I35: =H35*F35 -> 427308
A36: Plumber | D36: 12AM-8AM | E36: 1 | F36: 12 | G36: ='MEP Budget'!K67 -> 15261 | H36: =G36*E36 -> 15261 | I36: =H36*F36 -> 183132
A37: Inside Units
A38: Internal MEP Engineer | D38: Morning 8AM-5PM | E38: 0 | F38: 12 | G38: ='MEP Budget'!K101 -> 0 | H38: =G38*E38 -> 0 | I38: =H38*F38 -> 0
A39: AC | D39: 8AM-8PM | E39: 2 | F39: 12 | G39: ='MEP Budget'!K102 -> 24573 | H39: =G39*E39 -> 49146 | I39: =H39*F39 -> 589752
A40: Carpenter | E40: 1 | F40: 12 | G40: ='MEP Budget'!K103 -> 21296 | H40: =G40*E40 -> 21296 | I40: =H40*F40 -> 255552
A41: Aluminum | E41: 1 | F41: 12 | G41: ='MEP Budget'!K104 -> 21296 | H41: =G41*E41 -> 21296 | I41: =H41*F41 -> 255552
A42: Electrician | E42: 2 | F42: 12 | G42: ='MEP Budget'!K105 -> 20477 | H42: =G42*E42 -> 40954 | I42: =H42*F42 -> 491448
A43: Plumber | E43: 3 | F43: 12 | G43: ='MEP Budget'!K106 -> 20750 | H43: =G43*E43 -> 62250 | I43: =H43*F43 -> 747000
...

Sheet MEP Budget
A2: 1 | B2: Manpower | F2: 0.2
A4: A | B4: Public
B6: # | C6: Position / Designation | D6: Working Hours | E6: Net Rate | F6: CTC Rate | G6: Head Count (Required) | H6: Head Count (Budget) | I6: Total CTC | K6: Offer Rate | M6: Totals
B7: 1 | C7: ='MEP Scope BOQ '!A8 -> MEP Engineer (2-4 Years experience) | D7: ='[1]MEP Scope BOQ '!D8 -> Morning 8AM - 5PM | E7: 28000 | F7: =E7+(F$2*E7) -> 33600 | G7: ='MEP Scope BOQ '!E8 -> 1 | H7: =G7 -> 1 | I7: =H7*F7 -> 33600 | K7: =ROUND((I7/(1-F$54))/G7,0) -> 44085 | M7: =K7*G7 -> 44085
B8: 2 | C8: ='MEP Scope BOQ '!A9 -> Safety Engineer | D8: ='[1]MEP Scope BOQ '!D9 -> Morning 8AM - 5PM | E8: 20000 | F8: =E8+(F$2*E8) -> 24000 | G8: ='MEP Scope BOQ '!E9 -> 1 | H8: 2 | I8: =H8*F8 -> 48000 | K8: =ROUND((I8/(1-F$54))/G8,0) -> 62979 | M8: =K8*G8 -> 62979
B9: 3 | C9: ='MEP Scope BOQ '!A10 -> Plumber | D9: Morning 8AM - 8 PM | E9: 9000 | F9: =E9+(F$2*E9) -> 10800 | G9: ='MEP Scope BOQ '!E10 -> 4 | H9: 6 | I9: =H9*F9 -> 64800 | K9: =ROUND((I9/(1-F$54))/G9,0) -> 21255 | M9: =K9*G9 -> 85020
B10: 4 | C10: ='MEP Scope BOQ '!A11 -> Mechanical | D10: Morning 8AM - 8 PM | E10: 9250 | F10: =E10+(F$2*E10) -> 11100 | G10: ='MEP Scope BOQ '!E11 -> 2 | H10: =ROUNDUP(G10+(G10/4),1) -> 2.5 | I10: =H10*F10 -> 27750 | K10: =ROUND((I10/(1-F$54))/G10,0) -> 18205 | M10: =K10*G10 -> 36410
B11: 5 | C11: ='MEP Scope BOQ '!A12 -> Swimming pools | D11: Morning 8AM - 8 PM | E11: 9250 | F11: =E11+(F$2*E11) -> 11100 | G11: ='MEP Scope BOQ '!E12 -> 3 | H11: =ROUNDUP(G11+(G11/4),1) -> 3.8 | I11: =H11*F11 -> 42180 | K11: =ROUND((I11/(1-F$54))/G11,0) -> 18448 | M11: =K11*G11 -> 55344
B12: 6 | C12: ='MEP Scope BOQ '!A13 -> Electrcian | D12: Morning 8AM - 8 PM | E12: 9350 | F12: =E12+(F$2*E12) -> 11220 | G12: ='MEP Scope BOQ '!E13 -> 3 | H12: 4.8 | I12: =H12*F12 -> 53856 | K12: =ROUND((I12/(1-F$54))/G12,0) -> 23554 | M12: =K12*G12 -> 70662
B13: 7 | C13: ='MEP Scope BOQ '!A14 -> Light Current | D13: Morning 8AM - 8 PM | E13: 10000 | F13: =E13+(F$2*E13) -> 12000 | G13: ='MEP Scope BOQ '!E14 -> 1 | H13: =ROUNDUP(G13+(G13/4),1) -> 1.3 | I13: =H13*F13 -> 15600 | K13: =ROUND((I13/(1-F$54))/G13,0) -> 20468 | M13: =K13*G13 -> 20468
B14: 8 | C14: ='MEP Scope BOQ '!A15 -> Control | D14: Morning 8AM - 8 PM | E14: 10500 | F14: =E14+(F$2*E14) -> 12600 | G14: ='MEP Scope BOQ '!E15 -> 1 | H14: =ROUNDUP(G14+(G14/4),1) -> 1.3 | I14: =H14*F14 -> 16380 | K14: =ROUND((I14/(1-F$54))/G14,0) -> 21491 | M14: =K14*G14 -> 21491
B15: 9 | C15: ='MEP Scope BOQ '!A16 -> Generators Tech. | D15: Morning 8AM - 8 PM | E15: 9850 | F15: =E15+(F$2*E15) -> 11820 | G15: ='MEP Scope BOQ '!E16 -> 0 | H15: =ROUNDUP(G15+(G15/4),1) -> 0 | I15: =H15*F15 -> 0 | K15: =IFERROR(ROUND((I15/(1-F$54))/G15,0),0) -> 0 | M15: =K15*G15 -> 0
B16: 10 | C16: ='MEP Scope BOQ '!A17 -> Painters | D16: Morning 8AM - 8 PM | E16: 9000 | F16: =E16+(F$2*E16) -> 10800 | G16: ='MEP Scope BOQ '!E17 -> 1 | H16: =ROUNDUP(G16+(G16/4),1) -> 1.3 | I16: =H16*F16 -> 14040 | K16: =ROUND((I16/(1-F$54))/G16,0) -> 18421 | M16: =K16*G16 -> 18421
B17: 11 | C17: ='MEP Scope BOQ '!A18 -> Carpenter | D17: Morning 8AM - 8 PM | E17: 9000 | F17: =E17+(F$2*E17) -> 10800 | G17: ='MEP Scope BOQ '!E18 -> 0 | H17: =ROUNDUP(G17+(G17/4),1) -> 0 | I17: =H17*F17 -> 0 | K17: =IFERROR(ROUND((I17/(1-F$54))/G17,0),0) -> 0 | M17: =K17*G17 -> 0
B18: 12 | C18: ='MEP Scope BOQ '!A19 -> Civil Workers | D18: Morning 8AM - 8 PM | E18: 9000 | F18: =E18+(F$2*E18) -> 10800 | G18: ='MEP Scope BOQ '!E19 -> 1 | H18: 2.3 | I18: =H18*F18 -> 24840 | K18: =ROUND((I18/(1-F$54))/G18,0) -> 32591 | M18: =K18*G18 -> 32591
B19: 13 | C19: ='MEP Scope BOQ '!A20 -> Labors | D19: Morning 8AM - 8 PM | E19: 7500 | F19: =E19+(F$2*E19) -> 9000 | G19: ='MEP Scope BOQ '!E20 -> 3 | H19: =ROUNDUP(G19+(G19/4),1) -> 3.8 | I19: =H19*F19 -> 34200 | K19: =ROUND((I19/(1-F$54))/G19,0) -> 14957 | M19: =K19*G19 -> 44871
B20: 14 | C20: ='MEP Scope BOQ '!A21 -> Aluminum | D20: Morning 8AM - 8 PM | E20: 9000 | F20: =E20+(F$2*E20) -> 10800 | G20: ='MEP Scope BOQ '!E21 -> 1 | H20: =ROUNDUP(G20+(G20/4),1) -> 1.3 | I20: =H20*F20 -> 14040 | K20: =ROUND((I20/(1-F$54))/G20,0) -> 18421 | M20: =K20*G20 -> 18421
B21: 15 | C21: ='MEP Scope BOQ '!A22 -> Gypsum Board (Instead of Interlock) | D21: Morning 8AM - 8 PM | E21: 9000 | F21: =E21+(F$2*E21) -> 10800 | G21: ='MEP Scope BOQ '!E22 -> 1 | H21: =ROUNDUP(G21+(G21/4),1) -> 1.3 | I21: =H21*F21 -> 14040 | K21: =ROUND((I21/(1-F$54))/G21,0) -> 18421 | M21: =K21*G21 -> 18421
B22: 16 | C22: ='MEP Scope BOQ '!A23 -> Marble & Ceramics | D22: Morning 8AM - 8 PM | E22: 9000 | F22: =E22+(F$2*E22) -> 10800 | G22: ='MEP Scope BOQ '!E23 -> 1 | H22: =ROUNDUP(G22+(G22/4),1) -> 1.3 | I22: =H22*F22 -> 14040 | K22: =ROUND((I22/(1-F$54))/G22,0) -> 18421 | M22: =K22*G22 -> 18421
B23: 17 | C23: ='MEP Scope BOQ '!A24 -> Mechanical Supervisor | D23: Morning 8AM - 8 PM | E23: 14500 | F23: =E23+(F$2*E23) -> 17400 | G23: ='MEP Scope BOQ '!E24 -> 1 | H23: 2.3 | I23: =H23*F23 -> 40020 | K23: =ROUND((I23/(1-F$54))/G23,0) -> 52508 | M23: =K23*G23 -> 52508
B24: 18 | C24: ='MEP Scope BOQ '!A25 -> Electrical Supervisor | D24: Morning 8AM - 8 PM | E24: 14500 | F24: =E24+(F$2*E24) -> 17400 | G24: ='MEP Scope BOQ '!E25 -> 1 | H24: =ROUNDUP(G24+(G24/4),1) -> 1.3 | I24: =H24*F24 -> 22620 | K24: =ROUND((I24/(1-F$54))/G24,0) -> 29679 | M24: =K24*G24 -> 29679
B25: 19 | C25: ='MEP Scope BOQ '!A26 -> Plumber | D25: Night 8PM - 8 AM | E25: 9000 | F25: =E25+(F$2*E25) -> 10800 | G25: ='MEP Scope BOQ '!E26 -> 2 | H25: 3.5 | I25: =H25*F25 -> 37800 | K25: =ROUND((I25/(1-F$54))/G25,0) -> 24798 | M25: =K25*G25 -> 49596
B26: 20 | C26: ='MEP Scope BOQ '!A27 -> Electrcian | D26: Night 8PM - 8 AM | E26: 9350 | F26: =E26+(F$2*E26) -> 11220 | G26: ='MEP Scope BOQ '!E27 -> 2 | H26: 3.5 | I26: =H26*F26 -> 39270 | K26: =ROUND((I26/(1-F$54))/G26,0) -> 25762 | M26: =K26*G26 -> 51524
B27: 21 | C27: ='MEP Scope BOQ '!A28 -> Control | D27: Night 8PM - 8 AM | E27: 10500 | F27: =E27+(F$2*E27) -> 12600 | G27: ='MEP Scope BOQ '!E28 -> 1 | H27: =ROUNDUP(G27+(G27/4),1) -> 1.3 | I27: =H27*F27 -> 16380 | K27: =ROUND((I27/(1-F$54))/G27,0) -> 21491 | M27: =K27*G27 -> 21491
B28: 22 | C28: ='MEP Scope BOQ '!A29 -> Generators Tech. | D28: Night 8PM - 8 AM | E28: 9850 | F28: =E28+(F$2*E28) -> 11820 | G28: ='MEP Scope BOQ '!E29 -> 0 | H28: =ROUNDUP(G28+(G28/4),1) -> 0 | I28: =H28*F28 -> 0 | K28: =IFERROR(ROUND((I28/(1-F$54))/G28,0),0) -> 0 | M28: =K28*G28 -> 0
H30: Total Manpower | I30: =SUM(I7:I28) -> 573456 | M30: =SUM(M7:M28) -> 752403
A33: 2 | B33: List Of Indirects
B35: # | C35: Item | D35: QTY | E35: Monthly Cost | F35: Total Costs
B36: 2.1 | C36: Uniform | D36: =SUM(H8:H28) -> 44.9 | E36: 500 | F36: =E36*D36 -> 22450
B37: 2.2 | C37: Consumables | D37: 1 | E37: 8500 | F37: =E37*D37 -> 8500
B38: 2.3 | C38: Tools | D38: 1 | E38: 9850 | F38: =E38*D38 -> 9850
B39: 2.4 | C39: Equipment | D39: 1 | E39: 6750 | F39: =E39*D39 -> 6750
B40: 2.5 | C40: Transportation - Inside Site With Fuel | D40: 0 | E40: 38500 | F40: =E40*D40 -> 0
B41: 2.6 | C41: Transportation - Outside Site | D41: =SUM(G8:G28) -> 30 | E41: 2000 | F41: =E41*D41 -> 60000
B42: 2.7 | C42: IT, Laptop, Printers | D42: 1 | E42: 3000 | F42: =E42*D42 -> 3000
E44: Total InD | F44: =SUM(F36:F42) -> 110550
A46: 3 | B46: Project OVH & GM
B48: # | C48: Item | D48: % | E48: Costs | F48: Total Costs
B49: 3.1 | C49: OVH | D49: 0 | E49: =(I30+F44) -> 684006 | F49: =E49*D49 -> 0
B50: 3.2 | C50: Gross Profit % | D50: 0.1 | E50: =E49 -> 684006 | F50: =E50*D50 -> 68400.6
...

Sheet Landscape BOQ
A1: TFM Package for TRIO 2025 Landscape section | G1: FMPlus
F2: Total Incl VAT | G2: =G4+G3 -> 5404420.8
F3: VAT | G3: =G4*0.14 -> 663700.8
F4: Total | G4: =SUM(I7:I136) -> 4740720 | J4: 4881140.4
A5: Service Provider Manpower Resource | D5: Shifts | E5: Qty/month | F5: Months | G5: Monthly rate | H5: Monthly Total fees | I5: Annual Total Fees
A6: The fee includes the salaries, Taxes, internal transportation, external transportation, uniform, light tools (ANNEX 7) , Etc,
A7: Landscape Public Engineer | D7: 8AM-5PM | E7: 1 | F7: 12 | G7: ='LS Budget'!K5 -> 35252 | H7: =G7*E7 -> 35252 | I7: =H7*F7 -> 423024
A8: زراعة Supervisor | E8: 1 | F8: 12 | G8: ='LS Budget'!K6 -> 33049 | H8: =G8*E8 -> 33049 | I8: =H8*F8 -> 396588
A9: ري Supervisor | E9: 1 | F9: 12 | G9: ='LS Budget'!K7 -> 33049 | H9: =G9*E9 -> 33049 | I9: =H9*F9 -> 396588
A10: عامل زراعة | E10: 5 | F10: 12 | G10: ='LS Budget'!K8 -> 14057 | H10: =G10*E10 -> 70285 | I10: =H10*F10 -> 843420
A11: عامل ري | E11: 2 | F11: 12 | G11: ='LS Budget'!K9 -> 14982 | H11: =G11*E11 -> 29964 | I11: =H11*F11 -> 359568
A12: Major Equipment, Tools (ANNEX 6)
A13: ماكينة قص نجيله هوندا دفع ذاتى موديل 216 | E13: 1 | F13: 12 | G13: ='LS Budget'!H43 -> 5923 | H13: =G13*E13 -> 5923 | I13: =H13*F13 -> 71076
A14: موتور رش 600 لتر | E14: 1 | F14: 12 | G14: ='LS Budget'!H44 -> 5665 | H14: =G14*E14 -> 5665 | I14: =H14*F14 -> 67980
A15: رشاشة ظهرية بالبطارية | E15: 2 | F15: 12 | G15: ='LS Budget'!H45 -> 292 | H15: =G15*E15 -> 584 | I15: =H15*F15 -> 7008
A16: ماكينة حدية للنجيلة 5*1 نوعية استيجا | E16: 1 | F16: 12 | G16: ='LS Budget'!H46 -> 1460 | H16: =G16*E16 -> 1460 | I16: =H16*F16 -> 17520
A17: عدد مقص اسوار بنزين نوعية كراون | E17: 1 | F17: 12 | G17: ='LS Budget'!H47 -> 644 | H17: =G17*E17 -> 644 | I17: =H17*F17 -> 7728
A18: Overhead percentage on additional items invoices (consumables, back to back contracts. Emergencies)
A19: Annual Increasing Percentage
A20: Landscape Inside units
A21: The fee includes the salaries, Taxes, internal transportation, external transportation, uniform, light tools (ANNEX 8) , Etc,
A22: Landscape Internal Engineer | D22: 8AM-5PM | E22: 1 | F22: 12 | G22: ='LS Budget'!K53 -> 31529 | H22: =G22*E22 -> 31529 | I22: =H22*F22 -> 378348
A23: Landscape Internal Supervisor | E23: 1 | F23: 12 | G23: ='LS Budget'!K54 -> 29559 | H23: =G23*E23 -> 29559 | I23: =H23*F23 -> 354708
A24: عامل اول زراعة | E24: 1 | F24: 12 | G24: ='LS Budget'!K55 -> 29559 | H24: =G24*E24 -> 29559 | I24: =H24*F24 -> 354708
A25: عامل زراعة | E25: 4 | F25: 12 | G25: ='LS Budget'!K56 -> 15272 | H25: =G25*E25 -> 61088 | I25: =H25*F25 -> 733056
A26: عامل ري | E26: 1 | F26: 12 | G26: ='LS Budget'!K57 -> 20691 | H26: =G26*E26 -> 20691 | I26: =H26*F26 -> 248292
A27: Major Equipment, Tools (ANNEX 10)
A28: ماكينة قص كهرباء 220V (Stiga or Total) | E28: 2 | F28: 12 | G28: ='LS Budget'!H91 -> 1245 | H28: =G28*E28 -> 2490 | I28: =H28*F28 -> 29880
A29: Trimmer منشار قص الورق | E29: 2 | F29: 12 | G29: ='LS Budget'!H92 -> 503 | H29: =G29*E29 -> 1006 | I29: =H29*F29 -> 12072
A30: موتور رش ظهري يعمل بالبطارية 20 لتر | E30: 2 | F30: 12 | G30: ='LS Budget'!H93 -> 258 | H30: =G30*E30 -> 516 | I30: =H30*F30 -> 6192
A31: موتور رش 300 لتر يعمل بالجاز و يشمل مستلزمات الماكينات من زيت وبنزين | E31: 1 | F31: 12 | G31: ='LS Budget'!H94 -> 2747 | H31: =G31*E31 -> 2747 | I31: =H31*F31 -> 32964
A32: Overhead percentage on additional items invoices (consumables "ANNEX 9", back to back contracts. Emergencies) | E32: 0.1
A33: Annual Increasing Percentage | E33: 0.1

Sheet LS Budget
A2: 1 | B2: Manpower | F2: 0.18
B4: # | C4: Position / Designation | D4: Working Hours | E4: Net Rate | F4: CTC Rate | G4: Head Count (Required) | H4: Head Count (Budget) | I4: Total CTC | K4: Offer Rate | M4: Totals
B5: 1 | C5: ='[1]Landscape BOQ'!A8 -> Landscape Public Engineer | D5: 8:00 AM - 5:00 PM | E5: 16000 | F5: =E5+(F$2*E5) -> 18880 | G5: ='[1]Landscape BOQ'!E8 -> 1 | H5: =G5 -> 1 | I5: =H5*F5 -> 18880 | K5: =ROUND((I5/(1-F$35))/G5,0) -> 35252 | M5: =K5*G5 -> 35252
B6: 2 | C6: ='[1]Landscape BOQ'!A9 -> زراعة Supervisor | D6: 8:00 AM - 5:00 PM | E6: 10000 | F6: =E6+(F$2*E6) -> 11800 | G6: ='[1]Landscape BOQ'!E9 -> 1 | H6: 1.5 | I6: =H6*F6 -> 17700 | K6: =ROUND((I6/(1-F$35))/G6,0) -> 33049 | M6: =K6*G6 -> 33049
B7: 3 | C7: ='[1]Landscape BOQ'!A10 -> ري Supervisor | D7: 8:00 AM - 5:00 PM | E7: 10000 | F7: =E7+(F$2*E7) -> 11800 | G7: ='[1]Landscape BOQ'!E10 -> 1 | H7: 1.5 | I7: =H7*F7 -> 17700 | K7: =ROUND((I7/(1-F$35))/G7,0) -> 33049 | M7: =K7*G7 -> 33049
B8: 4 | C8: ='[1]Landscape BOQ'!A11 -> عامل زراعة | D8: 8:00 AM - 5:00 PM | E8: 5800 | F8: =E8+(F$2*E8) -> 6844 | G8: ='[1]Landscape BOQ'!E11 -> 5 | H8: 5.5 | I8: =H8*F8 -> 37642 | K8: =ROUND((I8/(1-F$35))/G8,0) -> 14057 | M8: =K8*G8 -> 70285
B9: 5 | C9: ='[1]Landscape BOQ'!A12 -> عامل ري | D9: 8:00 AM - 5:00 PM | E9: 6800 | F9: =E9+(F$2*E9) -> 8024 | G9: ='[1]Landscape BOQ'!E12 -> 2 | H9: 2 | I9: =H9*F9 -> 16048 | K9: =ROUND((I9/(1-F$35))/G9,0) -> 14982 | M9: =K9*G9 -> 29964
H11: Total Manpower | I11: =SUM(I5:I9) -> 107970 | M11: =SUM(M5:M9) -> 201599
A14: 2 | B14: List Of Indirects
B16: # | C16: Item | D16: QTY | E16: Monthly Cost | F16: Total Costs
B17: 2.1 | C17: Uniform | D17: =SUM(H6:H9) -> 10.5 | E17: 500 | F17: =E17*D17 -> 5250
B18: 2.2 | C18: LS Light Consumables | D18: 1 | E18: 18000 | F18: =E18*D18 -> 18000
B19: 2.3 | C19: LS Light Tools | D19: 1 | E19: 12550 | F19: =E19*D19 -> 12550
B20: 2.4 | C20: LS Equipment Included | D20: 1 | E20: 4500 | F20: =E20*D20 -> 4500
B21: 2.5 | C21: HK Transportation - Inside Site With Fuel | D21: 0 | E21: 38500 | F21: =E21*D21 -> 0
B22: 2.6 | C22: HK Transportation - Outside Site | D22: =SUM(G5:G9) -> 10 | E22: 3000 | F22: =E22*D22 -> 30000
B23: 2.7 | C23: HK IT, Laptop, Printers | D23: 1 | E23: 5000 | F23: =E23*D23 -> 5000
E25: Total InD | F25: =SUM(F17:F23) -> 75300
A27: 3 | B27: Project OVH & GM
B29: # | C29: Item | D29: % | E29: Costs | F29: Total Costs
B30: 3.1 | C30: OVH | D30: 0 | E30: =(I11+F25) -> 183270 | F30: =E30*D30 -> 0
B31: 3.2 | C31: Gross Profit % | D31: 0.1 | E31: =E30 -> 183270 | F31: =E31*D31 -> 18327
E33: OVH&GM - Value | F33: =SUM(F30:F31) -> 18327
E35: InD % | F35: =(F33+F25)/(F33+F25+I11) -> 0.46442655
E37: Total With Profit | F37: =F33+F25+I11 -> 201597
A40: 4 | B40: List Of Heavy Equipment | F40: 0.03
B42: # | C42: Item | D42: QTY | E42: Cost / Item | F42: Profit | G42: Selling Price / Unit | H42: Monthly Rate / Unit
B43: 4.1 | C43: ='[1]Landscape BOQ'!A14 -> ماكينة قص نجيله هوندا دفع ذاتى موديل 216 | D43: ='[1]Landscape BOQ'!E14 -> 1 | E43: 69000 | F43: =E43*F$40 -> 2070 | G43: =F43+E43 -> 71070 | H43: =ROUNDUP(G43/12,0) -> 5923
B44: 4.2 | C44: ='[1]Landscape BOQ'!A15 -> موتور رش 600 لتر | D44: ='[1]Landscape BOQ'!E15 -> 1 | E44: 66000 | F44: =E44*F$40 -> 1980 | G44: =F44+E44 -> 67980 | H44: =ROUNDUP(G44/12,0) -> 5665
B45: 4.3 | C45: ='[1]Landscape BOQ'!A16 -> رشاشة ظهرية بالبطارية | D45: ='[1]Landscape BOQ'!E16 -> 2 | E45: 3400 | F45: =E45*F$40 -> 102 | G45: =F45+E45 -> 3502 | H45: =ROUNDUP(G45/12,0) -> 292
B46: 4.4 | C46: ='[1]Landscape BOQ'!A17 -> ماكينة حدية للنجيلة 5*1 نوعية استيجا | D46: ='[1]Landscape BOQ'!E17 -> 1 | E46: 17000 | F46: =E46*F$40 -> 510 | G46: =F46+E46 -> 17510 | H46: =ROUNDUP(G46/12,0) -> 1460
B47: 4.5 | C47: ='[1]Landscape BOQ'!A18 -> عدد مقص اسوار بنزين نوعية كراون | D47: ='[1]Landscape BOQ'!E18 -> 1 | E47: 7500 | F47: =E47*F$40 -> 225 | G47: =F47+E47 -> 7725 | H47: =ROUNDUP(G47/12,0) -> 644
A50: 1 | B50: Manpower | F50: 0.2
B52: # | C52: Position / Designation | D52: Working Hours | E52: Net Rate | F52: CTC Rate | G52: Head Count (Required) | H52: Head Count (Budget) | I52: Total CTC | K52: Offer Rate | M52: Totals
B53: 1 | C53: ='[1]Landscape BOQ'!A23 -> Landscape Internal Engineer | D53: 8:00 AM - 5:00 PM | E53: =E5 -> 16000 | F53: =E53+(F$50*E53) -> 19200 | G53: ='[1]Landscape BOQ'!E23 -> 1 | H53: =G53 -> 1 | I53: =H53*F53 -> 19200 | K53: =ROUND((I53/(1-F$83))/G53,0) -> 31529 | M53: =K53*G53 -> 31529
B54: 2 | C54: ='[1]Landscape BOQ'!A24 -> Landscape Internal Supervisor | D54: 8:00 AM - 5:00 PM | E54: =E6 -> 10000 | F54: =E54+(F$50*E54) -> 12000 | G54: ='[1]Landscape BOQ'!E24 -> 1 | H54: 1.5 | I54: =H54*F54 -> 18000 | K54: =ROUND((I54/(1-F$83))/G54,0) -> 29559 | M54: =K54*G54 -> 29559
B55: 3 | C55: ='[1]Landscape BOQ'!A25 -> عامل اول زراعة | D55: 8:00 AM - 5:00 PM | E55: =E7 -> 10000 | F55: =E55+(F$50*E55) -> 12000 | G55: ='[1]Landscape BOQ'!E25 -> 1 | H55: 1.5 | I55: =H55*F55 -> 18000 | K55: =ROUND((I55/(1-F$83))/G55,0) -> 29559 | M55: =K55*G55 -> 29559
B56: 4 | C56: ='[1]Landscape BOQ'!A26 -> عامل زراعة | D56: 8:00 AM - 5:00 PM | E56: 6200 | F56: =E56+(F$50*E56) -> 7440 | G56: ='[1]Landscape BOQ'!E26 -> 4 | H56: =ROUNDUP(G56+(G56/6),0) -> 5 | I56: =H56*F56 -> 37200 | K56: =ROUND((I56/(1-F$83))/G56,0) -> 15272 | M56: =K56*G56 -> 61088
B57: 5 | C57: ='[1]Landscape BOQ'!A27 -> عامل ري | D57: 8:00 AM - 5:00 PM | E57: 7000 | F57: =E57+(F$50*E57) -> 8400 | G57: ='[1]Landscape BOQ'!E27 -> 1 | H57: 1.5 | I57: =H57*F57 -> 12600 | K57: =ROUND((I57/(1-F$83))/G57,0) -> 20691 | M57: =K57*G57 -> 20691
H59: Total Manpower | I59: =SUM(I53:I57) -> 105000 | M59: =SUM(M53:M57) -> 172426
...

Sheet Pest Control BOQ
A1: TFM Package for TRIO 2025 Landscape section | G1: FMPlus
F2: Total Incl VAT | G2: =G4+G3 -> 975110.4
F3: VAT | G3: =G4*0.14 -> 119750.4
F4: Total | G4: =I8 -> 855360
A6: Service Provider Manpower Resource | D6: Shifts | E6: Qty/month | F6: Months | G6: Monthly rate | H6: Monthly Total fees | I6: Annual Total Fees
A7: The fee includes the salaries, Taxes, internal transportation, external transportation, uniform, light tools (ANNEX 12) , light consumables.(ANNEX 11) Etc,
A8: فني مكافحة | D8: 8AM-5PM | E8: 3 | F8: 12 | G8: ='Pest Control Budget'!K6 -> 23760 | H8: =G8*E8 -> 71280 | I8: =H8*F8 -> 855360
A9: Overhead percentage on additional items invoices (consumables, back to back contracts. Emergencies) | H9: 0.1
A10: Annual Increasing Percentage | H10: 0.1
G24: 992839

Sheet Pest Control Budget
A2: 1 | B2: Manpower | F2: 0.2
B4: # | C4: Position / Designation | D4: Working Hours | E4: Net Rate | F4: CTC Rate | G4: Head Count (Required) | H4: Head Count (Budget) | I4: Total CTC | K4: Offer Rate | M4: Totals
B5: 1 | C5: Pest Control Engineer | D5: 8:00 AM - 5:00 PM | E5: 25000 | F5: =E5+(F$2*E5) -> 30000 | G5: 0 | H5: =G5 -> 0 | I5: =H5*F5 -> 0 | K5: =ROUND((I5/(1-F$32))/G5,0) -> #DIV/0! | M5: =K5*G5 -> #DIV/0!
B6: 2 | C6: Pest Control Tech | D6: 8:00 AM - 5:00 PM | E6: 7000 | F6: =E6+(F$2*E6) -> 8400 | G6: 3 | H6: 4 | I6: =H6*F6 -> 33600 | K6: =ROUND((I6/(1-F$32))/G6,0) -> 23760 | M6: =K6*G6 -> 71280
H8: Total Manpower | I8: =SUM(I5:I6) -> 33600 | M8: =ROUNDUP(SUM(M5:M6),0) -> #DIV/0!
A11: 2 | B11: List Of Indirects
B13: # | C13: Item | D13: QTY | E13: Monthly Cost | F13: Total Costs
B14: 2.1 | C14: Uniform | D14: 3 | E14: 500 | F14: =E14*D14 -> 1500
B15: 2.2 | C15: PC Light Consumables | D15: 1 | E15: 8000 | F15: =E15*D15 -> 8000
B16: 2.3 | C16: PC Light Tools | D16: 1 | E16: 3200 | F16: =E16*D16 -> 3200
B17: 2.4 | C17: PC Equipment Included | D17: 1 | E17: 7500 | F17: =E17*D17 -> 7500
B18: 2.5 | C18: PC Transportation - Inside Site With Fuel | D18: 0 | E18: 38500 | F18: =E18*D18 -> 0
B19: 2.6 | C19: PC Transportation - Outside Site | D19: =SUM(G5:G6) -> 3 | E19: 2500 | F19: =E19*D19 -> 7500
B20: 2.7 | C20: PC IT, Laptop, Printers | D20: 1 | E20: 3500 | F20: =E20*D20 -> 3500
E22: Total InD | F22: =SUM(F14:F20) -> 31200
A24: 3 | B24: Project OVH & GM
B26: # | C26: Item | D26: % | E26: Costs | F26: Total Costs
B27: 3.1 | C27: OVH | D27: 0 | E27: =(I8+F22) -> 64800 | F27: =E27*D27 -> 0
B28: 3.2 | C28: Gross Profit % | D28: 0.1 | E28: =E27 -> 64800 | F28: =E28*D28 -> 6480
E30: OVH&GM - Value | F30: =SUM(F27:F28) -> 6480
E32: InD % | F32: =(F30+F22)/(F30+F22+I8) -> 0.52861953
E34: Total With Profit | F34: =F30+F22+I8 -> 71280

Sheet Backoffice & Admin BOQ
A1: TFM Package for TRIO 2025 Backoffice & Admin section | G1: FMPlus
F2: Total Incl VAT | G2: =G4+G3 -> 2680295
F3: VAT | G3: =G4*0.14 -> 329159.04
F4: Total | G4: =SUM(I8:I118) -> 2351136
A6: Service Provider Manpower Resource | D6: Shifts | E6: Qty/month | F6: Months | G6: Monthly rate | H6: Monthly Total fees | I6: Annual Total Fees
A7: The fee includes the salaries, Taxes, internal transportation, external transportation, uniform, laptop, 2 mobiles with sim cards
A8: Helpdesk | D8: 8AM-5PM | E8: 1 | F8: 12 | G8: ='Back Office Budget'!K5 -> 22164 | H8: =G8*E8 -> 22164 | I8: =H8*F8 -> 265968
A9: Admin | E9: 2 | F9: 12 | G9: ='Back Office Budget'!K6 -> 22164 | H9: =G9*E9 -> 44328 | I9: =H9*F9 -> 531936
A10: Dispatcher | E10: 1 | F10: 12 | G10: ='Back Office Budget'!K7 -> 22164 | H10: =G10*E10 -> 22164 | I10: =H10*F10 -> 265968
A11: Collecter | E11: 1 | F11: 12 | G11: ='Back Office Budget'!K8 -> 22164 | H11: =G11*E11 -> 22164 | I11: =H11*F11 -> 265968
A12: Duty Manager (MEP Supervisor) Night Shift | D12: 5PM-1AM (Accomodation on Site Available) | E12: 1 | F12: 12 | G12: ='Back Office Budget'!K9 -> 58512 | H12: =G12*E12 -> 58512 | I12: =H12*F12 -> 702144
A13: Helpdesk Night Shift | E13: 1 | F13: 12 | G13: ='Back Office Budget'!K10 -> 26596 | H13: =G13*E13 -> 26596 | I13: =H13*F13 -> 319152
A14: Overhead percentage on additional items invoices (consumables, back to back contracts. Emergencies)
A15: Annual Increasing Percentage

Sheet Back Office Budget
A2: 1 | B2: Manpower | F2: 0.2
B4: # | C4: Position / Designation | D4: Working Hours | E4: Net Rate | F4: CTC Rate | G4: Head Count (Required) | H4: Head Count (Budget) | I4: Total CTC | K4: Offer Rate | M4: Totals
B5: 1 | C5: ='[1]Backoffice & Admin BOQ'!A8 -> Helpdesk | D5: 8:00 AM - 5:00 PM | E5: 12500 | F5: =E5+(F$2*E5) -> 15000 | G5: ='[1]Backoffice & Admin BOQ'!E8 -> 1 | H5: 1.25 | I5: =H5*F5 -> 18750 | K5: =ROUND((I5/(1-F$36))/G5,0) -> 22164 | M5: =K5*G5 -> 22164
B6: 2 | C6: ='[1]Backoffice & Admin BOQ'!A9 -> Admin | D6: 8:00 AM - 5:00 PM | E6: 12500 | F6: =E6+(F$2*E6) -> 15000 | G6: ='[1]Backoffice & Admin BOQ'!E9 -> 2 | H6: 2.5 | I6: =H6*F6 -> 37500 | K6: =ROUND((I6/(1-F$36))/G6,0) -> 22164 | M6: =K6*G6 -> 44328
B7: 3 | C7: ='[1]Backoffice & Admin BOQ'!A10 -> Dispatcher | D7: 8:00 AM - 5:00 PM | E7: 12500 | F7: =E7+(F$2*E7) -> 15000 | G7: ='[1]Backoffice & Admin BOQ'!E10 -> 1 | H7: 1.25 | I7: =H7*F7 -> 18750 | K7: =ROUND((I7/(1-F$36))/G7,0) -> 22164 | M7: =K7*G7 -> 22164
B8: 4 | C8: ='[1]Backoffice & Admin BOQ'!A11 -> Collecter | D8: 8:00 AM - 5:00 PM | E8: 12500 | F8: =E8+(F$2*E8) -> 15000 | G8: ='[1]Backoffice & Admin BOQ'!E11 -> 1 | H8: 1.25 | I8: =H8*F8 -> 18750 | K8: =ROUND((I8/(1-F$36))/G8,0) -> 22164 | M8: =K8*G8 -> 22164
B9: 5 | C9: ='[1]Backoffice & Admin BOQ'!A12 -> Duty Manager (MEP Supervisor) Night Shift | D9: 5:00 PM - 1:00 AM | E9: 16500 | F9: =E9+(F$2*E9) -> 19800 | G9: 1 | H9: 2.5 | I9: =H9*F9 -> 49500 | K9: =ROUND((I9/(1-F$36))/G9,0) -> 58512 | M9: =K9*G9 -> 58512
B10: 6 | C10: ='[1]Backoffice & Admin BOQ'!A13 -> Helpdesk Night Shift | D10: 5:00 PM - 1:00 AM | E10: 12500 | F10: =E10+(F$2*E10) -> 15000 | G10: ='[1]Backoffice & Admin BOQ'!E13 -> 1 | H10: 1.5 | I10: =H10*F10 -> 22500 | K10: =ROUND((I10/(1-F$36))/G10,0) -> 26596 | M10: =K10*G10 -> 26596
H12: Total Manpower | I12: =SUM(I5:I10) -> 165750 | M12: =ROUNDUP(SUM(M5:M10),0) -> 195928
A15: 2 | B15: List Of Indirects
B17: # | C17: Item | D17: QTY | E17: Monthly Cost | F17: Total Costs
B18: 2.1 | C18: Uniform | D18: 0 | E18: 600 | F18: =E18*D18 -> 0
B19: 2.2 | C19: Light Consumables | D19: 0 | E19: 8000 | F19: =E19*D19 -> 0
B20: 2.3 | C20: Light Tools | D20: 0 | E20: 3200 | F20: =E20*D20 -> 0
B21: 2.4 | C21: Equipment Included | D21: 0 | E21: 7500 | F21: =E21*D21 -> 0
B22: 2.5 | C22: Transportation - Inside Site With Fuel | D22: 0 | E22: 38500 | F22: =E22*D22 -> 0
B23: 2.6 | C23: Transportation - Outside Site | D23: =SUM(G5:G10) -> 7 | E23: 1500 | F23: =E23*D23 -> 10500
B24: 2.7 | C24: IT, Laptop, Printers | D24: 1 | E24: 3500 | F24: =E24*D24 -> 3500
E26: Total InD | F26: =SUM(F18:F24) -> 14000
A28: 3 | B28: Project OVH & GM
B30: # | C30: Item | D30: % | E30: Costs | F30: Total Costs
B31: 3.1 | C31: OVH | D31: 0 | E31: =(I12+F26) -> 179750 | F31: =E31*D31 -> 0
B32: 3.2 | C32: Gross Profit % | D32: 0.09 | E32: =E31 -> 179750 | F32: =E32*D32 -> 16177.5
E34: OVH&GM - Value | F34: =SUM(F31:F32) -> 16177.5
E36: InD % | F36: =(F34+F26)/(F34+F26+I12) -> 0.15402381
E38: Total With Profit | F38: =F34+F26+I12 -> 195927.5
